Workbook

Sheet 구역1
A1: 2026년 하계수양회 ─ 11구역
A2: NO | B2: 구역 | C2: 부서 (회별) | D2: 성 명 | E2: 차수 | F2: 본대 | H2: 기타 | L2: 인 도 자 | N2: 비고
F3: 상행 | G3: 하행 | H3: 상행 | I3: 참석 시점 | J3: 하행 | K3: 귀가 시점 | L3: 성 명 | M3: 관계
A74: 합 계 | E74: =IF(COUNTA(E4:E73)=0,"",COUNTA(E4:E73)) | F74: =IF(COUNTA(F4:F73)=0,"",COUNTA(F4:F73)) | G74: =IF(COUNTA(G4:G73)=0,"",COUNTA(G4:G73)) | H74: =IF(COUNTA(H4:H73)=0,"",COUNTA(H4:H73)) | I74: =IF(COUNTA(I4:I73)=0,"",COUNTA(I4:I73)) | J74: =IF(COUNTA(J4:J73)=0,"",COUNTA(J4:J73)) | K74: =IF(COUNTA(K4:K73)=0,"",COUNTA(K4:K73)) | L74: =IF(COUNTA(L4:L73)=0,"",COUNTA(L4:L73))

Sheet 구역2
A1: 2026년 하계수양회 ─ 11구역
A2: NO | B2: 구역 | C2: 부서 (회별) | D2: 성 명 | E2: 차수 | F2: 본대 | H2: 기타 | L2: 인 도 자 | N2: 비고
F3: 상행 | G3: 하행 | H3: 상행 | I3: 참석 시점 | J3: 하행 | K3: 귀가 시점 | L3: 성 명 | M3: 관계
A74: 합 계 | E74: =IF(COUNTA(E4:E73)=0,"",COUNTA(E4:E73)) | F74: =IF(COUNTA(F4:F73)=0,"",COUNTA(F4:F73)) | G74: =IF(COUNTA(G4:G73)=0,"",COUNTA(G4:G73)) | H74: =IF(COUNTA(H4:H73)=0,"",COUNTA(H4:H73)) | I74: =IF(COUNTA(I4:I73)=0,"",COUNTA(I4:I73)) | J74: =IF(COUNTA(J4:J73)=0,"",COUNTA(J4:J73)) | K74: =IF(COUNTA(K4:K73)=0,"",COUNTA(K4:K73)) | L74: =IF(COUNTA(L4:L73)=0,"",COUNTA(L4:L73))

Sheet 구역3
A1: 2026년 하계수양회 ─ 11구역
A2: NO | B2: 구역 | C2: 부서 (회별) | D2: 성 명 | E2: 차수 | F2: 본대 | H2: 기타 | L2: 인 도 자 | N2: 비고
F3: 상행 | G3: 하행 | H3: 상행 | I3: 참석 시점 | J3: 하행 | K3: 귀가 시점 | L3: 성 명 | M3: 관계
A74: 합 계 | E74: =IF(COUNTA(E4:E73)=0,"",COUNTA(E4:E73)) | F74: =IF(COUNTA(F4:F73)=0,"",COUNTA(F4:F73)) | G74: =IF(COUNTA(G4:G73)=0,"",COUNTA(G4:G73)) | H74: =IF(COUNTA(H4:H73)=0,"",COUNTA(H4:H73)) | I74: =IF(COUNTA(I4:I73)=0,"",COUNTA(I4:I73)) | J74: =IF(COUNTA(J4:J73)=0,"",COUNTA(J4:J73)) | K74: =IF(COUNTA(K4:K73)=0,"",COUNTA(K4:K73)) | L74: =IF(COUNTA(L4:L73)=0,"",COUNTA(L4:L73))

Sheet 구역4
A1: 2026년 하계수양회 ─ 11구역
A2: NO | B2: 구역 | C2: 부서 (회별) | D2: 성 명 | E2: 차수 | F2: 본대 | H2: 기타 | L2: 인 도 자 | N2: 비고
F3: 상행 | G3: 하행 | H3: 상행 | I3: 참석 시점 | J3: 하행 | K3: 귀가 시점 | L3: 성 명 | M3: 관계
A74: 합 계 | E74: =IF(COUNTA(E4:E73)=0,"",COUNTA(E4:E73)) | F74: =IF(COUNTA(F4:F73)=0,"",COUNTA(F4:F73)) | G74: =IF(COUNTA(G4:G73)=0,"",COUNTA(G4:G73)) | H74: =IF(COUNTA(H4:H73)=0,"",COUNTA(H4:H73)) | I74: =IF(COUNTA(I4:I73)=0,"",COUNTA(I4:I73)) | J74: =IF(COUNTA(J4:J73)=0,"",COUNTA(J4:J73)) | K74: =IF(COUNTA(K4:K73)=0,"",COUNTA(K4:K73)) | L74: =IF(COUNTA(L4:L73)=0,"",COUNTA(L4:L73))

Sheet 구역5
A1: 2026년 하계수양회 ─ 11구역
A2: NO | B2: 구역 | C2: 부서 (회별) | D2: 성 명 | E2: 차수 | F2: 본대 | H2: 기타 | L2: 인 도 자 | N2: 비고
F3: 상행 | G3: 하행 | H3: 상행 | I3: 참석 시점 | J3: 하행 | K3: 귀가 시점 | L3: 성 명 | M3: 관계
A74: 합 계 | E74: =IF(COUNTA(E4:E73)=0,"",COUNTA(E4:E73)) | F74: =IF(COUNTA(F4:F73)=0,"",COUNTA(F4:F73)) | G74: =IF(COUNTA(G4:G73)=0,"",COUNTA(G4:G73)) | H74: =IF(COUNTA(H4:H73)=0,"",COUNTA(H4:H73)) | I74: =IF(COUNTA(I4:I73)=0,"",COUNTA(I4:I73)) | J74: =IF(COUNTA(J4:J73)=0,"",COUNTA(J4:J73)) | K74: =IF(COUNTA(K4:K73)=0,"",COUNTA(K4:K73)) | L74: =IF(COUNTA(L4:L73)=0,"",COUNTA(L4:L73))

Sheet 구역6
A1: 2026년 하계수양회 ─ 11구역
A2: NO | B2: 구역 | C2: 부서 (회별) | D2: 성 명 | E2: 차수 | F2: 본대 | H2: 기타 | L2: 인 도 자 | N2: 비고
F3: 상행 | G3: 하행 | H3: 상행 | I3: 참석 시점 | J3: 하행 | K3: 귀가 시점 | L3: 성 명 | M3: 관계
A74: 합 계 | E74: =IF(COUNTA(E4:E73)=0,"",COUNTA(E4:E73)) | F74: =IF(COUNTA(F4:F73)=0,"",COUNTA(F4:F73)) | G74: =IF(COUNTA(G4:G73)=0,"",COUNTA(G4:G73)) | H74: =IF(COUNTA(H4:H73)=0,"",COUNTA(H4:H73)) | I74: =IF(COUNTA(I4:I73)=0,"",COUNTA(I4:I73)) | J74: =IF(COUNTA(J4:J73)=0,"",COUNTA(J4:J73)) | K74: =IF(COUNTA(K4:K73)=0,"",COUNTA(K4:K73)) | L74: =IF(COUNTA(L4:L73)=0,"",COUNTA(L4:L73))

Sheet 구역7
A1: 2026년 하계수양회 ─ 11구역
A2: NO | B2: 구역 | C2: 부서 (회별) | D2: 성 명 | E2: 차수 | F2: 본대 | H2: 기타 | L2: 인 도 자 | N2: 비고
F3: 상행 | G3: 하행 | H3: 상행 | I3: 참석 시점 | J3: 하행 | K3: 귀가 시점 | L3: 성 명 | M3: 관계
A74: 합 계 | E74: =IF(COUNTA(E4:E73)=0,"",COUNTA(E4:E73)) | F74: =IF(COUNTA(F4:F73)=0,"",COUNTA(F4:F73)) | G74: =IF(COUNTA(G4:G73)=0,"",COUNTA(G4:G73)) | H74: =IF(COUNTA(H4:H73)=0,"",COUNTA(H4:H73)) | I74: =IF(COUNTA(I4:I73)=0,"",COUNTA(I4:I73)) | J74: =IF(COUNTA(J4:J73)=0,"",COUNTA(J4:J73)) | K74: =IF(COUNTA(K4:K73)=0,"",COUNTA(K4:K73)) | L74: =IF(COUNTA(L4:L73)=0,"",COUNTA(L4:L73))

Sheet 구역8
A1: 2026년 하계수양회 ─ 11구역
A2: NO | B2: 구역 | C2: 부서 (회별) | D2: 성 명 | E2: 차수 | F2: 본대 | H2: 기타 | L2: 인 도 자 | N2: 비고
F3: 상행 | G3: 하행 | H3: 상행 | I3: 참석 시점 | J3: 하행 | K3: 귀가 시점 | L3: 성 명 | M3: 관계
A74: 합 계 | E74: =IF(COUNTA(E4:E73)=0,"",COUNTA(E4:E73)) | F74: =IF(COUNTA(F4:F73)=0,"",COUNTA(F4:F73)) | G74: =IF(COUNTA(G4:G73)=0,"",COUNTA(G4:G73)) | H74: =IF(COUNTA(H4:H73)=0,"",COUNTA(H4:H73)) | I74: =IF(COUNTA(I4:I73)=0,"",COUNTA(I4:I73)) | J74: =IF(COUNTA(J4:J73)=0,"",COUNTA(J4:J73)) | K74: =IF(COUNTA(K4:K73)=0,"",COUNTA(K4:K73)) | L74: =IF(COUNTA(L4:L73)=0,"",COUNTA(L4:L73))

Sheet 구역9
A1: 2026년 하계수양회 ─ 11구역
A2: NO | B2: 구역 | C2: 부서 (회별) | D2: 성 명 | E2: 차수 | F2: 본대 | H2: 기타 | L2: 인 도 자 | N2: 비고
F3: 상행 | G3: 하행 | H3: 상행 | I3: 참석 시점 | J3: 하행 | K3: 귀가 시점 | L3: 성 명 | M3: 관계
A74: 합 계 | E74: =IF(COUNTA(E4:E73)=0,"",COUNTA(E4:E73)) | F74: =IF(COUNTA(F4:F73)=0,"",COUNTA(F4:F73)) | G74: =IF(COUNTA(G4:G73)=0,"",COUNTA(G4:G73)) | H74: =IF(COUNTA(H4:H73)=0,"",COUNTA(H4:H73)) | I74: =IF(COUNTA(I4:I73)=0,"",COUNTA(I4:I73)) | J74: =IF(COUNTA(J4:J73)=0,"",COUNTA(J4:J73)) | K74: =IF(COUNTA(K4:K73)=0,"",COUNTA(K4:K73)) | L74: =IF(COUNTA(L4:L73)=0,"",COUNTA(L4:L73))

Sheet 구역10
A1: 2026년 하계수양회 ─ 11구역
A2: NO | B2: 구역 | C2: 부서 (회별) | D2: 성 명 | E2: 차수 | F2: 본대 | H2: 기타 | L2: 인 도 자 | N2: 비고
F3: 상행 | G3: 하행 | H3: 상행 | I3: 참석 시점 | J3: 하행 | K3: 귀가 시점 | L3: 성 명 | M3: 관계
A74: 합 계 | E74: =IF(COUNTA(E4:E73)=0,"",COUNTA(E4:E73)) | F74: =IF(COUNTA(F4:F73)=0,"",COUNTA(F4:F73)) | G74: =IF(COUNTA(G4:G73)=0,"",COUNTA(G4:G73)) | H74: =IF(COUNTA(H4:H73)=0,"",COUNTA(H4:H73)) | I74: =IF(COUNTA(I4:I73)=0,"",COUNTA(I4:I73)) | J74: =IF(COUNTA(J4:J73)=0,"",COUNTA(J4:J73)) | K74: =IF(COUNTA(K4:K73)=0,"",COUNTA(K4:K73)) | L74: =IF(COUNTA(L4:L73)=0,"",COUNTA(L4:L73))

Sheet 구역11
A1: 2026년 하계수양회 ─ 11구역
A2: NO | B2: 구역 | C2: 부서 (회별) | D2: 성 명 | E2: 차수 | F2: 본대 | H2: 기타 | L2: 인 도 자 | N2: 비고
F3: 상행 | G3: 하행 | H3: 상행 | I3: 참석 시점 | J3: 하행 | K3: 귀가 시점 | L3: 성 명 | M3: 관계
A74: 합 계 | E74: =IF(COUNTA(E4:E73)=0,"",COUNTA(E4:E73)) | F74: =IF(COUNTA(F4:F73)=0,"",COUNTA(F4:F73)) | G74: =IF(COUNTA(G4:G73)=0,"",COUNTA(G4:G73)) | H74: =IF(COUNTA(H4:H73)=0,"",COUNTA(H4:H73)) | I74: =IF(COUNTA(I4:I73)=0,"",COUNTA(I4:I73)) | J74: =IF(COUNTA(J4:J73)=0,"",COUNTA(J4:J73)) | K74: =IF(COUNTA(K4:K73)=0,"",COUNTA(K4:K73)) | L74: =IF(COUNTA(L4:L73)=0,"",COUNTA(L4:L73))

Sheet 구역12
A1: 2026년 하계수양회 ─ 11구역
A2: NO | B2: 구역 | C2: 부서 (회별) | D2: 성 명 | E2: 차수 | F2: 본대 | H2: 기타 | L2: 인 도 자 | N2: 비고
F3: 상행 | G3: 하행 | H3: 상행 | I3: 참석 시점 | J3: 하행 | K3: 귀가 시점 | L3: 성 명 | M3: 관계
A74: 합 계 | E74: =IF(COUNTA(E4:E73)=0,"",COUNTA(E4:E73)) | F74: =IF(COUNTA(F4:F73)=0,"",COUNTA(F4:F73)) | G74: =IF(COUNTA(G4:G73)=0,"",COUNTA(G4:G73)) | H74: =IF(COUNTA(H4:H73)=0,"",COUNTA(H4:H73)) | I74: =IF(COUNTA(I4:I73)=0,"",COUNTA(I4:I73)) | J74: =IF(COUNTA(J4:J73)=0,"",COUNTA(J4:J73)) | K74: =IF(COUNTA(K4:K73)=0,"",COUNTA(K4:K73)) | L74: =IF(COUNTA(L4:L73)=0,"",COUNTA(L4:L73))

Sheet 구역13
A1: 2026년 하계수양회 ─ 11구역
A2: NO | B2: 구역 | C2: 부서 (회별) | D2: 성 명 | E2: 차수 | F2: 본대 | H2: 기타 | L2: 인 도 자 | N2: 비고
F3: 상행 | G3: 하행 | H3: 상행 | I3: 참석 시점 | J3: 하행 | K3: 귀가 시점 | L3: 성 명 | M3: 관계
A74: 합 계 | E74: =IF(COUNTA(E4:E73)=0,"",COUNTA(E4:E73)) | F74: =IF(COUNTA(F4:F73)=0,"",COUNTA(F4:F73)) | G74: =IF(COUNTA(G4:G73)=0,"",COUNTA(G4:G73)) | H74: =IF(COUNTA(H4:H73)=0,"",COUNTA(H4:H73)) | I74: =IF(COUNTA(I4:I73)=0,"",COUNTA(I4:I73)) | J74: =IF(COUNTA(J4:J73)=0,"",COUNTA(J4:J73)) | K74: =IF(COUNTA(K4:K73)=0,"",COUNTA(K4:K73)) | L74: =IF(COUNTA(L4:L73)=0,"",COUNTA(L4:L73))

Sheet 구역14
A1: 2026년 하계수양회 ─ 11구역
A2: NO | B2: 구역 | C2: 부서 (회별) | D2: 성 명 | E2: 차수 | F2: 본대 | H2: 기타 | L2: 인 도 자 | N2: 비고
F3: 상행 | G3: 하행 | H3: 상행 | I3: 참석 시점 | J3: 하행 | K3: 귀가 시점 | L3: 성 명 | M3: 관계
A74: 합 계 | E74: =IF(COUNTA(E4:E73)=0,"",COUNTA(E4:E73)) | F74: =IF(COUNTA(F4:F73)=0,"",COUNTA(F4:F73)) | G74: =IF(COUNTA(G4:G73)=0,"",COUNTA(G4:G73)) | H74: =IF(COUNTA(H4:H73)=0,"",COUNTA(H4:H73)) | I74: =IF(COUNTA(I4:I73)=0,"",COUNTA(I4:I73)) | J74: =IF(COUNTA(J4:J73)=0,"",COUNTA(J4:J73)) | K74: =IF(COUNTA(K4:K73)=0,"",COUNTA(K4:K73)) | L74: =IF(COUNTA(L4:L73)=0,"",COUNTA(L4:L73))

Sheet 구역15
A1: 2026년 하계수양회 ─ 11구역
A2: NO | B2: 구역 | C2: 부서 (회별) | D2: 성 명 | E2: 차수 | F2: 본대 | H2: 기타 | L2: 인 도 자 | N2: 비고
F3: 상행 | G3: 하행 | H3: 상행 | I3: 참석 시점 | J3: 하행 | K3: 귀가 시점 | L3: 성 명 | M3: 관계
A74: 합 계 | E74: =IF(COUNTA(E4:E73)=0,"",COUNTA(E4:E73)) | F74: =IF(COUNTA(F4:F73)=0,"",COUNTA(F4:F73)) | G74: =IF(COUNTA(G4:G73)=0,"",COUNTA(G4:G73)) | H74: =IF(COUNTA(H4:H73)=0,"",COUNTA(H4:H73)) | I74: =IF(COUNTA(I4:I73)=0,"",COUNTA(I4:I73)) | J74: =IF(COUNTA(J4:J73)=0,"",COUNTA(J4:J73)) | K74: =IF(COUNTA(K4:K73)=0,"",COUNTA(K4:K73)) | L74: =IF(COUNTA(L4:L73)=0,"",COUNTA(L4:L73))

Sheet 구역16
A1: 2026년 하계수양회 ─ 11구역
A2: NO | B2: 구역 | C2: 부서 (회별) | D2: 성 명 | E2: 차수 | F2: 본대 | H2: 기타 | L2: 인 도 자 | N2: 비고
F3: 상행 | G3: 하행 | H3: 상행 | I3: 참석 시점 | J3: 하행 | K3: 귀가 시점 | L3: 성 명 | M3: 관계
A74: 합 계 | E74: =IF(COUNTA(E4:E73)=0,"",COUNTA(E4:E73)) | F74: =IF(COUNTA(F4:F73)=0,"",COUNTA(F4:F73)) | G74: =IF(COUNTA(G4:G73)=0,"",COUNTA(G4:G73)) | H74: =IF(COUNTA(H4:H73)=0,"",COUNTA(H4:H73)) | I74: =IF(COUNTA(I4:I73)=0,"",COUNTA(I4:I73)) | J74: =IF(COUNTA(J4:J73)=0,"",COUNTA(J4:J73)) | K74: =IF(COUNTA(K4:K73)=0,"",COUNTA(K4:K73)) | L74: =IF(COUNTA(L4:L73)=0,"",COUNTA(L4:L73))

Sheet 구역17
A1: 2026년 하계수양회 ─ 11구역
A2: NO | B2: 구역 | C2: 부서 (회별) | D2: 성 명 | E2: 차수 | F2: 본대 | H2: 기타 | L2: 인 도 자 | N2: 비고
F3: 상행 | G3: 하행 | H3: 상행 | I3: 참석 시점 | J3: 하행 | K3: 귀가 시점 | L3: 성 명 | M3: 관계
A74: 합 계 | E74: =IF(COUNTA(E4:E73)=0,"",COUNTA(E4:E73)) | F74: =IF(COUNTA(F4:F73)=0,"",COUNTA(F4:F73)) | G74: =IF(COUNTA(G4:G73)=0,"",COUNTA(G4:G73)) | H74: =IF(COUNTA(H4:H73)=0,"",COUNTA(H4:H73)) | I74: =IF(COUNTA(I4:I73)=0,"",COUNTA(I4:I73)) | J74: =IF(COUNTA(J4:J73)=0,"",COUNTA(J4:J73)) | K74: =IF(COUNTA(K4:K73)=0,"",COUNTA(K4:K73)) | L74: =IF(COUNTA(L4:L73)=0,"",COUNTA(L4:L73))

Sheet 구역18
A1: 2026년 하계수양회 ─ 11구역
A2: NO | B2: 구역 | C2: 부서 (회별) | D2: 성 명 | E2: 차수 | F2: 본대 | H2: 기타 | L2: 인 도 자 | N2: 비고
F3: 상행 | G3: 하행 | H3: 상행 | I3: 참석 시점 | J3: 하행 | K3: 귀가 시점 | L3: 성 명 | M3: 관계
A74: 합 계 | E74: =IF(COUNTA(E4:E73)=0,"",COUNTA(E4:E73)) | F74: =IF(COUNTA(F4:F73)=0,"",COUNTA(F4:F73)) | G74: =IF(COUNTA(G4:G73)=0,"",COUNTA(G4:G73)) | H74: =IF(COUNTA(H4:H73)=0,"",COUNTA(H4:H73)) | I74: =IF(COUNTA(I4:I73)=0,"",COUNTA(I4:I73)) | J74: =IF(COUNTA(J4:J73)=0,"",COUNTA(J4:J73)) | K74: =IF(COUNTA(K4:K73)=0,"",COUNTA(K4:K73)) | L74: =IF(COUNTA(L4:L73)=0,"",COUNTA(L4:L73))

Sheet 구역19
A1: 2026년 하계수양회 ─ 11구역
A2: NO | B2: 구역 | C2: 부서 (회별) | D2: 성 명 | E2: 차수 | F2: 본대 | H2: 기타 | L2: 인 도 자 | N2: 비고
F3: 상행 | G3: 하행 | H3: 상행 | I3: 참석 시점 | J3: 하행 | K3: 귀가 시점 | L3: 성 명 | M3: 관계
A74: 합 계 | E74: =IF(COUNTA(E4:E73)=0,"",COUNTA(E4:E73)) | F74: =IF(COUNTA(F4:F73)=0,"",COUNTA(F4:F73)) | G74: =IF(COUNTA(G4:G73)=0,"",COUNTA(G4:G73)) | H74: =IF(COUNTA(H4:H73)=0,"",COUNTA(H4:H73)) | I74: =IF(COUNTA(I4:I73)=0,"",COUNTA(I4:I73)) | J74: =IF(COUNTA(J4:J73)=0,"",COUNTA(J4:J73)) | K74: =IF(COUNTA(K4:K73)=0,"",COUNTA(K4:K73)) | L74: =IF(COUNTA(L4:L73)=0,"",COUNTA(L4:L73))

Sheet 구역20
A1: 2026년 하계수양회 ─ 11구역
A2: NO | B2: 구역 | C2: 부서 (회별) | D2: 성 명 | E2: 차수 | F2: 본대 | H2: 기타 | L2: 인 도 자 | N2: 비고
F3: 상행 | G3: 하행 | H3: 상행 | I3: 참석 시점 | J3: 하행 | K3: 귀가 시점 | L3: 성 명 | M3: 관계
A74: 합 계 | E74: =IF(COUNTA(E4:E73)=0,"",COUNTA(E4:E73)) | F74: =IF(COUNTA(F4:F73)=0,"",COUNTA(F4:F73)) | G74: =IF(COUNTA(G4:G73)=0,"",COUNTA(G4:G73)) | H74: =IF(COUNTA(H4:H73)=0,"",COUNTA(H4:H73)) | I74: =IF(COUNTA(I4:I73)=0,"",COUNTA(I4:I73)) | J74: =IF(COUNTA(J4:J73)=0,"",COUNTA(J4:J73)) | K74: =IF(COUNTA(K4:K73)=0,"",COUNTA(K4:K73)) | L74: =IF(COUNTA(L4:L73)=0,"",COUNTA(L4:L73))

Sheet 전도대상자
A1: 전도 대상자 명단
A2: NO | B2: 구역 | C2: 회(부서) | D2: 성 명 | E2: 관계 | F2: 인도자 | G2: 숙소 | I2: 비고
A3: 1
A4: 2
A5: 3
A6: 4
A7: 5
A8: 6
A9: 7
A10: 8
A11: 9
A12: 10
A13: 11
A14: 12
... A42: 40

Sheet 전도현황
A1: 2026년 하계수양회 전도 및 침례 현황
A2: NO | B2: 구역 | C2: 성명 | D2: 회(부서) | E2: 인도자 | F2: 관계 | G2: 구원시인 | H2: 침례여부 | I2: 비고

Sheet 회비지원
A1: 회비 지원 명단
A2: NO | B2: 구역 | C2: 회(부서) | D2: 성 명 | E2: 금액 | F2: 비고 | J2: 회비
A3: 1 | E3: =IF(C3="","",VLOOKUP(C3,$J$3:$K$11,2,0)) | J3: 은장회 | K3: 50000
A4: 2 | E4: =IF(C4="","",VLOOKUP(C4,$J$3:$K$11,2,0)) | J4: 봉사회 | K4: 70000
A5: 3 | E5: =IF(C5="","",VLOOKUP(C5,$J$3:$K$11,2,0)) | J5: 어머니회 | K5: 70000
A6: 4 | E6: =IF(C6="","",VLOOKUP(C6,$J$3:$K$11,2,0)) | J6: 청년회 | K6: 70000
A7: 5 | E7: =IF(C7="","",VLOOKUP(C7,$J$3:$K$11,2,0)) | J7: 대학부 | K7: 50000
A8: 6 | E8: =IF(C8="","",VLOOKUP(C8,$J$3:$K$11,2,0)) | J8: 중고등부 | K8: 0
A9: 7 | E9: =IF(C9="","",VLOOKUP(C9,$J$3:$K$11,2,0)) | J9: 초등부 | K9: 0
A10: 8 | E10: =IF(C10="","",VLOOKUP(C10,$J$3:$K$11,2,0)) | J10: 유치부 | K10: 0
A11: 9 | E11: =IF(C11="","",VLOOKUP(C11,$J$3:$K$11,2,0)) | J11: 미취학 | K11: 0
A12: 10 | E12: =IF(C12="","",VLOOKUP(C12,$J$3:$K$11,2,0))
A13: 11 | E13: =IF(C13="","",VLOOKUP(C13,$J$3:$K$11,2,0))
A14: 12 | E14: =IF(C14="","",VLOOKUP(C14,$J$3:$K$11,2,0))
A15: 13 | E15: =IF(C15="","",VLOOKUP(C15,$J$3:$K$11,2,0))
A16: 14 | E16: =IF(C16="","",VLOOKUP(C16,$J$3:$K$11,2,0))
A17: 15 | E17: =IF(C17="","",VLOOKUP(C17,$J$3:$K$11,2,0))
A18: 16 | E18: =IF(C18="","",VLOOKUP(C18,$J$3:$K$11,2,0))
A19: 17 | E19: =IF(C19="","",VLOOKUP(C19,$J$3:$K$11,2,0))
A20: 18 | E20: =IF(C20="","",VLOOKUP(C20,$J$3:$K$11,2,0))
A21: 19 | E21: =IF(C21="","",VLOOKUP(C21,$J$3:$K$11,2,0))
A22: 20 | E22: =IF(C22="","",VLOOKUP(C22,$J$3:$K$11,2,0))
A23: 21 | E23: =IF(C23="","",VLOOKUP(C23,$J$3:$K$11,2,0))
... A82: 80 | E82: =IF(C82="","",VLOOKUP(C82,$J$3:$K$11,2,0))
A83: 합 계 | E83: =IF(SUM(E3:E82)=0,"",SUM(E3:E82))

Sheet 통계
A1: 교통편 집계표
A2: 구역 | B2: 본대 버스 | D2: 교회차 | F2: 타교회 | H2: 개인차량 | J2: 대중교통 | L2: 계
B3: 상행 | C3: 하행 | D3: 상행 | E3: 하행 | F3: 상행 | G3: 하행 | H3: 상행 | I3: 하행 | J3: 상행 | K3: 하행
A4: 구역1 | B4: =IF(COUNTIFS(구역1!F4:F73,"1호차",구역1!E4:E73,"*"&$B31&"*")+COUNTIFS(구역1!F4:F73,"2호차",구역1!E4:E73,"*"&$B31&"*")+COUNTIFS(구역1!F4:F73,"3호차",구역1!E4:E73,"*"&$B31&"*")+COUNTIFS(구역1!F4:F73,"4호차",구역1!E4:E73,"*"&$B31&"*")+COUNTIFS(구역1!F4:F73,"5호차",구역1!E4:E73,"*"&$B31&"*")+COUNTIFS(구역1!F4:F73,"6호차",구역1!E4:E73,"*"&$B31&"*")+COUNTIFS(구역1!F4:F73,"7호차",구역1!E4:E73,"*"&$B31&"*")+COUNTIFS(구역1!F4:F73,"8호차",구역1!E4:E73,"*"&$B31&"*")+COUNTIFS(구역1!F4:F73,"9호차",구역1!E4:E73,"*"&$B31&"*")+COUNTIFS(구역1!F4:F73,"10호차",구역1!E4:E73,"*"&$B31&"*")=0,"",COUNTIFS(구역1!F4:F73,"1호차",구역1!E4:E73,"*"&$B31&"*")+COUNTIFS(구역1!F4:F73,"2호차",구역1!E4:E73,"*"&$B31&"*")+COUNTIFS(구역1!F4:F73,"3호차",구역1!E4:E73,"*"&$B31&"*")+COUNTIFS(구역1!F4:F73,"4호차",구역1!E4:E73,"*"&$B31&"*")+COUNTIFS(구역1!F4:F73,"5호차",구역1!E4:E73,"*"&$B31&"*")+COUNTIFS(구역1!F4:F73,"6호차",구역1!E4:E73,"*"&$B31&"*")+COUNTIFS(구역1!F4:F73,"7호차",구역1!E4:E73,"*"&$B31&"*")+COUNTIFS(구역1!F4:F73,"8호차",구역1!E4:E73,"*"&$B31&"*")+COUNTIFS(구역1!F4:F73,"9호차",구역1!E4:E73,"*"&$B31&"*")+COUNTIFS(구역1!F4:F73,"10호차",구역1!E4:E73,"*"&$B31&"*")) | C4: =IF(COUNTIFS(구역1!G4:G73,"1호차",구역1!E4:E73,"*"&$B31&"*")+COUNTIFS(구역1!G4:G73,"2호차",구역1!E4:E73,"*"&$B31&"*")+COUNTIFS(구역1!G4:G73,"3호차",구역1!E4:E73,"*"&$B31&"*")+COUNTIFS(구역1!G4:G73,"4호차",구역1!E4:E73,"*"&$B31&"*")+COUNTIFS(구역1!G4:G73,"5호차",구역1!E4:E73,"*"&$B31&"*")+COUNTIFS(구역1!G4:G73,"6호차",구역1!E4:E73,"*"&$B31&"*")+COUNTIFS(구역1!G4:G73,"7호차",구역1!E4:E73,"*"&$B31&"*")+COUNTIFS(구역1!G4:G73,"8호차",구역1!E4:E73,"*"&$B31&"*")+COUNTIFS(구역1!G4:G73,"9호차",구역1!E4:E73,"*"&$B31&"*")+COUNTIFS(구역1!G4:G73,"10호차",구역1!E4:E73,"*"&$B31&"*")=0,"",COUNTIFS(구역1!G4:G73,"1호차",구역1!E4:E73,"*"&$B31&"*")+COUNTIFS(구역1!G4:G73,"2호차",구역1!E4:E73,"*"&$B31&"*")+COUNTIFS(구역1!G4:G73,"3호차",구역1!E4:E73,"*"&$B31&"*")+COUNTIFS(구역1!G4:G73,"4호차",구역1!E4:E73,"*"&$B31&"*")+COUNTIFS(구역1!G4:G73,"5호차",구역1!E4:E73,"*"&$B31&"*")+COUNTIFS(구역1!G4:G73,"6호차",구역1!E4:E73,"*"&$B31&"*")+COUNTIFS(구역1!G4:G73,"7호차",구역1!E4:E73,"*"&$B31&"*")+COUNTIFS(구역1!G4:G73,"8호차",구역1!E4:E73,"*"&$B31&"*")+COUNTIFS(구역1!G4:G73,"9호차",구역1!E4:E73,"*"&$B31&"*")+COUNTIFS(구역1!G4:G73,"10호차",구역1!E4:E73,"*"&$B31&"*")) | D4: =IF(COUNTIFS(구역1!F4:F73,"교회차1",구역1!E4:E73,"*"&$B31&"*")+COUNTIFS(구역1!F4:F73,"교회차2",구역1!E4:E73,"*"&$B31&"*")+COUNTIFS(구역1!F4:F73,"교회차3",구역1!E4:E73,"*"&$B31&"*")+COUNTIFS(구역1!F4:F73,"교회차4",구역1!E4:E73,"*"&$B31&"*")+COUNTIFS(구역1!F4:F73,"교회차5",구역1!E4:E73,"*"&$B31&"*")+COUNTIFS(구역1!H4:H73,"*교회차*",구역1!E4:E73,"*"&$B31&"*")=0,"",COUNTIFS(구역1!F4:F73,"교회차1",구역1!E4:E73,"*"&$B31&"*")+COUNTIFS(구역1!F4:F73,"교회차2",구역1!E4:E73,"*"&$B31&"*")+COUNTIFS(구역1!F4:F73,"교회차3",구역1!E4:E73,"*"&$B31&"*")+COUNTIFS(구역1!F4:F73,"교회차4",구역1!E4:E73,"*"&$B31&"*")+COUNTIFS(구역1!F4:F73,"교회차5",구역1!E4:E73,"*"&$B31&"*")+COUNTIFS(구역1!H4:H73,"*교회차*",구역1!E4:E73,"*"&$B31&"*")) | E4: =IF(COUNTIFS(구역1!G4:G73,"교회차1",구역1!E4:E73,"*"&$B31&"*")+COUNTIFS(구역1!G4:G73,"교회차2",구역1!E4:E73,"*"&$B31&"*")+COUNTIFS(구역1!G4:G73,"교회차3",구역1!E4:E73,"*"&$B31&"*")+COUNTIFS(구역1!G4:G73,"교회차4",구역1!E4:E73,"*"&$B31&"*")+COUNTIFS(구역1!G4:G73,"교회차5",구역1!E4:E73,"*"&$B31&"*")+COUNTIFS(구역1!J4:J73,"*교회차*",구역1!E4:E73,"*"&$B31&"*")=0,"",COUNTIFS(구역1!G4:G73,"교회차1",구역1!E4:E73,"*"&$B31&"*")+COUNTIFS(구역1!G4:G73,"교회차2",구역1!E4:E73,"*"&$B31&"*")+COUNTIFS(구역1!G4:G73,"교회차3",구역1!E4:E73,"*"&$B31&"*")+COUNTIFS(구역1!G4:G73,"교회차4",구역1!E4:E73,"*"&$B31&"*")+COUNTIFS(구역1!G4:G73,"교회차5",구역1!E4:E73,"*"&$B31&"*")+COUNTIFS(구역1!J4:J73,"*교회차*",구역1!E4:E73,"*"&$B31&"*")) | F4: =IF(COUNTIFS(구역1!F4:F73,"타교회",구역1!E4:E73,"*"&$B31&"*")+COUNTIFS(구역1!H4:H73,"*타교회*",구역1!E4:E73,"*"&$B31&"*")=0,"",COUNTIFS(구역1!F4:F73,"타교회",구역1!E4:E73,"*"&$B31&"*")+COUNTIFS(구역1!H4:H73,"*타교회*",구역1!E4:E73,"*"&$B31&"*")) | G4: =IF(COUNTIFS(구역1!G4:G73,"타교회",구역1!E4:E73,"*"&$B31&"*")+COUNTIFS(구역1!J4:J73,"*타교회*",구역1!E4:E73,"*"&$B31&"*")=0,"",COUNTIFS(구역1!G4:G73,"타교회",구역1!E4:E73,"*"&$B31&"*")+COUNTIFS(구역1!J4:J73,"*타교회*",구역1!E4:E73,"*"&$B31&"*")) | H4: =IF(COUNTIFS(구역1!F4:F73,"개인차",구역1!E4:E73,"*"&$B31&"*")+(COUNTIFS(구역1!H4:H73,"?*",구역1!E4:E73,"*"&$B31&"*")-COUNTIFS(구역1!H4:H73,"*교회차*",구역1!E4:E73,"*"&$B31&"*")-COUNTIFS(구역1!H4:H73,"*타교회*",구역1!E4:E73,"*"&$B31&"*")-COUNTIFS(구역1!H4:H73,"*대중교통*",구역1!E4:E73,"*"&$B31&"*"))=0,"",COUNTIFS(구역1!F4:F73,"개인차",구역1!E4:E73,"*"&$B31&"*")+(COUNTIFS(구역1!H4:H73,"?*",구역1!E4:E73,"*"&$B31&"*")-COUNTIFS(구역1!H4:H73,"*교회차*",구역1!E4:E73,"*"&$B31&"*")-COUNTIFS(구역1!H4:H73,"*타교회*",구역1!E4:E73,"*"&$B31&"*")-COUNTIFS(구역1!H4:H73,"*대중교통*",구역1!E4:E73,"*"&$B31&"*"))) | I4: =IF(COUNTIFS(구역1!G4:G73,"개인차",구역1!E4:E73,"*"&$B31&"*")+(COUNTIFS(구역1!J4:J73,"?*",구역1!E4:E73,"*"&$B31&"*")-COUNTIFS(구역1!J4:J73,"*교회차*",구역1!E4:E73,"*"&$B31&"*")-COUNTIFS(구역1!J4:J73,"*타교회*",구역1!E4:E73,"*"&$B31&"*")-COUNTIFS(구역1!J4:J73,"*대중교통*",구역1!E4:E73,"*"&$B31&"*"))=0,"",COUNTIFS(구역1!G4:G73,"개인차",구역1!E4:E73,"*"&$B31&"*")+(COUNTIFS(구역1!J4:J73,"?*",구역1!E4:E73,"*"&$B31&"*")-COUNTIFS(구역1!J4:J73,"*교회차*",구역1!E4:E73,"*"&$B31&"*")-COUNTIFS(구역1!J4:J73,"*타교회*",구역1!E4:E73,"*"&$B31&"*")-COUNTIFS(구역1!J4:J73,"*대중교통*",구역1!E4:E73,"*"&$B31&"*"))) | J4: =IF(COUNTIFS(구역1!F4:F73,"대중교통",구역1!E4:E73,"*"&$B31&"*")+COUNTIFS(구역1!H4:H73,"*대중교통*",구역1!E4:E73,"*"&$B31&"*")=0,"",COUNTIFS(구역1!F4:F73,"대중교통",구역1!E4:E73,"*"&$B31&"*")+COUNTIFS(구역1!H4:H73,"*대중교통*",구역1!E4:E73,"*"&$B31&"*")) | K4: =IF(COUNTIFS(구역1!G4:G73,"대중교통",구역1!E4:E73,"*"&$B31&"*")+COUNTIFS(구역1!J4:J73,"*대중교통*",구역1!E4:E73,"*"&$B31&"*")=0,"",COUNTIFS(구역1!G4:G73,"대중교통",구역1!E4:E73,"*"&$B31&"*")+COUNTIFS(구역1!J4:J73,"*대중교통*",구역1!E4:E73,"*"&$B31&"*")) | L4: =IF(SUM(B4,D4,F4,H4,J4)=0,"",SUM(B4,D4,F4,H4,J4))
A5: 구역2 | B5: =IF(COUNTIFS(구역2!F4:F73,"1호차",구역2!E4:E73,"*"&$B31&"*")+COUNTIFS(구역2!F4:F73,"2호차",구역2!E4:E73,"*"&$B31&"*")+COUNTIFS(구역2!F4:F73,"3호차",구역2!E4:E73,"*"&$B31&"*")+COUNTIFS(구역2!F4:F73,"4호차",구역2!E4:E73,"*"&$B31&"*")+COUNTIFS(구역2!F4:F73,"5호차",구역2!E4:E73,"*"&$B31&"*")+COUNTIFS(구역2!F4:F73,"6호차",구역2!E4:E73,"*"&$B31&"*")+COUNTIFS(구역2!F4:F73,"7호차",구역2!E4:E73,"*"&$B31&"*")+COUNTIFS(구역2!F4:F73,"8호차",구역2!E4:E73,"*"&$B31&"*")+COUNTIFS(구역2!F4:F73,"9호차",구역2!E4:E73,"*"&$B31&"*")+COUNTIFS(구역2!F4:F73,"10호차",구역2!E4:E73,"*"&$B31&"*")=0,"",COUNTIFS(구역2!F4:F73,"1호차",구역2!E4:E73,"*"&$B31&"*")+COUNTIFS(구역2!F4:F73,"2호차",구역2!E4:E73,"*"&$B31&"*")+COUNTIFS(구역2!F4:F73,"3호차",구역2!E4:E73,"*"&$B31&"*")+COUNTIFS(구역2!F4:F73,"4호차",구역2!E4:E73,"*"&$B31&"*")+COUNTIFS(구역2!F4:F73,"5호차",구역2!E4:E73,"*"&$B31&"*")+COUNTIFS(구역2!F4:F73,"6호차",구역2!E4:E73,"*"&$B31&"*")+COUNTIFS(구역2!F4:F73,"7호차",구역2!E4:E73,"*"&$B31&"*")+COUNTIFS(구역2!F4:F73,"8호차",구역2!E4:E73,"*"&$B31&"*")+COUNTIFS(구역2!F4:F73,"9호차",구역2!E4:E73,"*"&$B31&"*")+COUNTIFS(구역2!F4:F73,"10호차",구역2!E4:E73,"*"&$B31&"*")) | C5: =IF(COUNTIFS(구역2!G4:G73,"1호차",구역2!E4:E73,"*"&$B31&"*")+COUNTIFS(구역2!G4:G73,"2호차",구역2!E4:E73,"*"&$B31&"*")+COUNTIFS(구역2!G4:G73,"3호차",구역2!E4:E73,"*"&$B31&"*")+COUNTIFS(구역2!G4:G73,"4호차",구역2!E4:E73,"*"&$B31&"*")+COUNTIFS(구역2!G4:G73,"5호차",구역2!E4:E73,"*"&$B31&"*")+COUNTIFS(구역2!G4:G73,"6호차",구역2!E4:E73,"*"&$B31&"*")+COUNTIFS(구역2!G4:G73,"7호차",구역2!E4:E73,"*"&$B31&"*")+COUNTIFS(구역2!G4:G73,"8호차",구역2!E4:E73,"*"&$B31&"*")+COUNTIFS(구역2!G4:G73,"9호차",구역2!E4:E73,"*"&$B31&"*")+COUNTIFS(구역2!G4:G73,"10호차",구역2!E4:E73,"*"&$B31&"*")=0,"",COUNTIFS(구역2!G4:G73,"1호차",구역2!E4:E73,"*"&$B31&"*")+COUNTIFS(구역2!G4:G73,"2호차",구역2!E4:E73,"*"&$B31&"*")+COUNTIFS(구역2!G4:G73,"3호차",구역2!E4:E73,"*"&$B31&"*")+COUNTIFS(구역2!G4:G73,"4호차",구역2!E4:E73,"*"&$B31&"*")+COUNTIFS(구역2!G4:G73,"5호차",구역2!E4:E73,"*"&$B31&"*")+COUNTIFS(구역2!G4:G73,"6호차",구역2!E4:E73,"*"&$B31&"*")+COUNTIFS(구역2!G4:G73,"7호차",구역2!E4:E73,"*"&$B31&"*")+COUNTIFS(구역2!G4:G73,"8호차",구역2!E4:E73,"*"&$B31&"*")+COUNTIFS(구역2!G4:G73,"9호차",구역2!E4:E73,"*"&$B31&"*")+COUNTIFS(구역2!G4:G73,"10호차",구역2!E4:E73,"*"&$B31&"*")) | D5: =IF(COUNTIFS(구역2!F4:F73,"교회차1",구역2!E4:E73,"*"&$B31&"*")+COUNTIFS(구역2!F4:F73,"교회차2",구역2!E4:E73,"*"&$B31&"*")+COUNTIFS(구역2!F4:F73,"교회차3",구역2!E4:E73,"*"&$B31&"*")+COUNTIFS(구역2!F4:F73,"교회차4",구역2!E4:E73,"*"&$B31&"*")+COUNTIFS(구역2!F4:F73,"교회차5",구역2!E4:E73,"*"&$B31&"*")+COUNTIFS(구역2!H4:H73,"*교회차*",구역2!E4:E73,"*"&$B31&"*")=0,"",COUNTIFS(구역2!F4:F73,"교회차1",구역2!E4:E73,"*"&$B31&"*")+COUNTIFS(구역2!F4:F73,"교회차2",구역2!E4:E73,"*"&$B31&"*")+COUNTIFS(구역2!F4:F73,"교회차3",구역2!E4:E73,"*"&$B31&"*")+COUNTIFS(구역2!F4:F73,"교회차4",구역2!E4:E73,"*"&$B31&"*")+COUNTIFS(구역2!F4:F73,"교회차5",구역2!E4:E73,"*"&$B31&"*")+COUNTIFS(구역2!H4:H73,"*교회차*",구역2!E4:E73,"*"&$B31&"*")) | E5: =IF(COUNTIFS(구역2!G4:G73,"교회차1",구역2!E4:E73,"*"&$B31&"*")+COUNTIFS(구역2!G4:G73,"교회차2",구역2!E4:E73,"*"&$B31&"*")+COUNTIFS(구역2!G4:G73,"교회차3",구역2!E4:E73,"*"&$B31&"*")+COUNTIFS(구역2!G4:G73,"교회차4",구역2!E4:E73,"*"&$B31&"*")+COUNTIFS(구역2!G4:G73,"교회차5",구역2!E4:E73,"*"&$B31&"*")+COUNTIFS(구역2!J4:J73,"*교회차*",구역2!E4:E73,"*"&$B31&"*")=0,"",COUNTIFS(구역2!G4:G73,"교회차1",구역2!E4:E73,"*"&$B31&"*")+COUNTIFS(구역2!G4:G73,"교회차2",구역2!E4:E73,"*"&$B31&"*")+COUNTIFS(구역2!G4:G73,"교회차3",구역2!E4:E73,"*"&$B31&"*")+COUNTIFS(구역2!G4:G73,"교회차4",구역2!E4:E73,"*"&$B31&"*")+COUNTIFS(구역2!G4:G73,"교회차5",구역2!E4:E73,"*"&$B31&"*")+COUNTIFS(구역2!J4:J73,"*교회차*",구역2!E4:E73,"*"&$B31&"*")) | F5: =IF(COUNTIFS(구역2!F4:F73,"타교회",구역2!E4:E73,"*"&$B31&"*")+COUNTIFS(구역2!H4:H73,"*타교회*",구역2!E4:E73,"*"&$B31&"*")=0,"",COUNTIFS(구역2!F4:F73,"타교회",구역2!E4:E73,"*"&$B31&"*")+COUNTIFS(구역2!H4:H73,"*타교회*",구역2!E4:E73,"*"&$B31&"*")) | G5: =IF(COUNTIFS(구역2!G4:G73,"타교회",구역2!E4:E73,"*"&$B31&"*")+COUNTIFS(구역2!J4:J73,"*타교회*",구역2!E4:E73,"*"&$B31&"*")=0,"",COUNTIFS(구역2!G4:G73,"타교회",구역2!E4:E73,"*"&$B31&"*")+COUNTIFS(구역2!J4:J73,"*타교회*",구역2!E4:E73,"*"&$B31&"*")) | H5: =IF(COUNTIFS(구역2!F4:F73,"개인차",구역2!E4:E73,"*"&$B31&"*")+(COUNTIFS(구역2!H4:H73,"?*",구역2!E4:E73,"*"&$B31&"*")-COUNTIFS(구역2!H4:H73,"*교회차*",구역2!E4:E73,"*"&$B31&"*")-COUNTIFS(구역2!H4:H73,"*타교회*",구역2!E4:E73,"*"&$B31&"*")-COUNTIFS(구역2!H4:H73,"*대중교통*",구역2!E4:E73,"*"&$B31&"*"))=0,"",COUNTIFS(구역2!F4:F73,"개인차",구역2!E4:E73,"*"&$B31&"*")+(COUNTIFS(구역2!H4:H73,"?*",구역2!E4:E73,"*"&$B31&"*")-COUNTIFS(구역2!H4:H73,"*교회차*",구역2!E4:E73,"*"&$B31&"*")-COUNTIFS(구역2!H4:H73,"*타교회*",구역2!E4:E73,"*"&$B31&"*")-COUNTIFS(구역2!H4:H73,"*대중교통*",구역2!E4:E73,"*"&$B31&"*"))) | I5: =IF(COUNTIFS(구역2!G4:G73,"개인차",구역2!E4:E73,"*"&$B31&"*")+(COUNTIFS(구역2!J4:J73,"?*",구역2!E4:E73,"*"&$B31&"*")-COUNTIFS(구역2!J4:J73,"*교회차*",구역2!E4:E73,"*"&$B31&"*")-COUNTIFS(구역2!J4:J73,"*타교회*",구역2!E4:E73,"*"&$B31&"*")-COUNTIFS(구역2!J4:J73,"*대중교통*",구역2!E4:E73,"*"&$B31&"*"))=0,"",COUNTIFS(구역2!G4:G73,"개인차",구역2!E4:E73,"*"&$B31&"*")+(COUNTIFS(구역2!J4:J73,"?*",구역2!E4:E73,"*"&$B31&"*")-COUNTIFS(구역2!J4:J73,"*교회차*",구역2!E4:E73,"*"&$B31&"*")-COUNTIFS(구역2!J4:J73,"*타교회*",구역2!E4:E73,"*"&$B31&"*")-COUNTIFS(구역2!J4:J73,"*대중교통*",구역2!E4:E73,"*"&$B31&"*"))) | J5: =IF(COUNTIFS(구역2!F4:F73,"대중교통",구역2!E4:E73,"*"&$B31&"*")+COUNTIFS(구역2!H4:H73,"*대중교통*",구역2!E4:E73,"*"&$B31&"*")=0,"",COUNTIFS(구역2!F4:F73,"대중교통",구역2!E4:E73,"*"&$B31&"*")+COUNTIFS(구역2!H4:H73,"*대중교통*",구역2!E4:E73,"*"&$B31&"*")) | K5: =IF(COUNTIFS(구역2!G4:G73,"대중교통",구역2!E4:E73,"*"&$B31&"*")+COUNTIFS(구역2!J4:J73,"*대중교통*",구역2!E4:E73,"*"&$B31&"*")=0,"",COUNTIFS(구역2!G4:G73,"대중교통",구역2!E4:E73,"*"&$B31&"*")+COUNTIFS(구역2!J4:J73,"*대중교통*",구역2!E4:E73,"*"&$B31&"*")) | L5: =IF(SUM(B5,D5,F5,H5,J5)=0,"",SUM(B5,D5,F5,H5,J5))
A6: 구역3 | B6: =IF(COUNTIFS(구역3!F4:F73,"1호차",구역3!E4:E73,"*"&$B31&"*")+COUNTIFS(구역3!F4:F73,"2호차",구역3!E4:E73,"*"&$B31&"*")+COUNTIFS(구역3!F4:F73,"3호차",구역3!E4:E73,"*"&$B31&"*")+COUNTIFS(구역3!F4:F73,"4호차",구역3!E4:E73,"*"&$B31&"*")+COUNTIFS(구역3!F4:F73,"5호차",구역3!E4:E73,"*"&$B31&"*")+COUNTIFS(구역3!F4:F73,"6호차",구역3!E4:E73,"*"&$B31&"*")+COUNTIFS(구역3!F4:F73,"7호차",구역3!E4:E73,"*"&$B31&"*")+COUNTIFS(구역3!F4:F73,"8호차",구역3!E4:E73,"*"&$B31&"*")+COUNTIFS(구역3!F4:F73,"9호차",구역3!E4:E73,"*"&$B31&"*")+COUNTIFS(구역3!F4:F73,"10호차",구역3!E4:E73,"*"&$B31&"*")=0,"",COUNTIFS(구역3!F4:F73,"1호차",구역3!E4:E73,"*"&$B31&"*")+COUNTIFS(구역3!F4:F73,"2호차",구역3!E4:E73,"*"&$B31&"*")+COUNTIFS(구역3!F4:F73,"3호차",구역3!E4:E73,"*"&$B31&"*")+COUNTIFS(구역3!F4:F73,"4호차",구역3!E4:E73,"*"&$B31&"*")+COUNTIFS(구역3!F4:F73,"5호차",구역3!E4:E73,"*"&$B31&"*")+COUNTIFS(구역3!F4:F73,"6호차",구역3!E4:E73,"*"&$B31&"*")+COUNTIFS(구역3!F4:F73,"7호차",구역3!E4:E73,"*"&$B31&"*")+COUNTIFS(구역3!F4:F73,"8호차",구역3!E4:E73,"*"&$B31&"*")+COUNTIFS(구역3!F4:F73,"9호차",구역3!E4:E73,"*"&$B31&"*")+COUNTIFS(구역3!F4:F73,"10호차",구역3!E4:E73,"*"&$B31&"*")) | C6: =IF(COUNTIFS(구역3!G4:G73,"1호차",구역3!E4:E73,"*"&$B31&"*")+COUNTIFS(구역3!G4:G73,"2호차",구역3!E4:E73,"*"&$B31&"*")+COUNTIFS(구역3!G4:G73,"3호차",구역3!E4:E73,"*"&$B31&"*")+COUNTIFS(구역3!G4:G73,"4호차",구역3!E4:E73,"*"&$B31&"*")+COUNTIFS(구역3!G4:G73,"5호차",구역3!E4:E73,"*"&$B31&"*")+COUNTIFS(구역3!G4:G73,"6호차",구역3!E4:E73,"*"&$B31&"*")+COUNTIFS(구역3!G4:G73,"7호차",구역3!E4:E73,"*"&$B31&"*")+COUNTIFS(구역3!G4:G73,"8호차",구역3!E4:E73,"*"&$B31&"*")+COUNTIFS(구역3!G4:G73,"9호차",구역3!E4:E73,"*"&$B31&"*")+COUNTIFS(구역3!G4:G73,"10호차",구역3!E4:E73,"*"&$B31&"*")=0,"",COUNTIFS(구역3!G4:G73,"1호차",구역3!E4:E73,"*"&$B31&"*")+COUNTIFS(구역3!G4:G73,"2호차",구역3!E4:E73,"*"&$B31&"*")+COUNTIFS(구역3!G4:G73,"3호차",구역3!E4:E73,"*"&$B31&"*")+COUNTIFS(구역3!G4:G73,"4호차",구역3!E4:E73,"*"&$B31&"*")+COUNTIFS(구역3!G4:G73,"5호차",구역3!E4:E73,"*"&$B31&"*")+COUNTIFS(구역3!G4:G73,"6호차",구역3!E4:E73,"*"&$B31&"*")+COUNTIFS(구역3!G4:G73,"7호차",구역3!E4:E73,"*"&$B31&"*")+COUNTIFS(구역3!G4:G73,"8호차",구역3!E4:E73,"*"&$B31&"*")+COUNTIFS(구역3!G4:G73,"9호차",구역3!E4:E73,"*"&$B31&"*")+COUNTIFS(구역3!G4:G73,"10호차",구역3!E4:E73,"*"&$B31&"*")) | D6: =IF(COUNTIFS(구역3!F4:F73,"교회차1",구역3!E4:E73,"*"&$B31&"*")+COUNTIFS(구역3!F4:F73,"교회차2",구역3!E4:E73,"*"&$B31&"*")+COUNTIFS(구역3!F4:F73,"교회차3",구역3!E4:E73,"*"&$B31&"*")+COUNTIFS(구역3!F4:F73,"교회차4",구역3!E4:E73,"*"&$B31&"*")+COUNTIFS(구역3!F4:F73,"교회차5",구역3!E4:E73,"*"&$B31&"*")+COUNTIFS(구역3!H4:H73,"*교회차*",구역3!E4:E73,"*"&$B31&"*")=0,"",COUNTIFS(구역3!F4:F73,"교회차1",구역3!E4:E73,"*"&$B31&"*")+COUNTIFS(구역3!F4:F73,"교회차2",구역3!E4:E73,"*"&$B31&"*")+COUNTIFS(구역3!F4:F73,"교회차3",구역3!E4:E73,"*"&$B31&"*")+COUNTIFS(구역3!F4:F73,"교회차4",구역3!E4:E73,"*"&$B31&"*")+COUNTIFS(구역3!F4:F73,"교회차5",구역3!E4:E73,"*"&$B31&"*")+COUNTIFS(구역3!H4:H73,"*교회차*",구역3!E4:E73,"*"&$B31&"*")) | E6: =IF(COUNTIFS(구역3!G4:G73,"교회차1",구역3!E4:E73,"*"&$B31&"*")+COUNTIFS(구역3!G4:G73,"교회차2",구역3!E4:E73,"*"&$B31&"*")+COUNTIFS(구역3!G4:G73,"교회차3",구역3!E4:E73,"*"&$B31&"*")+COUNTIFS(구역3!G4:G73,"교회차4",구역3!E4:E73,"*"&$B31&"*")+COUNTIFS(구역3!G4:G73,"교회차5",구역3!E4:E73,"*"&$B31&"*")+COUNTIFS(구역3!J4:J73,"*교회차*",구역3!E4:E73,"*"&$B31&"*")=0,"",COUNTIFS(구역3!G4:G73,"교회차1",구역3!E4:E73,"*"&$B31&"*")+COUNTIFS(구역3!G4:G73,"교회차2",구역3!E4:E73,"*"&$B31&"*")+COUNTIFS(구역3!G4:G73,"교회차3",구역3!E4:E73,"*"&$B31&"*")+COUNTIFS(구역3!G4:G73,"교회차4",구역3!E4:E73,"*"&$B31&"*")+COUNTIFS(구역3!G4:G73,"교회차5",구역3!E4:E73,"*"&$B31&"*")+COUNTIFS(구역3!J4:J73,"*교회차*",구역3!E4:E73,"*"&$B31&"*")) | F6: =IF(COUNTIFS(구역3!F4:F73,"타교회",구역3!E4:E73,"*"&$B31&"*")+COUNTIFS(구역3!H4:H73,"*타교회*",구역3!E4:E73,"*"&$B31&"*")=0,"",COUNTIFS(구역3!F4:F73,"타교회",구역3!E4:E73,"*"&$B31&"*")+COUNTIFS(구역3!H4:H73,"*타교회*",구역3!E4:E73,"*"&$B31&"*")) | G6: =IF(COUNTIFS(구역3!G4:G73,"타교회",구역3!E4:E73,"*"&$B31&"*")+COUNTIFS(구역3!J4:J73,"*타교회*",구역3!E4:E73,"*"&$B31&"*")=0,"",COUNTIFS(구역3!G4:G73,"타교회",구역3!E4:E73,"*"&$B31&"*")+COUNTIFS(구역3!J4:J73,"*타교회*",구역3!E4:E73,"*"&$B31&"*")) | H6: =IF(COUNTIFS(구역3!F4:F73,"개인차",구역3!E4:E73,"*"&$B31&"*")+(COUNTIFS(구역3!H4:H73,"?*",구역3!E4:E73,"*"&$B31&"*")-COUNTIFS(구역3!H4:H73,"*교회차*",구역3!E4:E73,"*"&$B31&"*")-COUNTIFS(구역3!H4:H73,"*타교회*",구역3!E4:E73,"*"&$B31&"*")-COUNTIFS(구역3!H4:H73,"*대중교통*",구역3!E4:E73,"*"&$B31&"*"))=0,"",COUNTIFS(구역3!F4:F73,"개인차",구역3!E4:E73,"*"&$B31&"*")+(COUNTIFS(구역3!H4:H73,"?*",구역3!E4:E73,"*"&$B31&"*")-COUNTIFS(구역3!H4:H73,"*교회차*",구역3!E4:E73,"*"&$B31&"*")-COUNTIFS(구역3!H4:H73,"*타교회*",구역3!E4:E73,"*"&$B31&"*")-COUNTIFS(구역3!H4:H73,"*대중교통*",구역3!E4:E73,"*"&$B31&"*"))) | I6: =IF(COUNTIFS(구역3!G4:G73,"개인차",구역3!E4:E73,"*"&$B31&"*")+(COUNTIFS(구역3!J4:J73,"?*",구역3!E4:E73,"*"&$B31&"*")-COUNTIFS(구역3!J4:J73,"*교회차*",구역3!E4:E73,"*"&$B31&"*")-COUNTIFS(구역3!J4:J73,"*타교회*",구역3!E4:E73,"*"&$B31&"*")-COUNTIFS(구역3!J4:J73,"*대중교통*",구역3!E4:E73,"*"&$B31&"*"))=0,"",COUNTIFS(구역3!G4:G73,"개인차",구역3!E4:E73,"*"&$B31&"*")+(COUNTIFS(구역3!J4:J73,"?*",구역3!E4:E73,"*"&$B31&"*")-COUNTIFS(구역3!J4:J73,"*교회차*",구역3!E4:E73,"*"&$B31&"*")-COUNTIFS(구역3!J4:J73,"*타교회*",구역3!E4:E73,"*"&$B31&"*")-COUNTIFS(구역3!J4:J73,"*대중교통*",구역3!E4:E73,"*"&$B31&"*"))) | J6: =IF(COUNTIFS(구역3!F4:F73,"대중교통",구역3!E4:E73,"*"&$B31&"*")+COUNTIFS(구역3!H4:H73,"*대중교통*",구역3!E4:E73,"*"&$B31&"*")=0,"",COUNTIFS(구역3!F4:F73,"대중교통",구역3!E4:E73,"*"&$B31&"*")+COUNTIFS(구역3!H4:H73,"*대중교통*",구역3!E4:E73,"*"&$B31&"*")) | K6: =IF(COUNTIFS(구역3!G4:G73,"대중교통",구역3!E4:E73,"*"&$B31&"*")+COUNTIFS(구역3!J4:J73,"*대중교통*",구역3!E4:E73,"*"&$B31&"*")=0,"",COUNTIFS(구역3!G4:G73,"대중교통",구역3!E4:E73,"*"&$B31&"*")+COUNTIFS(구역3!J4:J73,"*대중교통*",구역3!E4:E73,"*"&$B31&"*")) | L6: =IF(SUM(B6,D6,F6,H6,J6)=0,"",SUM(B6,D6,F6,H6,J6))
A7: 구역4 | B7: =IF(COUNTIFS(구역4!F4:F73,"1호차",구역4!E4:E73,"*"&$B31&"*")+COUNTIFS(구역4!F4:F73,"2호차",구역4!E4:E73,"*"&$B31&"*")+COUNTIFS(구역4!F4:F73,"3호차",구역4!E4:E73,"*"&$B31&"*")+COUNTIFS(구역4!F4:F73,"4호차",구역4!E4:E73,"*"&$B31&"*")+COUNTIFS(구역4!F4:F73,"5호차",구역4!E4:E73,"*"&$B31&"*")+COUNTIFS(구역4!F4:F73,"6호차",구역4!E4:E73,"*"&$B31&"*")+COUNTIFS(구역4!F4:F73,"7호차",구역4!E4:E73,"*"&$B31&"*")+COUNTIFS(구역4!F4:F73,"8호차",구역4!E4:E73,"*"&$B31&"*")+COUNTIFS(구역4!F4:F73,"9호차",구역4!E4:E73,"*"&$B31&"*")+COUNTIFS(구역4!F4:F73,"10호차",구역4!E4:E73,"*"&$B31&"*")=0,"",COUNTIFS(구역4!F4:F73,"1호차",구역4!E4:E73,"*"&$B31&"*")+COUNTIFS(구역4!F4:F73,"2호차",구역4!E4:E73,"*"&$B31&"*")+COUNTIFS(구역4!F4:F73,"3호차",구역4!E4:E73,"*"&$B31&"*")+COUNTIFS(구역4!F4:F73,"4호차",구역4!E4:E73,"*"&$B31&"*")+COUNTIFS(구역4!F4:F73,"5호차",구역4!E4:E73,"*"&$B31&"*")+COUNTIFS(구역4!F4:F73,"6호차",구역4!E4:E73,"*"&$B31&"*")+COUNTIFS(구역4!F4:F73,"7호차",구역4!E4:E73,"*"&$B31&"*")+COUNTIFS(구역4!F4:F73,"8호차",구역4!E4:E73,"*"&$B31&"*")+COUNTIFS(구역4!F4:F73,"9호차",구역4!E4:E73,"*"&$B31&"*")+COUNTIFS(구역4!F4:F73,"10호차",구역4!E4:E73,"*"&$B31&"*")) | C7: =IF(COUNTIFS(구역4!G4:G73,"1호차",구역4!E4:E73,"*"&$B31&"*")+COUNTIFS(구역4!G4:G73,"2호차",구역4!E4:E73,"*"&$B31&"*")+COUNTIFS(구역4!G4:G73,"3호차",구역4!E4:E73,"*"&$B31&"*")+COUNTIFS(구역4!G4:G73,"4호차",구역4!E4:E73,"*"&$B31&"*")+COUNTIFS(구역4!G4:G73,"5호차",구역4!E4:E73,"*"&$B31&"*")+COUNTIFS(구역4!G4:G73,"6호차",구역4!E4:E73,"*"&$B31&"*")+COUNTIFS(구역4!G4:G73,"7호차",구역4!E4:E73,"*"&$B31&"*")+COUNTIFS(구역4!G4:G73,"8호차",구역4!E4:E73,"*"&$B31&"*")+COUNTIFS(구역4!G4:G73,"9호차",구역4!E4:E73,"*"&$B31&"*")+COUNTIFS(구역4!G4:G73,"10호차",구역4!E4:E73,"*"&$B31&"*")=0,"",COUNTIFS(구역4!G4:G73,"1호차",구역4!E4:E73,"*"&$B31&"*")+COUNTIFS(구역4!G4:G73,"2호차",구역4!E4:E73,"*"&$B31&"*")+COUNTIFS(구역4!G4:G73,"3호차",구역4!E4:E73,"*"&$B31&"*")+COUNTIFS(구역4!G4:G73,"4호차",구역4!E4:E73,"*"&$B31&"*")+COUNTIFS(구역4!G4:G73,"5호차",구역4!E4:E73,"*"&$B31&"*")+COUNTIFS(구역4!G4:G73,"6호차",구역4!E4:E73,"*"&$B31&"*")+COUNTIFS(구역4!G4:G73,"7호차",구역4!E4:E73,"*"&$B31&"*")+COUNTIFS(구역4!G4:G73,"8호차",구역4!E4:E73,"*"&$B31&"*")+COUNTIFS(구역4!G4:G73,"9호차",구역4!E4:E73,"*"&$B31&"*")+COUNTIFS(구역4!G4:G73,"10호차",구역4!E4:E73,"*"&$B31&"*")) | D7: =IF(COUNTIFS(구역4!F4:F73,"교회차1",구역4!E4:E73,"*"&$B31&"*")+COUNTIFS(구역4!F4:F73,"교회차2",구역4!E4:E73,"*"&$B31&"*")+COUNTIFS(구역4!F4:F73,"교회차3",구역4!E4:E73,"*"&$B31&"*")+COUNTIFS(구역4!F4:F73,"교회차4",구역4!E4:E73,"*"&$B31&"*")+COUNTIFS(구역4!F4:F73,"교회차5",구역4!E4:E73,"*"&$B31&"*")+COUNTIFS(구역4!H4:H73,"*교회차*",구역4!E4:E73,"*"&$B31&"*")=0,"",COUNTIFS(구역4!F4:F73,"교회차1",구역4!E4:E73,"*"&$B31&"*")+COUNTIFS(구역4!F4:F73,"교회차2",구역4!E4:E73,"*"&$B31&"*")+COUNTIFS(구역4!F4:F73,"교회차3",구역4!E4:E73,"*"&$B31&"*")+COUNTIFS(구역4!F4:F73,"교회차4",구역4!E4:E73,"*"&$B31&"*")+COUNTIFS(구역4!F4:F73,"교회차5",구역4!E4:E73,"*"&$B31&"*")+COUNTIFS(구역4!H4:H73,"*교회차*",구역4!E4:E73,"*"&$B31&"*")) | E7: =IF(COUNTIFS(구역4!G4:G73,"교회차1",구역4!E4:E73,"*"&$B31&"*")+COUNTIFS(구역4!G4:G73,"교회차2",구역4!E4:E73,"*"&$B31&"*")+COUNTIFS(구역4!G4:G73,"교회차3",구역4!E4:E73,"*"&$B31&"*")+COUNTIFS(구역4!G4:G73,"교회차4",구역4!E4:E73,"*"&$B31&"*")+COUNTIFS(구역4!G4:G73,"교회차5",구역4!E4:E73,"*"&$B31&"*")+COUNTIFS(구역4!J4:J73,"*교회차*",구역4!E4:E73,"*"&$B31&"*")=0,"",COUNTIFS(구역4!G4:G73,"교회차1",구역4!E4:E73,"*"&$B31&"*")+COUNTIFS(구역4!G4:G73,"교회차2",구역4!E4:E73,"*"&$B31&"*")+COUNTIFS(구역4!G4:G73,"교회차3",구역4!E4:E73,"*"&$B31&"*")+COUNTIFS(구역4!G4:G73,"교회차4",구역4!E4:E73,"*"&$B31&"*")+COUNTIFS(구역4!G4:G73,"교회차5",구역4!E4:E73,"*"&$B31&"*")+COUNTIFS(구역4!J4:J73,"*교회차*",구역4!E4:E73,"*"&$B31&"*")) | F7: =IF(COUNTIFS(구역4!F4:F73,"타교회",구역4!E4:E73,"*"&$B31&"*")+COUNTIFS(구역4!H4:H73,"*타교회*",구역4!E4:E73,"*"&$B31&"*")=0,"",COUNTIFS(구역4!F4:F73,"타교회",구역4!E4:E73,"*"&$B31&"*")+COUNTIFS(구역4!H4:H73,"*타교회*",구역4!E4:E73,"*"&$B31&"*")) | G7: =IF(COUNTIFS(구역4!G4:G73,"타교회",구역4!E4:E73,"*"&$B31&"*")+COUNTIFS(구역4!J4:J73,"*타교회*",구역4!E4:E73,"*"&$B31&"*")=0,"",COUNTIFS(구역4!G4:G73,"타교회",구역4!E4:E73,"*"&$B31&"*")+COUNTIFS(구역4!J4:J73,"*타교회*",구역4!E4:E73,"*"&$B31&"*")) | H7: =IF(COUNTIFS(구역4!F4:F73,"개인차",구역4!E4:E73,"*"&$B31&"*")+(COUNTIFS(구역4!H4:H73,"?*",구역4!E4:E73,"*"&$B31&"*")-COUNTIFS(구역4!H4:H73,"*교회차*",구역4!E4:E73,"*"&$B31&"*")-COUNTIFS(구역4!H4:H73,"*타교회*",구역4!E4:E73,"*"&$B31&"*")-COUNTIFS(구역4!H4:H73,"*대중교통*",구역4!E4:E73,"*"&$B31&"*"))=0,"",COUNTIFS(구역4!F4:F73,"개인차",구역4!E4:E73,"*"&$B31&"*")+(COUNTIFS(구역4!H4:H73,"?*",구역4!E4:E73,"*"&$B31&"*")-COUNTIFS(구역4!H4:H73,"*교회차*",구역4!E4:E73,"*"&$B31&"*")-COUNTIFS(구역4!H4:H73,"*타교회*",구역4!E4:E73,"*"&$B31&"*")-COUNTIFS(구역4!H4:H73,"*대중교통*",구역4!E4:E73,"*"&$B31&"*"))) | I7: =IF(COUNTIFS(구역4!G4:G73,"개인차",구역4!E4:E73,"*"&$B31&"*")+(COUNTIFS(구역4!J4:J73,"?*",구역4!E4:E73,"*"&$B31&"*")-COUNTIFS(구역4!J4:J73,"*교회차*",구역4!E4:E73,"*"&$B31&"*")-COUNTIFS(구역4!J4:J73,"*타교회*",구역4!E4:E73,"*"&$B31&"*")-COUNTIFS(구역4!J4:J73,"*대중교통*",구역4!E4:E73,"*"&$B31&"*"))=0,"",COUNTIFS(구역4!G4:G73,"개인차",구역4!E4:E73,"*"&$B31&"*")+(COUNTIFS(구역4!J4:J73,"?*",구역4!E4:E73,"*"&$B31&"*")-COUNTIFS(구역4!J4:J73,"*교회차*",구역4!E4:E73,"*"&$B31&"*")-COUNTIFS(구역4!J4:J73,"*타교회*",구역4!E4:E73,"*"&$B31&"*")-COUNTIFS(구역4!J4:J73,"*대중교통*",구역4!E4:E73,"*"&$B31&"*"))) | J7: =IF(COUNTIFS(구역4!F4:F73,"대중교통",구역4!E4:E73,"*"&$B31&"*")+COUNTIFS(구역4!H4:H73,"*대중교통*",구역4!E4:E73,"*"&$B31&"*")=0,"",COUNTIFS(구역4!F4:F73,"대중교통",구역4!E4:E73,"*"&$B31&"*")+COUNTIFS(구역4!H4:H73,"*대중교통*",구역4!E4:E73,"*"&$B31&"*")) | K7: =IF(COUNTIFS(구역4!G4:G73,"대중교통",구역4!E4:E73,"*"&$B31&"*")+COUNTIFS(구역4!J4:J73,"*대중교통*",구역4!E4:E73,"*"&$B31&"*")=0,"",COUNTIFS(구역4!G4:G73,"대중교통",구역4!E4:E73,"*"&$B31&"*")+COUNTIFS(구역4!J4:J73,"*대중교통*",구역4!E4:E73,"*"&$B31&"*")) | L7: =IF(SUM(B7,D7,F7,H7,J7)=0,"",SUM(B7,D7,F7,H7,J7))
A8: 구역5 | B8: =IF(COUNTIFS(구역5!F4:F73,"1호차",구역5!E4:E73,"*"&$B31&"*")+COUNTIFS(구역5!F4:F73,"2호차",구역5!E4:E73,"*"&$B31&"*")+COUNTIFS(구역5!F4:F73,"3호차",구역5!E4:E73,"*"&$B31&"*")+COUNTIFS(구역5!F4:F73,"4호차",구역5!E4:E73,"*"&$B31&"*")+COUNTIFS(구역5!F4:F73,"5호차",구역5!E4:E73,"*"&$B31&"*")+COUNTIFS(구역5!F4:F73,"6호차",구역5!E4:E73,"*"&$B31&"*")+COUNTIFS(구역5!F4:F73,"7호차",구역5!E4:E73,"*"&$B31&"*")+COUNTIFS(구역5!F4:F73,"8호차",구역5!E4:E73,"*"&$B31&"*")+COUNTIFS(구역5!F4:F73,"9호차",구역5!E4:E73,"*"&$B31&"*")+COUNTIFS(구역5!F4:F73,"10호차",구역5!E4:E73,"*"&$B31&"*")=0,"",COUNTIFS(구역5!F4:F73,"1호차",구역5!E4:E73,"*"&$B31&"*")+COUNTIFS(구역5!F4:F73,"2호차",구역5!E4:E73,"*"&$B31&"*")+COUNTIFS(구역5!F4:F73,"3호차",구역5!E4:E73,"*"&$B31&"*")+COUNTIFS(구역5!F4:F73,"4호차",구역5!E4:E73,"*"&$B31&"*")+COUNTIFS(구역5!F4:F73,"5호차",구역5!E4:E73,"*"&$B31&"*")+COUNTIFS(구역5!F4:F73,"6호차",구역5!E4:E73,"*"&$B31&"*")+COUNTIFS(구역5!F4:F73,"7호차",구역5!E4:E73,"*"&$B31&"*")+COUNTIFS(구역5!F4:F73,"8호차",구역5!E4:E73,"*"&$B31&"*")+COUNTIFS(구역5!F4:F73,"9호차",구역5!E4:E73,"*"&$B31&"*")+COUNTIFS(구역5!F4:F73,"10호차",구역5!E4:E73,"*"&$B31&"*")) | C8: =IF(COUNTIFS(구역5!G4:G73,"1호차",구역5!E4:E73,"*"&$B31&"*")+COUNTIFS(구역5!G4:G73,"2호차",구역5!E4:E73,"*"&$B31&"*")+COUNTIFS(구역5!G4:G73,"3호차",구역5!E4:E73,"*"&$B31&"*")+COUNTIFS(구역5!G4:G73,"4호차",구역5!E4:E73,"*"&$B31&"*")+COUNTIFS(구역5!G4:G73,"5호차",구역5!E4:E73,"*"&$B31&"*")+COUNTIFS(구역5!G4:G73,"6호차",구역5!E4:E73,"*"&$B31&"*")+COUNTIFS(구역5!G4:G73,"7호차",구역5!E4:E73,"*"&$B31&"*")+COUNTIFS(구역5!G4:G73,"8호차",구역5!E4:E73,"*"&$B31&"*")+COUNTIFS(구역5!G4:G73,"9호차",구역5!E4:E73,"*"&$B31&"*")+COUNTIFS(구역5!G4:G73,"10호차",구역5!E4:E73,"*"&$B31&"*")=0,"",COUNTIFS(구역5!G4:G73,"1호차",구역5!E4:E73,"*"&$B31&"*")+COUNTIFS(구역5!G4:G73,"2호차",구역5!E4:E73,"*"&$B31&"*")+COUNTIFS(구역5!G4:G73,"3호차",구역5!E4:E73,"*"&$B31&"*")+COUNTIFS(구역5!G4:G73,"4호차",구역5!E4:E73,"*"&$B31&"*")+COUNTIFS(구역5!G4:G73,"5호차",구역5!E4:E73,"*"&$B31&"*")+COUNTIFS(구역5!G4:G73,"6호차",구역5!E4:E73,"*"&$B31&"*")+COUNTIFS(구역5!G4:G73,"7호차",구역5!E4:E73,"*"&$B31&"*")+COUNTIFS(구역5!G4:G73,"8호차",구역5!E4:E73,"*"&$B31&"*")+COUNTIFS(구역5!G4:G73,"9호차",구역5!E4:E73,"*"&$B31&"*")+COUNTIFS(구역5!G4:G73,"10호차",구역5!E4:E73,"*"&$B31&"*")) | D8: =IF(COUNTIFS(구역5!F4:F73,"교회차1",구역5!E4:E73,"*"&$B31&"*")+COUNTIFS(구역5!F4:F73,"교회차2",구역5!E4:E73,"*"&$B31&"*")+COUNTIFS(구역5!F4:F73,"교회차3",구역5!E4:E73,"*"&$B31&"*")+COUNTIFS(구역5!F4:F73,"교회차4",구역5!E4:E73,"*"&$B31&"*")+COUNTIFS(구역5!F4:F73,"교회차5",구역5!E4:E73,"*"&$B31&"*")+COUNTIFS(구역5!H4:H73,"*교회차*",구역5!E4:E73,"*"&$B31&"*")=0,"",COUNTIFS(구역5!F4:F73,"교회차1",구역5!E4:E73,"*"&$B31&"*")+COUNTIFS(구역5!F4:F73,"교회차2",구역5!E4:E73,"*"&$B31&"*")+COUNTIFS(구역5!F4:F73,"교회차3",구역5!E4:E73,"*"&$B31&"*")+COUNTIFS(구역5!F4:F73,"교회차4",구역5!E4:E73,"*"&$B31&"*")+COUNTIFS(구역5!F4:F73,"교회차5",구역5!E4:E73,"*"&$B31&"*")+COUNTIFS(구역5!H4:H73,"*교회차*",구역5!E4:E73,"*"&$B31&"*")) | E8: =IF(COUNTIFS(구역5!G4:G73,"교회차1",구역5!E4:E73,"*"&$B31&"*")+COUNTIFS(구역5!G4:G73,"교회차2",구역5!E4:E73,"*"&$B31&"*")+COUNTIFS(구역5!G4:G73,"교회차3",구역5!E4:E73,"*"&$B31&"*")+COUNTIFS(구역5!G4:G73,"교회차4",구역5!E4:E73,"*"&$B31&"*")+COUNTIFS(구역5!G4:G73,"교회차5",구역5!E4:E73,"*"&$B31&"*")+COUNTIFS(구역5!J4:J73,"*교회차*",구역5!E4:E73,"*"&$B31&"*")=0,"",COUNTIFS(구역5!G4:G73,"교회차1",구역5!E4:E73,"*"&$B31&"*")+COUNTIFS(구역5!G4:G73,"교회차2",구역5!E4:E73,"*"&$B31&"*")+COUNTIFS(구역5!G4:G73,"교회차3",구역5!E4:E73,"*"&$B31&"*")+COUNTIFS(구역5!G4:G73,"교회차4",구역5!E4:E73,"*"&$B31&"*")+COUNTIFS(구역5!G4:G73,"교회차5",구역5!E4:E73,"*"&$B31&"*")+COUNTIFS(구역5!J4:J73,"*교회차*",구역5!E4:E73,"*"&$B31&"*")) | F8: =IF(COUNTIFS(구역5!F4:F73,"타교회",구역5!E4:E73,"*"&$B31&"*")+COUNTIFS(구역5!H4:H73,"*타교회*",구역5!E4:E73,"*"&$B31&"*")=0,"",COUNTIFS(구역5!F4:F73,"타교회",구역5!E4:E73,"*"&$B31&"*")+COUNTIFS(구역5!H4:H73,"*타교회*",구역5!E4:E73,"*"&$B31&"*")) | G8: =IF(COUNTIFS(구역5!G4:G73,"타교회",구역5!E4:E73,"*"&$B31&"*")+COUNTIFS(구역5!J4:J73,"*타교회*",구역5!E4:E73,"*"&$B31&"*")=0,"",COUNTIFS(구역5!G4:G73,"타교회",구역5!E4:E73,"*"&$B31&"*")+COUNTIFS(구역5!J4:J73,"*타교회*",구역5!E4:E73,"*"&$B31&"*")) | H8: =IF(COUNTIFS(구역5!F4:F73,"개인차",구역5!E4:E73,"*"&$B31&"*")+(COUNTIFS(구역5!H4:H73,"?*",구역5!E4:E73,"*"&$B31&"*")-COUNTIFS(구역5!H4:H73,"*교회차*",구역5!E4:E73,"*"&$B31&"*")-COUNTIFS(구역5!H4:H73,"*타교회*",구역5!E4:E73,"*"&$B31&"*")-COUNTIFS(구역5!H4:H73,"*대중교통*",구역5!E4:E73,"*"&$B31&"*"))=0,"",COUNTIFS(구역5!F4:F73,"개인차",구역5!E4:E73,"*"&$B31&"*")+(COUNTIFS(구역5!H4:H73,"?*",구역5!E4:E73,"*"&$B31&"*")-COUNTIFS(구역5!H4:H73,"*교회차*",구역5!E4:E73,"*"&$B31&"*")-COUNTIFS(구역5!H4:H73,"*타교회*",구역5!E4:E73,"*"&$B31&"*")-COUNTIFS(구역5!H4:H73,"*대중교통*",구역5!E4:E73,"*"&$B31&"*"))) | I8: =IF(COUNTIFS(구역5!G4:G73,"개인차",구역5!E4:E73,"*"&$B31&"*")+(COUNTIFS(구역5!J4:J73,"?*",구역5!E4:E73,"*"&$B31&"*")-COUNTIFS(구역5!J4:J73,"*교회차*",구역5!E4:E73,"*"&$B31&"*")-COUNTIFS(구역5!J4:J73,"*타교회*",구역5!E4:E73,"*"&$B31&"*")-COUNTIFS(구역5!J4:J73,"*대중교통*",구역5!E4:E73,"*"&$B31&"*"))=0,"",COUNTIFS(구역5!G4:G73,"개인차",구역5!E4:E73,"*"&$B31&"*")+(COUNTIFS(구역5!J4:J73,"?*",구역5!E4:E73,"*"&$B31&"*")-COUNTIFS(구역5!J4:J73,"*교회차*",구역5!E4:E73,"*"&$B31&"*")-COUNTIFS(구역5!J4:J73,"*타교회*",구역5!E4:E73,"*"&$B31&"*")-COUNTIFS(구역5!J4:J73,"*대중교통*",구역5!E4:E73,"*"&$B31&"*"))) | J8: =IF(COUNTIFS(구역5!F4:F73,"대중교통",구역5!E4:E73,"*"&$B31&"*")+COUNTIFS(구역5!H4:H73,"*대중교통*",구역5!E4:E73,"*"&$B31&"*")=0,"",COUNTIFS(구역5!F4:F73,"대중교통",구역5!E4:E73,"*"&$B31&"*")+COUNTIFS(구역5!H4:H73,"*대중교통*",구역5!E4:E73,"*"&$B31&"*")) | K8: =IF(COUNTIFS(구역5!G4:G73,"대중교통",구역5!E4:E73,"*"&$B31&"*")+COUNTIFS(구역5!J4:J73,"*대중교통*",구역5!E4:E73,"*"&$B31&"*")=0,"",COUNTIFS(구역5!G4:G73,"대중교통",구역5!E4:E73,"*"&$B31&"*")+COUNTIFS(구역5!J4:J73,"*대중교통*",구역5!E4:E73,"*"&$B31&"*")) | L8: =IF(SUM(B8,D8,F8,H8,J8)=0,"",SUM(B8,D8,F8,H8,J8))
A9: 구역6 | B9: =IF(COUNTIFS(구역6!F4:F73,"1호차",구역6!E4:E73,"*"&$B31&"*")+COUNTIFS(구역6!F4:F73,"2호차",구역6!E4:E73,"*"&$B31&"*")+COUNTIFS(구역6!F4:F73,"3호차",구역6!E4:E73,"*"&$B31&"*")+COUNTIFS(구역6!F4:F73,"4호차",구역6!E4:E73,"*"&$B31&"*")+COUNTIFS(구역6!F4:F73,"5호차",구역6!E4:E73,"*"&$B31&"*")+COUNTIFS(구역6!F4:F73,"6호차",구역6!E4:E73,"*"&$B31&"*")+COUNTIFS(구역6!F4:F73,"7호차",구역6!E4:E73,"*"&$B31&"*")+COUNTIFS(구역6!F4:F73,"8호차",구역6!E4:E73,"*"&$B31&"*")+COUNTIFS(구역6!F4:F73,"9호차",구역6!E4:E73,"*"&$B31&"*")+COUNTIFS(구역6!F4:F73,"10호차",구역6!E4:E73,"*"&$B31&"*")=0,"",COUNTIFS(구역6!F4:F73,"1호차",구역6!E4:E73,"*"&$B31&"*")+COUNTIFS(구역6!F4:F73,"2호차",구역6!E4:E73,"*"&$B31&"*")+COUNTIFS(구역6!F4:F73,"3호차",구역6!E4:E73,"*"&$B31&"*")+COUNTIFS(구역6!F4:F73,"4호차",구역6!E4:E73,"*"&$B31&"*")+COUNTIFS(구역6!F4:F73,"5호차",구역6!E4:E73,"*"&$B31&"*")+COUNTIFS(구역6!F4:F73,"6호차",구역6!E4:E73,"*"&$B31&"*")+COUNTIFS(구역6!F4:F73,"7호차",구역6!E4:E73,"*"&$B31&"*")+COUNTIFS(구역6!F4:F73,"8호차",구역6!E4:E73,"*"&$B31&"*")+COUNTIFS(구역6!F4:F73,"9호차",구역6!E4:E73,"*"&$B31&"*")+COUNTIFS(구역6!F4:F73,"10호차",구역6!E4:E73,"*"&$B31&"*")) | C9: =IF(COUNTIFS(구역6!G4:G73,"1호차",구역6!E4:E73,"*"&$B31&"*")+COUNTIFS(구역6!G4:G73,"2호차",구역6!E4:E73,"*"&$B31&"*")+COUNTIFS(구역6!G4:G73,"3호차",구역6!E4:E73,"*"&$B31&"*")+COUNTIFS(구역6!G4:G73,"4호차",구역6!E4:E73,"*"&$B31&"*")+COUNTIFS(구역6!G4:G73,"5호차",구역6!E4:E73,"*"&$B31&"*")+COUNTIFS(구역6!G4:G73,"6호차",구역6!E4:E73,"*"&$B31&"*")+COUNTIFS(구역6!G4:G73,"7호차",구역6!E4:E73,"*"&$B31&"*")+COUNTIFS(구역6!G4:G73,"8호차",구역6!E4:E73,"*"&$B31&"*")+COUNTIFS(구역6!G4:G73,"9호차",구역6!E4:E73,"*"&$B31&"*")+COUNTIFS(구역6!G4:G73,"10호차",구역6!E4:E73,"*"&$B31&"*")=0,"",COUNTIFS(구역6!G4:G73,"1호차",구역6!E4:E73,"*"&$B31&"*")+COUNTIFS(구역6!G4:G73,"2호차",구역6!E4:E73,"*"&$B31&"*")+COUNTIFS(구역6!G4:G73,"3호차",구역6!E4:E73,"*"&$B31&"*")+COUNTIFS(구역6!G4:G73,"4호차",구역6!E4:E73,"*"&$B31&"*")+COUNTIFS(구역6!G4:G73,"5호차",구역6!E4:E73,"*"&$B31&"*")+COUNTIFS(구역6!G4:G73,"6호차",구역6!E4:E73,"*"&$B31&"*")+COUNTIFS(구역6!G4:G73,"7호차",구역6!E4:E73,"*"&$B31&"*")+COUNTIFS(구역6!G4:G73,"8호차",구역6!E4:E73,"*"&$B31&"*")+COUNTIFS(구역6!G4:G73,"9호차",구역6!E4:E73,"*"&$B31&"*")+COUNTIFS(구역6!G4:G73,"10호차",구역6!E4:E73,"*"&$B31&"*")) | D9: =IF(COUNTIFS(구역6!F4:F73,"교회차1",구역6!E4:E73,"*"&$B31&"*")+COUNTIFS(구역6!F4:F73,"교회차2",구역6!E4:E73,"*"&$B31&"*")+COUNTIFS(구역6!F4:F73,"교회차3",구역6!E4:E73,"*"&$B31&"*")+COUNTIFS(구역6!F4:F73,"교회차4",구역6!E4:E73,"*"&$B31&"*")+COUNTIFS(구역6!F4:F73,"교회차5",구역6!E4:E73,"*"&$B31&"*")+COUNTIFS(구역6!H4:H73,"*교회차*",구역6!E4:E73,"*"&$B31&"*")=0,"",COUNTIFS(구역6!F4:F73,"교회차1",구역6!E4:E73,"*"&$B31&"*")+COUNTIFS(구역6!F4:F73,"교회차2",구역6!E4:E73,"*"&$B31&"*")+COUNTIFS(구역6!F4:F73,"교회차3",구역6!E4:E73,"*"&$B31&"*")+COUNTIFS(구역6!F4:F73,"교회차4",구역6!E4:E73,"*"&$B31&"*")+COUNTIFS(구역6!F4:F73,"교회차5",구역6!E4:E73,"*"&$B31&"*")+COUNTIFS(구역6!H4:H73,"*교회차*",구역6!E4:E73,"*"&$B31&"*")) | E9: =IF(COUNTIFS(구역6!G4:G73,"교회차1",구역6!E4:E73,"*"&$B31&"*")+COUNTIFS(구역6!G4:G73,"교회차2",구역6!E4:E73,"*"&$B31&"*")+COUNTIFS(구역6!G4:G73,"교회차3",구역6!E4:E73,"*"&$B31&"*")+COUNTIFS(구역6!G4:G73,"교회차4",구역6!E4:E73,"*"&$B31&"*")+COUNTIFS(구역6!G4:G73,"교회차5",구역6!E4:E73,"*"&$B31&"*")+COUNTIFS(구역6!J4:J73,"*교회차*",구역6!E4:E73,"*"&$B31&"*")=0,"",COUNTIFS(구역6!G4:G73,"교회차1",구역6!E4:E73,"*"&$B31&"*")+COUNTIFS(구역6!G4:G73,"교회차2",구역6!E4:E73,"*"&$B31&"*")+COUNTIFS(구역6!G4:G73,"교회차3",구역6!E4:E73,"*"&$B31&"*")+COUNTIFS(구역6!G4:G73,"교회차4",구역6!E4:E73,"*"&$B31&"*")+COUNTIFS(구역6!G4:G73,"교회차5",구역6!E4:E73,"*"&$B31&"*")+COUNTIFS(구역6!J4:J73,"*교회차*",구역6!E4:E73,"*"&$B31&"*")) | F9: =IF(COUNTIFS(구역6!F4:F73,"타교회",구역6!E4:E73,"*"&$B31&"*")+COUNTIFS(구역6!H4:H73,"*타교회*",구역6!E4:E73,"*"&$B31&"*")=0,"",COUNTIFS(구역6!F4:F73,"타교회",구역6!E4:E73,"*"&$B31&"*")+COUNTIFS(구역6!H4:H73,"*타교회*",구역6!E4:E73,"*"&$B31&"*")) | G9: =IF(COUNTIFS(구역6!G4:G73,"타교회",구역6!E4:E73,"*"&$B31&"*")+COUNTIFS(구역6!J4:J73,"*타교회*",구역6!E4:E73,"*"&$B31&"*")=0,"",COUNTIFS(구역6!G4:G73,"타교회",구역6!E4:E73,"*"&$B31&"*")+COUNTIFS(구역6!J4:J73,"*타교회*",구역6!E4:E73,"*"&$B31&"*")) | H9: =IF(COUNTIFS(구역6!F4:F73,"개인차",구역6!E4:E73,"*"&$B31&"*")+(COUNTIFS(구역6!H4:H73,"?*",구역6!E4:E73,"*"&$B31&"*")-COUNTIFS(구역6!H4:H73,"*교회차*",구역6!E4:E73,"*"&$B31&"*")-COUNTIFS(구역6!H4:H73,"*타교회*",구역6!E4:E73,"*"&$B31&"*")-COUNTIFS(구역6!H4:H73,"*대중교통*",구역6!E4:E73,"*"&$B31&"*"))=0,"",COUNTIFS(구역6!F4:F73,"개인차",구역6!E4:E73,"*"&$B31&"*")+(COUNTIFS(구역6!H4:H73,"?*",구역6!E4:E73,"*"&$B31&"*")-COUNTIFS(구역6!H4:H73,"*교회차*",구역6!E4:E73,"*"&$B31&"*")-COUNTIFS(구역6!H4:H73,"*타교회*",구역6!E4:E73,"*"&$B31&"*")-COUNTIFS(구역6!H4:H73,"*대중교통*",구역6!E4:E73,"*"&$B31&"*"))) | I9: =IF(COUNTIFS(구역6!G4:G73,"개인차",구역6!E4:E73,"*"&$B31&"*")+(COUNTIFS(구역6!J4:J73,"?*",구역6!E4:E73,"*"&$B31&"*")-COUNTIFS(구역6!J4:J73,"*교회차*",구역6!E4:E73,"*"&$B31&"*")-COUNTIFS(구역6!J4:J73,"*타교회*",구역6!E4:E73,"*"&$B31&"*")-COUNTIFS(구역6!J4:J73,"*대중교통*",구역6!E4:E73,"*"&$B31&"*"))=0,"",COUNTIFS(구역6!G4:G73,"개인차",구역6!E4:E73,"*"&$B31&"*")+(COUNTIFS(구역6!J4:J73,"?*",구역6!E4:E73,"*"&$B31&"*")-COUNTIFS(구역6!J4:J73,"*교회차*",구역6!E4:E73,"*"&$B31&"*")-COUNTIFS(구역6!J4:J73,"*타교회*",구역6!E4:E73,"*"&$B31&"*")-COUNTIFS(구역6!J4:J73,"*대중교통*",구역6!E4:E73,"*"&$B31&"*"))) | J9: =IF(COUNTIFS(구역6!F4:F73,"대중교통",구역6!E4:E73,"*"&$B31&"*")+COUNTIFS(구역6!H4:H73,"*대중교통*",구역6!E4:E73,"*"&$B31&"*")=0,"",COUNTIFS(구역6!F4:F73,"대중교통",구역6!E4:E73,"*"&$B31&"*")+COUNTIFS(구역6!H4:H73,"*대중교통*",구역6!E4:E73,"*"&$B31&"*")) | K9: =IF(COUNTIFS(구역6!G4:G73,"대중교통",구역6!E4:E73,"*"&$B31&"*")+COUNTIFS(구역6!J4:J73,"*대중교통*",구역6!E4:E73,"*"&$B31&"*")=0,"",COUNTIFS(구역6!G4:G73,"대중교통",구역6!E4:E73,"*"&$B31&"*")+COUNTIFS(구역6!J4:J73,"*대중교통*",구역6!E4:E73,"*"&$B31&"*")) | L9: =IF(SUM(B9,D9,F9,H9,J9)=0,"",SUM(B9,D9,F9,H9,J9))
A10: 구역7 | B10: =IF(COUNTIFS(구역7!F4:F73,"1호차",구역7!E4:E73,"*"&$B31&"*")+COUNTIFS(구역7!F4:F73,"2호차",구역7!E4:E73,"*"&$B31&"*")+COUNTIFS(구역7!F4:F73,"3호차",구역7!E4:E73,"*"&$B31&"*")+COUNTIFS(구역7!F4:F73,"4호차",구역7!E4:E73,"*"&$B31&"*")+COUNTIFS(구역7!F4:F73,"5호차",구역7!E4:E73,"*"&$B31&"*")+COUNTIFS(구역7!F4:F73,"6호차",구역7!E4:E73,"*"&$B31&"*")+COUNTIFS(구역7!F4:F73,"7호차",구역7!E4:E73,"*"&$B31&"*")+COUNTIFS(구역7!F4:F73,"8호차",구역7!E4:E73,"*"&$B31&"*")+COUNTIFS(구역7!F4:F73,"9호차",구역7!E4:E73,"*"&$B31&"*")+COUNTIFS(구역7!F4:F73,"10호차",구역7!E4:E73,"*"&$B31&"*")=0,"",COUNTIFS(구역7!F4:F73,"1호차",구역7!E4:E73,"*"&$B31&"*")+COUNTIFS(구역7!F4:F73,"2호차",구역7!E4:E73,"*"&$B31&"*")+COUNTIFS(구역7!F4:F73,"3호차",구역7!E4:E73,"*"&$B31&"*")+COUNTIFS(구역7!F4:F73,"4호차",구역7!E4:E73,"*"&$B31&"*")+COUNTIFS(구역7!F4:F73,"5호차",구역7!E4:E73,"*"&$B31&"*")+COUNTIFS(구역7!F4:F73,"6호차",구역7!E4:E73,"*"&$B31&"*")+COUNTIFS(구역7!F4:F73,"7호차",구역7!E4:E73,"*"&$B31&"*")+COUNTIFS(구역7!F4:F73,"8호차",구역7!E4:E73,"*"&$B31&"*")+COUNTIFS(구역7!F4:F73,"9호차",구역7!E4:E73,"*"&$B31&"*")+COUNTIFS(구역7!F4:F73,"10호차",구역7!E4:E73,"*"&$B31&"*")) | C10: =IF(COUNTIFS(구역7!G4:G73,"1호차",구역7!E4:E73,"*"&$B31&"*")+COUNTIFS(구역7!G4:G73,"2호차",구역7!E4:E73,"*"&$B31&"*")+COUNTIFS(구역7!G4:G73,"3호차",구역7!E4:E73,"*"&$B31&"*")+COUNTIFS(구역7!G4:G73,"4호차",구역7!E4:E73,"*"&$B31&"*")+COUNTIFS(구역7!G4:G73,"5호차",구역7!E4:E73,"*"&$B31&"*")+COUNTIFS(구역7!G4:G73,"6호차",구역7!E4:E73,"*"&$B31&"*")+COUNTIFS(구역7!G4:G73,"7호차",구역7!E4:E73,"*"&$B31&"*")+COUNTIFS(구역7!G4:G73,"8호차",구역7!E4:E73,"*"&$B31&"*")+COUNTIFS(구역7!G4:G73,"9호차",구역7!E4:E73,"*"&$B31&"*")+COUNTIFS(구역7!G4:G73,"10호차",구역7!E4:E73,"*"&$B31&"*")=0,"",COUNTIFS(구역7!G4:G73,"1호차",구역7!E4:E73,"*"&$B31&"*")+COUNTIFS(구역7!G4:G73,"2호차",구역7!E4:E73,"*"&$B31&"*")+COUNTIFS(구역7!G4:G73,"3호차",구역7!E4:E73,"*"&$B31&"*")+COUNTIFS(구역7!G4:G73,"4호차",구역7!E4:E73,"*"&$B31&"*")+COUNTIFS(구역7!G4:G73,"5호차",구역7!E4:E73,"*"&$B31&"*")+COUNTIFS(구역7!G4:G73,"6호차",구역7!E4:E73,"*"&$B31&"*")+COUNTIFS(구역7!G4:G73,"7호차",구역7!E4:E73,"*"&$B31&"*")+COUNTIFS(구역7!G4:G73,"8호차",구역7!E4:E73,"*"&$B31&"*")+COUNTIFS(구역7!G4:G73,"9호차",구역7!E4:E73,"*"&$B31&"*")+COUNTIFS(구역7!G4:G73,"10호차",구역7!E4:E73,"*"&$B31&"*")) | D10: =IF(COUNTIFS(구역7!F4:F73,"교회차1",구역7!E4:E73,"*"&$B31&"*")+COUNTIFS(구역7!F4:F73,"교회차2",구역7!E4:E73,"*"&$B31&"*")+COUNTIFS(구역7!F4:F73,"교회차3",구역7!E4:E73,"*"&$B31&"*")+COUNTIFS(구역7!F4:F73,"교회차4",구역7!E4:E73,"*"&$B31&"*")+COUNTIFS(구역7!F4:F73,"교회차5",구역7!E4:E73,"*"&$B31&"*")+COUNTIFS(구역7!H4:H73,"*교회차*",구역7!E4:E73,"*"&$B31&"*")=0,"",COUNTIFS(구역7!F4:F73,"교회차1",구역7!E4:E73,"*"&$B31&"*")+COUNTIFS(구역7!F4:F73,"교회차2",구역7!E4:E73,"*"&$B31&"*")+COUNTIFS(구역7!F4:F73,"교회차3",구역7!E4:E73,"*"&$B31&"*")+COUNTIFS(구역7!F4:F73,"교회차4",구역7!E4:E73,"*"&$B31&"*")+COUNTIFS(구역7!F4:F73,"교회차5",구역7!E4:E73,"*"&$B31&"*")+COUNTIFS(구역7!H4:H73,"*교회차*",구역7!E4:E73,"*"&$B31&"*")) | E10: =IF(COUNTIFS(구역7!G4:G73,"교회차1",구역7!E4:E73,"*"&$B31&"*")+COUNTIFS(구역7!G4:G73,"교회차2",구역7!E4:E73,"*"&$B31&"*")+COUNTIFS(구역7!G4:G73,"교회차3",구역7!E4:E73,"*"&$B31&"*")+COUNTIFS(구역7!G4:G73,"교회차4",구역7!E4:E73,"*"&$B31&"*")+COUNTIFS(구역7!G4:G73,"교회차5",구역7!E4:E73,"*"&$B31&"*")+COUNTIFS(구역7!J4:J73,"*교회차*",구역7!E4:E73,"*"&$B31&"*")=0,"",COUNTIFS(구역7!G4:G73,"교회차1",구역7!E4:E73,"*"&$B31&"*")+COUNTIFS(구역7!G4:G73,"교회차2",구역7!E4:E73,"*"&$B31&"*")+COUNTIFS(구역7!G4:G73,"교회차3",구역7!E4:E73,"*"&$B31&"*")+COUNTIFS(구역7!G4:G73,"교회차4",구역7!E4:E73,"*"&$B31&"*")+COUNTIFS(구역7!G4:G73,"교회차5",구역7!E4:E73,"*"&$B31&"*")+COUNTIFS(구역7!J4:J73,"*교회차*",구역7!E4:E73,"*"&$B31&"*")) | F10: =IF(COUNTIFS(구역7!F4:F73,"타교회",구역7!E4:E73,"*"&$B31&"*")+COUNTIFS(구역7!H4:H73,"*타교회*",구역7!E4:E73,"*"&$B31&"*")=0,"",COUNTIFS(구역7!F4:F73,"타교회",구역7!E4:E73,"*"&$B31&"*")+COUNTIFS(구역7!H4:H73,"*타교회*",구역7!E4:E73,"*"&$B31&"*")) | G10: =IF(COUNTIFS(구역7!G4:G73,"타교회",구역7!E4:E73,"*"&$B31&"*")+COUNTIFS(구역7!J4:J73,"*타교회*",구역7!E4:E73,"*"&$B31&"*")=0,"",COUNTIFS(구역7!G4:G73,"타교회",구역7!E4:E73,"*"&$B31&"*")+COUNTIFS(구역7!J4:J73,"*타교회*",구역7!E4:E73,"*"&$B31&"*")) | H10: =IF(COUNTIFS(구역7!F4:F73,"개인차",구역7!E4:E73,"*"&$B31&"*")+(COUNTIFS(구역7!H4:H73,"?*",구역7!E4:E73,"*"&$B31&"*")-COUNTIFS(구역7!H4:H73,"*교회차*",구역7!E4:E73,"*"&$B31&"*")-COUNTIFS(구역7!H4:H73,"*타교회*",구역7!E4:E73,"*"&$B31&"*")-COUNTIFS(구역7!H4:H73,"*대중교통*",구역7!E4:E73,"*"&$B31&"*"))=0,"",COUNTIFS(구역7!F4:F73,"개인차",구역7!E4:E73,"*"&$B31&"*")+(COUNTIFS(구역7!H4:H73,"?*",구역7!E4:E73,"*"&$B31&"*")-COUNTIFS(구역7!H4:H73,"*교회차*",구역7!E4:E73,"*"&$B31&"*")-COUNTIFS(구역7!H4:H73,"*타교회*",구역7!E4:E73,"*"&$B31&"*")-COUNTIFS(구역7!H4:H73,"*대중교통*",구역7!E4:E73,"*"&$B31&"*"))) | I10: =IF(COUNTIFS(구역7!G4:G73,"개인차",구역7!E4:E73,"*"&$B31&"*")+(COUNTIFS(구역7!J4:J73,"?*",구역7!E4:E73,"*"&$B31&"*")-COUNTIFS(구역7!J4:J73,"*교회차*",구역7!E4:E73,"*"&$B31&"*")-COUNTIFS(구역7!J4:J73,"*타교회*",구역7!E4:E73,"*"&$B31&"*")-COUNTIFS(구역7!J4:J73,"*대중교통*",구역7!E4:E73,"*"&$B31&"*"))=0,"",COUNTIFS(구역7!G4:G73,"개인차",구역7!E4:E73,"*"&$B31&"*")+(COUNTIFS(구역7!J4:J73,"?*",구역7!E4:E73,"*"&$B31&"*")-COUNTIFS(구역7!J4:J73,"*교회차*",구역7!E4:E73,"*"&$B31&"*")-COUNTIFS(구역7!J4:J73,"*타교회*",구역7!E4:E73,"*"&$B31&"*")-COUNTIFS(구역7!J4:J73,"*대중교통*",구역7!E4:E73,"*"&$B31&"*"))) | J10: =IF(COUNTIFS(구역7!F4:F73,"대중교통",구역7!E4:E73,"*"&$B31&"*")+COUNTIFS(구역7!H4:H73,"*대중교통*",구역7!E4:E73,"*"&$B31&"*")=0,"",COUNTIFS(구역7!F4:F73,"대중교통",구역7!E4:E73,"*"&$B31&"*")+COUNTIFS(구역7!H4:H73,"*대중교통*",구역7!E4:E73,"*"&$B31&"*")) | K10: =IF(COUNTIFS(구역7!G4:G73,"대중교통",구역7!E4:E73,"*"&$B31&"*")+COUNTIFS(구역7!J4:J73,"*대중교통*",구역7!E4:E73,"*"&$B31&"*")=0,"",COUNTIFS(구역7!G4:G73,"대중교통",구역7!E4:E73,"*"&$B31&"*")+COUNTIFS(구역7!J4:J73,"*대중교통*",구역7!E4:E73,"*"&$B31&"*")) | L10: =IF(SUM(B10,D10,F10,H10,J10)=0,"",SUM(B10,D10,F10,H10,J10))
A11: 구역8 | B11: =IF(COUNTIFS(구역8!F4:F73,"1호차",구역8!E4:E73,"*"&$B31&"*")+COUNTIFS(구역8!F4:F73,"2호차",구역8!E4:E73,"*"&$B31&"*")+COUNTIFS(구역8!F4:F73,"3호차",구역8!E4:E73,"*"&$B31&"*")+COUNTIFS(구역8!F4:F73,"4호차",구역8!E4:E73,"*"&$B31&"*")+COUNTIFS(구역8!F4:F73,"5호차",구역8!E4:E73,"*"&$B31&"*")+COUNTIFS(구역8!F4:F73,"6호차",구역8!E4:E73,"*"&$B31&"*")+COUNTIFS(구역8!F4:F73,"7호차",구역8!E4:E73,"*"&$B31&"*")+COUNTIFS(구역8!F4:F73,"8호차",구역8!E4:E73,"*"&$B31&"*")+COUNTIFS(구역8!F4:F73,"9호차",구역8!E4:E73,"*"&$B31&"*")+COUNTIFS(구역8!F4:F73,"10호차",구역8!E4:E73,"*"&$B31&"*")=0,"",COUNTIFS(구역8!F4:F73,"1호차",구역8!E4:E73,"*"&$B31&"*")+COUNTIFS(구역8!F4:F73,"2호차",구역8!E4:E73,"*"&$B31&"*")+COUNTIFS(구역8!F4:F73,"3호차",구역8!E4:E73,"*"&$B31&"*")+COUNTIFS(구역8!F4:F73,"4호차",구역8!E4:E73,"*"&$B31&"*")+COUNTIFS(구역8!F4:F73,"5호차",구역8!E4:E73,"*"&$B31&"*")+COUNTIFS(구역8!F4:F73,"6호차",구역8!E4:E73,"*"&$B31&"*")+COUNTIFS(구역8!F4:F73,"7호차",구역8!E4:E73,"*"&$B31&"*")+COUNTIFS(구역8!F4:F73,"8호차",구역8!E4:E73,"*"&$B31&"*")+COUNTIFS(구역8!F4:F73,"9호차",구역8!E4:E73,"*"&$B31&"*")+COUNTIFS(구역8!F4:F73,"10호차",구역8!E4:E73,"*"&$B31&"*")) | C11: =IF(COUNTIFS(구역8!G4:G73,"1호차",구역8!E4:E73,"*"&$B31&"*")+COUNTIFS(구역8!G4:G73,"2호차",구역8!E4:E73,"*"&$B31&"*")+COUNTIFS(구역8!G4:G73,"3호차",구역8!E4:E73,"*"&$B31&"*")+COUNTIFS(구역8!G4:G73,"4호차",구역8!E4:E73,"*"&$B31&"*")+COUNTIFS(구역8!G4:G73,"5호차",구역8!E4:E73,"*"&$B31&"*")+COUNTIFS(구역8!G4:G73,"6호차",구역8!E4:E73,"*"&$B31&"*")+COUNTIFS(구역8!G4:G73,"7호차",구역8!E4:E73,"*"&$B31&"*")+COUNTIFS(구역8!G4:G73,"8호차",구역8!E4:E73,"*"&$B31&"*")+COUNTIFS(구역8!G4:G73,"9호차",구역8!E4:E73,"*"&$B31&"*")+COUNTIFS(구역8!G4:G73,"10호차",구역8!E4:E73,"*"&$B31&"*")=0,"",COUNTIFS(구역8!G4:G73,"1호차",구역8!E4:E73,"*"&$B31&"*")+COUNTIFS(구역8!G4:G73,"2호차",구역8!E4:E73,"*"&$B31&"*")+COUNTIFS(구역8!G4:G73,"3호차",구역8!E4:E73,"*"&$B31&"*")+COUNTIFS(구역8!G4:G73,"4호차",구역8!E4:E73,"*"&$B31&"*")+COUNTIFS(구역8!G4:G73,"5호차",구역8!E4:E73,"*"&$B31&"*")+COUNTIFS(구역8!G4:G73,"6호차",구역8!E4:E73,"*"&$B31&"*")+COUNTIFS(구역8!G4:G73,"7호차",구역8!E4:E73,"*"&$B31&"*")+COUNTIFS(구역8!G4:G73,"8호차",구역8!E4:E73,"*"&$B31&"*")+COUNTIFS(구역8!G4:G73,"9호차",구역8!E4:E73,"*"&$B31&"*")+COUNTIFS(구역8!G4:G73,"10호차",구역8!E4:E73,"*"&$B31&"*")) | D11: =IF(COUNTIFS(구역8!F4:F73,"교회차1",구역8!E4:E73,"*"&$B31&"*")+COUNTIFS(구역8!F4:F73,"교회차2",구역8!E4:E73,"*"&$B31&"*")+COUNTIFS(구역8!F4:F73,"교회차3",구역8!E4:E73,"*"&$B31&"*")+COUNTIFS(구역8!F4:F73,"교회차4",구역8!E4:E73,"*"&$B31&"*")+COUNTIFS(구역8!F4:F73,"교회차5",구역8!E4:E73,"*"&$B31&"*")+COUNTIFS(구역8!H4:H73,"*교회차*",구역8!E4:E73,"*"&$B31&"*")=0,"",COUNTIFS(구역8!F4:F73,"교회차1",구역8!E4:E73,"*"&$B31&"*")+COUNTIFS(구역8!F4:F73,"교회차2",구역8!E4:E73,"*"&$B31&"*")+COUNTIFS(구역8!F4:F73,"교회차3",구역8!E4:E73,"*"&$B31&"*")+COUNTIFS(구역8!F4:F73,"교회차4",구역8!E4:E73,"*"&$B31&"*")+COUNTIFS(구역8!F4:F73,"교회차5",구역8!E4:E73,"*"&$B31&"*")+COUNTIFS(구역8!H4:H73,"*교회차*",구역8!E4:E73,"*"&$B31&"*")) | E11: =IF(COUNTIFS(구역8!G4:G73,"교회차1",구역8!E4:E73,"*"&$B31&"*")+COUNTIFS(구역8!G4:G73,"교회차2",구역8!E4:E73,"*"&$B31&"*")+COUNTIFS(구역8!G4:G73,"교회차3",구역8!E4:E73,"*"&$B31&"*")+COUNTIFS(구역8!G4:G73,"교회차4",구역8!E4:E73,"*"&$B31&"*")+COUNTIFS(구역8!G4:G73,"교회차5",구역8!E4:E73,"*"&$B31&"*")+COUNTIFS(구역8!J4:J73,"*교회차*",구역8!E4:E73,"*"&$B31&"*")=0,"",COUNTIFS(구역8!G4:G73,"교회차1",구역8!E4:E73,"*"&$B31&"*")+COUNTIFS(구역8!G4:G73,"교회차2",구역8!E4:E73,"*"&$B31&"*")+COUNTIFS(구역8!G4:G73,"교회차3",구역8!E4:E73,"*"&$B31&"*")+COUNTIFS(구역8!G4:G73,"교회차4",구역8!E4:E73,"*"&$B31&"*")+COUNTIFS(구역8!G4:G73,"교회차5",구역8!E4:E73,"*"&$B31&"*")+COUNTIFS(구역8!J4:J73,"*교회차*",구역8!E4:E73,"*"&$B31&"*")) | F11: =IF(COUNTIFS(구역8!F4:F73,"타교회",구역8!E4:E73,"*"&$B31&"*")+COUNTIFS(구역8!H4:H73,"*타교회*",구역8!E4:E73,"*"&$B31&"*")=0,"",COUNTIFS(구역8!F4:F73,"타교회",구역8!E4:E73,"*"&$B31&"*")+COUNTIFS(구역8!H4:H73,"*타교회*",구역8!E4:E73,"*"&$B31&"*")) | G11: =IF(COUNTIFS(구역8!G4:G73,"타교회",구역8!E4:E73,"*"&$B31&"*")+COUNTIFS(구역8!J4:J73,"*타교회*",구역8!E4:E73,"*"&$B31&"*")=0,"",COUNTIFS(구역8!G4:G73,"타교회",구역8!E4:E73,"*"&$B31&"*")+COUNTIFS(구역8!J4:J73,"*타교회*",구역8!E4:E73,"*"&$B31&"*")) | H11: =IF(COUNTIFS(구역8!F4:F73,"개인차",구역8!E4:E73,"*"&$B31&"*")+(COUNTIFS(구역8!H4:H73,"?*",구역8!E4:E73,"*"&$B31&"*")-COUNTIFS(구역8!H4:H73,"*교회차*",구역8!E4:E73,"*"&$B31&"*")-COUNTIFS(구역8!H4:H73,"*타교회*",구역8!E4:E73,"*"&$B31&"*")-COUNTIFS(구역8!H4:H73,"*대중교통*",구역8!E4:E73,"*"&$B31&"*"))=0,"",COUNTIFS(구역8!F4:F73,"개인차",구역8!E4:E73,"*"&$B31&"*")+(COUNTIFS(구역8!H4:H73,"?*",구역8!E4:E73,"*"&$B31&"*")-COUNTIFS(구역8!H4:H73,"*교회차*",구역8!E4:E73,"*"&$B31&"*")-COUNTIFS(구역8!H4:H73,"*타교회*",구역8!E4:E73,"*"&$B31&"*")-COUNTIFS(구역8!H4:H73,"*대중교통*",구역8!E4:E73,"*"&$B31&"*"))) | I11: =IF(COUNTIFS(구역8!G4:G73,"개인차",구역8!E4:E73,"*"&$B31&"*")+(COUNTIFS(구역8!J4:J73,"?*",구역8!E4:E73,"*"&$B31&"*")-COUNTIFS(구역8!J4:J73,"*교회차*",구역8!E4:E73,"*"&$B31&"*")-COUNTIFS(구역8!J4:J73,"*타교회*",구역8!E4:E73,"*"&$B31&"*")-COUNTIFS(구역8!J4:J73,"*대중교통*",구역8!E4:E73,"*"&$B31&"*"))=0,"",COUNTIFS(구역8!G4:G73,"개인차",구역8!E4:E73,"*"&$B31&"*")+(COUNTIFS(구역8!J4:J73,"?*",구역8!E4:E73,"*"&$B31&"*")-COUNTIFS(구역8!J4:J73,"*교회차*",구역8!E4:E73,"*"&$B31&"*")-COUNTIFS(구역8!J4:J73,"*타교회*",구역8!E4:E73,"*"&$B31&"*")-COUNTIFS(구역8!J4:J73,"*대중교통*",구역8!E4:E73,"*"&$B31&"*"))) | J11: =IF(COUNTIFS(구역8!F4:F73,"대중교통",구역8!E4:E73,"*"&$B31&"*")+COUNTIFS(구역8!H4:H73,"*대중교통*",구역8!E4:E73,"*"&$B31&"*")=0,"",COUNTIFS(구역8!F4:F73,"대중교통",구역8!E4:E73,"*"&$B31&"*")+COUNTIFS(구역8!H4:H73,"*대중교통*",구역8!E4:E73,"*"&$B31&"*")) | K11: =IF(COUNTIFS(구역8!G4:G73,"대중교통",구역8!E4:E73,"*"&$B31&"*")+COUNTIFS(구역8!J4:J73,"*대중교통*",구역8!E4:E73,"*"&$B31&"*")=0,"",COUNTIFS(구역8!G4:G73,"대중교통",구역8!E4:E73,"*"&$B31&"*")+COUNTIFS(구역8!J4:J73,"*대중교통*",구역8!E4:E73,"*"&$B31&"*")) | L11: =IF(SUM(B11,D11,F11,H11,J11)=0,"",SUM(B11,D11,F11,H11,J11))
