Workbook

Sheet 11구역
A1: 2026년 하계수양회 ─ 11구역
A2: NO | B2: 구역 | C2: 부서 (회별) | D2: 성 명 | E2: 차수 | F2: 교 통 편 | L2: 인 도 자 | N2: 비고
F3: 본대 상행 | G3: 본대 하행 | H3: 기타 상행 | I3: 기타 하행 | J3: 개인차 상행 | K3: 개인차 하행 | L3: 성 명 | M3: 관계
A4: 1
A5: 2
A6: 3
A7: 4
A8: 5
A9: 6
A10: 7
A11: 8
A12: 9
A13: 10
A14: 11
A15: 12
... A43: 40
A44: 합 계 | E44: =IF(COUNTA(E4:E43)=0,"",COUNTA(E4:E43)) | F44: =IF(COUNTA(F4:F43)=0,"",COUNTA(F4:F43)) | G44: =IF(COUNTA(G4:G43)=0,"",COUNTA(G4:G43)) | H44: =IF(COUNTA(H4:H43)=0,"",COUNTA(H4:H43)) | I44: =IF(COUNTA(I4:I43)=0,"",COUNTA(I4:I43)) | J44: =IF(COUNTA(J4:J43)=0,"",COUNTA(J4:J43)) | K44: =IF(COUNTA(K4:K43)=0,"",COUNTA(K4:K43)) | L44: =IF(COUNTA(L4:L43)=0,"",COUNTA(L4:L43))

Sheet 12구역
A1: 2026년 하계수양회 ─ 12구역
A2: NO | B2: 구역 | C2: 부서 (회별) | D2: 성 명 | E2: 차수 | F2: 교 통 편 | L2: 인 도 자 | N2: 비고
F3: 본대 상행 | G3: 본대 하행 | H3: 기타 상행 | I3: 기타 하행 | J3: 개인차 상행 | K3: 개인차 하행 | L3: 성 명 | M3: 관계
A4: 1
A5: 2
A6: 3
A7: 4
A8: 5
A9: 6
A10: 7
A11: 8
A12: 9
A13: 10
A14: 11
A15: 12
... A43: 40
A44: 합 계 | E44: =IF(COUNTA(E4:E43)=0,"",COUNTA(E4:E43)) | F44: =IF(COUNTA(F4:F43)=0,"",COUNTA(F4:F43)) | G44: =IF(COUNTA(G4:G43)=0,"",COUNTA(G4:G43)) | H44: =IF(COUNTA(H4:H43)=0,"",COUNTA(H4:H43)) | I44: =IF(COUNTA(I4:I43)=0,"",COUNTA(I4:I43)) | J44: =IF(COUNTA(J4:J43)=0,"",COUNTA(J4:J43)) | K44: =IF(COUNTA(K4:K43)=0,"",COUNTA(K4:K43)) | L44: =IF(COUNTA(L4:L43)=0,"",COUNTA(L4:L43))

Sheet 13구역
A1: 2026년 하계수양회 ─ 13구역
A2: NO | B2: 구역 | C2: 부서 (회별) | D2: 성 명 | E2: 차수 | F2: 교 통 편 | L2: 인 도 자 | N2: 비고
F3: 본대 상행 | G3: 본대 하행 | H3: 기타 상행 | I3: 기타 하행 | J3: 개인차 상행 | K3: 개인차 하행 | L3: 성 명 | M3: 관계
A4: 1
A5: 2
A6: 3
A7: 4
A8: 5
A9: 6
A10: 7
A11: 8
A12: 9
A13: 10
A14: 11
A15: 12
... A43: 40
A44: 합 계 | E44: =IF(COUNTA(E4:E43)=0,"",COUNTA(E4:E43)) | F44: =IF(COUNTA(F4:F43)=0,"",COUNTA(F4:F43)) | G44: =IF(COUNTA(G4:G43)=0,"",COUNTA(G4:G43)) | H44: =IF(COUNTA(H4:H43)=0,"",COUNTA(H4:H43)) | I44: =IF(COUNTA(I4:I43)=0,"",COUNTA(I4:I43)) | J44: =IF(COUNTA(J4:J43)=0,"",COUNTA(J4:J43)) | K44: =IF(COUNTA(K4:K43)=0,"",COUNTA(K4:K43)) | L44: =IF(COUNTA(L4:L43)=0,"",COUNTA(L4:L43))

Sheet 14구역
A1: 2026년 하계수양회 ─ 14구역
A2: NO | B2: 구역 | C2: 부서 (회별) | D2: 성 명 | E2: 차수 | F2: 교 통 편 | L2: 인 도 자 | N2: 비고
F3: 본대 상행 | G3: 본대 하행 | H3: 기타 상행 | I3: 기타 하행 | J3: 개인차 상행 | K3: 개인차 하행 | L3: 성 명 | M3: 관계
A4: 1
A5: 2
A6: 3
A7: 4
A8: 5
A9: 6
A10: 7
A11: 8
A12: 9
A13: 10
A14: 11
A15: 12
... A43: 40
A44: 합 계 | E44: =IF(COUNTA(E4:E43)=0,"",COUNTA(E4:E43)) | F44: =IF(COUNTA(F4:F43)=0,"",COUNTA(F4:F43)) | G44: =IF(COUNTA(G4:G43)=0,"",COUNTA(G4:G43)) | H44: =IF(COUNTA(H4:H43)=0,"",COUNTA(H4:H43)) | I44: =IF(COUNTA(I4:I43)=0,"",COUNTA(I4:I43)) | J44: =IF(COUNTA(J4:J43)=0,"",COUNTA(J4:J43)) | K44: =IF(COUNTA(K4:K43)=0,"",COUNTA(K4:K43)) | L44: =IF(COUNTA(L4:L43)=0,"",COUNTA(L4:L43))

Sheet 21구역
A1: 2026년 하계수양회 ─ 21구역
A2: NO | B2: 구역 | C2: 부서 (회별) | D2: 성 명 | E2: 차수 | F2: 교 통 편 | L2: 인 도 자 | N2: 비고
F3: 본대 상행 | G3: 본대 하행 | H3: 기타 상행 | I3: 기타 하행 | J3: 개인차 상행 | K3: 개인차 하행 | L3: 성 명 | M3: 관계
A4: 1
A5: 2
A6: 3
A7: 4
A8: 5
A9: 6
A10: 7
A11: 8
A12: 9
A13: 10
A14: 11
A15: 12
... A43: 40
A44: 합 계 | E44: =IF(COUNTA(E4:E43)=0,"",COUNTA(E4:E43)) | F44: =IF(COUNTA(F4:F43)=0,"",COUNTA(F4:F43)) | G44: =IF(COUNTA(G4:G43)=0,"",COUNTA(G4:G43)) | H44: =IF(COUNTA(H4:H43)=0,"",COUNTA(H4:H43)) | I44: =IF(COUNTA(I4:I43)=0,"",COUNTA(I4:I43)) | J44: =IF(COUNTA(J4:J43)=0,"",COUNTA(J4:J43)) | K44: =IF(COUNTA(K4:K43)=0,"",COUNTA(K4:K43)) | L44: =IF(COUNTA(L4:L43)=0,"",COUNTA(L4:L43))

Sheet 22구역
A1: 2026년 하계수양회 ─ 22구역
A2: NO | B2: 구역 | C2: 부서 (회별) | D2: 성 명 | E2: 차수 | F2: 교 통 편 | L2: 인 도 자 | N2: 비고
F3: 본대 상행 | G3: 본대 하행 | H3: 기타 상행 | I3: 기타 하행 | J3: 개인차 상행 | K3: 개인차 하행 | L3: 성 명 | M3: 관계
A4: 1
A5: 2
A6: 3
A7: 4
A8: 5
A9: 6
A10: 7
A11: 8
A12: 9
A13: 10
A14: 11
A15: 12
... A43: 40
A44: 합 계 | E44: =IF(COUNTA(E4:E43)=0,"",COUNTA(E4:E43)) | F44: =IF(COUNTA(F4:F43)=0,"",COUNTA(F4:F43)) | G44: =IF(COUNTA(G4:G43)=0,"",COUNTA(G4:G43)) | H44: =IF(COUNTA(H4:H43)=0,"",COUNTA(H4:H43)) | I44: =IF(COUNTA(I4:I43)=0,"",COUNTA(I4:I43)) | J44: =IF(COUNTA(J4:J43)=0,"",COUNTA(J4:J43)) | K44: =IF(COUNTA(K4:K43)=0,"",COUNTA(K4:K43)) | L44: =IF(COUNTA(L4:L43)=0,"",COUNTA(L4:L43))

Sheet 23구역
A1: 2026년 하계수양회 ─ 23구역
A2: NO | B2: 구역 | C2: 부서 (회별) | D2: 성 명 | E2: 차수 | F2: 교 통 편 | L2: 인 도 자 | N2: 비고
F3: 본대 상행 | G3: 본대 하행 | H3: 기타 상행 | I3: 기타 하행 | J3: 개인차 상행 | K3: 개인차 하행 | L3: 성 명 | M3: 관계
A4: 1
A5: 2
A6: 3
A7: 4
A8: 5
A9: 6
A10: 7
A11: 8
A12: 9
A13: 10
A14: 11
A15: 12
... A43: 40
A44: 합 계 | E44: =IF(COUNTA(E4:E43)=0,"",COUNTA(E4:E43)) | F44: =IF(COUNTA(F4:F43)=0,"",COUNTA(F4:F43)) | G44: =IF(COUNTA(G4:G43)=0,"",COUNTA(G4:G43)) | H44: =IF(COUNTA(H4:H43)=0,"",COUNTA(H4:H43)) | I44: =IF(COUNTA(I4:I43)=0,"",COUNTA(I4:I43)) | J44: =IF(COUNTA(J4:J43)=0,"",COUNTA(J4:J43)) | K44: =IF(COUNTA(K4:K43)=0,"",COUNTA(K4:K43)) | L44: =IF(COUNTA(L4:L43)=0,"",COUNTA(L4:L43))

Sheet 24구역
A1: 2026년 하계수양회 ─ 24구역
A2: NO | B2: 구역 | C2: 부서 (회별) | D2: 성 명 | E2: 차수 | F2: 교 통 편 | L2: 인 도 자 | N2: 비고
F3: 본대 상행 | G3: 본대 하행 | H3: 기타 상행 | I3: 기타 하행 | J3: 개인차 상행 | K3: 개인차 하행 | L3: 성 명 | M3: 관계
A4: 1
A5: 2
A6: 3
A7: 4
A8: 5
A9: 6
A10: 7
A11: 8
A12: 9
A13: 10
A14: 11
A15: 12
... A43: 40
A44: 합 계 | E44: =IF(COUNTA(E4:E43)=0,"",COUNTA(E4:E43)) | F44: =IF(COUNTA(F4:F43)=0,"",COUNTA(F4:F43)) | G44: =IF(COUNTA(G4:G43)=0,"",COUNTA(G4:G43)) | H44: =IF(COUNTA(H4:H43)=0,"",COUNTA(H4:H43)) | I44: =IF(COUNTA(I4:I43)=0,"",COUNTA(I4:I43)) | J44: =IF(COUNTA(J4:J43)=0,"",COUNTA(J4:J43)) | K44: =IF(COUNTA(K4:K43)=0,"",COUNTA(K4:K43)) | L44: =IF(COUNTA(L4:L43)=0,"",COUNTA(L4:L43))

Sheet 31구역
A1: 2026년 하계수양회 ─ 31구역
A2: NO | B2: 구역 | C2: 부서 (회별) | D2: 성 명 | E2: 차수 | F2: 교 통 편 | L2: 인 도 자 | N2: 비고
F3: 본대 상행 | G3: 본대 하행 | H3: 기타 상행 | I3: 기타 하행 | J3: 개인차 상행 | K3: 개인차 하행 | L3: 성 명 | M3: 관계
A4: 1
A5: 2
A6: 3
A7: 4
A8: 5
A9: 6
A10: 7
A11: 8
A12: 9
A13: 10
A14: 11
A15: 12
... A43: 40
A44: 합 계 | E44: =IF(COUNTA(E4:E43)=0,"",COUNTA(E4:E43)) | F44: =IF(COUNTA(F4:F43)=0,"",COUNTA(F4:F43)) | G44: =IF(COUNTA(G4:G43)=0,"",COUNTA(G4:G43)) | H44: =IF(COUNTA(H4:H43)=0,"",COUNTA(H4:H43)) | I44: =IF(COUNTA(I4:I43)=0,"",COUNTA(I4:I43)) | J44: =IF(COUNTA(J4:J43)=0,"",COUNTA(J4:J43)) | K44: =IF(COUNTA(K4:K43)=0,"",COUNTA(K4:K43)) | L44: =IF(COUNTA(L4:L43)=0,"",COUNTA(L4:L43))

Sheet 32구역
A1: 2026년 하계수양회 ─ 32구역
A2: NO | B2: 구역 | C2: 부서 (회별) | D2: 성 명 | E2: 차수 | F2: 교 통 편 | L2: 인 도 자 | N2: 비고
F3: 본대 상행 | G3: 본대 하행 | H3: 기타 상행 | I3: 기타 하행 | J3: 개인차 상행 | K3: 개인차 하행 | L3: 성 명 | M3: 관계
A4: 1
A5: 2
A6: 3
A7: 4
A8: 5
A9: 6
A10: 7
A11: 8
A12: 9
A13: 10
A14: 11
A15: 12
... A43: 40
A44: 합 계 | E44: =IF(COUNTA(E4:E43)=0,"",COUNTA(E4:E43)) | F44: =IF(COUNTA(F4:F43)=0,"",COUNTA(F4:F43)) | G44: =IF(COUNTA(G4:G43)=0,"",COUNTA(G4:G43)) | H44: =IF(COUNTA(H4:H43)=0,"",COUNTA(H4:H43)) | I44: =IF(COUNTA(I4:I43)=0,"",COUNTA(I4:I43)) | J44: =IF(COUNTA(J4:J43)=0,"",COUNTA(J4:J43)) | K44: =IF(COUNTA(K4:K43)=0,"",COUNTA(K4:K43)) | L44: =IF(COUNTA(L4:L43)=0,"",COUNTA(L4:L43))

Sheet 33구역
A1: 2026년 하계수양회 ─ 33구역
A2: NO | B2: 구역 | C2: 부서 (회별) | D2: 성 명 | E2: 차수 | F2: 교 통 편 | L2: 인 도 자 | N2: 비고
F3: 본대 상행 | G3: 본대 하행 | H3: 기타 상행 | I3: 기타 하행 | J3: 개인차 상행 | K3: 개인차 하행 | L3: 성 명 | M3: 관계
A4: 1
A5: 2
A6: 3
A7: 4
A8: 5
A9: 6
A10: 7
A11: 8
A12: 9
A13: 10
A14: 11
A15: 12
... A43: 40
A44: 합 계 | E44: =IF(COUNTA(E4:E43)=0,"",COUNTA(E4:E43)) | F44: =IF(COUNTA(F4:F43)=0,"",COUNTA(F4:F43)) | G44: =IF(COUNTA(G4:G43)=0,"",COUNTA(G4:G43)) | H44: =IF(COUNTA(H4:H43)=0,"",COUNTA(H4:H43)) | I44: =IF(COUNTA(I4:I43)=0,"",COUNTA(I4:I43)) | J44: =IF(COUNTA(J4:J43)=0,"",COUNTA(J4:J43)) | K44: =IF(COUNTA(K4:K43)=0,"",COUNTA(K4:K43)) | L44: =IF(COUNTA(L4:L43)=0,"",COUNTA(L4:L43))

Sheet 34구역
A1: 2026년 하계수양회 ─ 34구역
A2: NO | B2: 구역 | C2: 부서 (회별) | D2: 성 명 | E2: 차수 | F2: 교 통 편 | L2: 인 도 자 | N2: 비고
F3: 본대 상행 | G3: 본대 하행 | H3: 기타 상행 | I3: 기타 하행 | J3: 개인차 상행 | K3: 개인차 하행 | L3: 성 명 | M3: 관계
A4: 1
A5: 2
A6: 3
A7: 4
A8: 5
A9: 6
A10: 7
A11: 8
A12: 9
A13: 10
A14: 11
A15: 12
... A43: 40
A44: 합 계 | E44: =IF(COUNTA(E4:E43)=0,"",COUNTA(E4:E43)) | F44: =IF(COUNTA(F4:F43)=0,"",COUNTA(F4:F43)) | G44: =IF(COUNTA(G4:G43)=0,"",COUNTA(G4:G43)) | H44: =IF(COUNTA(H4:H43)=0,"",COUNTA(H4:H43)) | I44: =IF(COUNTA(I4:I43)=0,"",COUNTA(I4:I43)) | J44: =IF(COUNTA(J4:J43)=0,"",COUNTA(J4:J43)) | K44: =IF(COUNTA(K4:K43)=0,"",COUNTA(K4:K43)) | L44: =IF(COUNTA(L4:L43)=0,"",COUNTA(L4:L43))

Sheet 전도대상자
A1: 전도 대상자 명단
A2: NO | B2: 구역 | C2: 회(부서) | D2: 성 명 | E2: 관계 | F2: 인도자 | G2: 숙소 | I2: 비고
A3: 1
A4: 2
A5: 3
A6: 4
A7: 5
A8: 6
A9: 7
A10: 8
A11: 9
A12: 10
A13: 11
A14: 12
... A42: 40

Sheet 전도현황
A1: 2026년 하계수양회 전도 및 침례 현황
A2: NO | B2: 구역 | C2: 성명 | D2: 회(부서) | E2: 인도자 | F2: 관계 | G2: 구원시인 | H2: 침례여부 | I2: 비고
A3: 1 | B3: =IF(전도대상자!B3="","",전도대상자!B3) | C3: =IF(전도대상자!D3="","",전도대상자!D3) | D3: =IF(전도대상자!C3="","",전도대상자!C3) | E3: =IF(전도대상자!F3="","",전도대상자!F3) | F3: =IF(전도대상자!E3="","",전도대상자!E3) | I3: =IF(전도대상자!I3="","",전도대상자!I3)
A4: 2 | B4: =IF(전도대상자!B4="","",전도대상자!B4) | C4: =IF(전도대상자!D4="","",전도대상자!D4) | D4: =IF(전도대상자!C4="","",전도대상자!C4) | E4: =IF(전도대상자!F4="","",전도대상자!F4) | F4: =IF(전도대상자!E4="","",전도대상자!E4) | I4: =IF(전도대상자!I4="","",전도대상자!I4)
A5: 3 | B5: =IF(전도대상자!B5="","",전도대상자!B5) | C5: =IF(전도대상자!D5="","",전도대상자!D5) | D5: =IF(전도대상자!C5="","",전도대상자!C5) | E5: =IF(전도대상자!F5="","",전도대상자!F5) | F5: =IF(전도대상자!E5="","",전도대상자!E5) | I5: =IF(전도대상자!I5="","",전도대상자!I5)
A6: 4 | B6: =IF(전도대상자!B6="","",전도대상자!B6) | C6: =IF(전도대상자!D6="","",전도대상자!D6) | D6: =IF(전도대상자!C6="","",전도대상자!C6) | E6: =IF(전도대상자!F6="","",전도대상자!F6) | F6: =IF(전도대상자!E6="","",전도대상자!E6) | I6: =IF(전도대상자!I6="","",전도대상자!I6)
A7: 5 | B7: =IF(전도대상자!B7="","",전도대상자!B7) | C7: =IF(전도대상자!D7="","",전도대상자!D7) | D7: =IF(전도대상자!C7="","",전도대상자!C7) | E7: =IF(전도대상자!F7="","",전도대상자!F7) | F7: =IF(전도대상자!E7="","",전도대상자!E7) | I7: =IF(전도대상자!I7="","",전도대상자!I7)
A8: 6 | B8: =IF(전도대상자!B8="","",전도대상자!B8) | C8: =IF(전도대상자!D8="","",전도대상자!D8) | D8: =IF(전도대상자!C8="","",전도대상자!C8) | E8: =IF(전도대상자!F8="","",전도대상자!F8) | F8: =IF(전도대상자!E8="","",전도대상자!E8) | I8: =IF(전도대상자!I8="","",전도대상자!I8)
A9: 7 | B9: =IF(전도대상자!B9="","",전도대상자!B9) | C9: =IF(전도대상자!D9="","",전도대상자!D9) | D9: =IF(전도대상자!C9="","",전도대상자!C9) | E9: =IF(전도대상자!F9="","",전도대상자!F9) | F9: =IF(전도대상자!E9="","",전도대상자!E9) | I9: =IF(전도대상자!I9="","",전도대상자!I9)
A10: 8 | B10: =IF(전도대상자!B10="","",전도대상자!B10) | C10: =IF(전도대상자!D10="","",전도대상자!D10) | D10: =IF(전도대상자!C10="","",전도대상자!C10) | E10: =IF(전도대상자!F10="","",전도대상자!F10) | F10: =IF(전도대상자!E10="","",전도대상자!E10) | I10: =IF(전도대상자!I10="","",전도대상자!I10)
A11: 9 | B11: =IF(전도대상자!B11="","",전도대상자!B11) | C11: =IF(전도대상자!D11="","",전도대상자!D11) | D11: =IF(전도대상자!C11="","",전도대상자!C11) | E11: =IF(전도대상자!F11="","",전도대상자!F11) | F11: =IF(전도대상자!E11="","",전도대상자!E11) | I11: =IF(전도대상자!I11="","",전도대상자!I11)
A12: 10 | B12: =IF(전도대상자!B12="","",전도대상자!B12) | C12: =IF(전도대상자!D12="","",전도대상자!D12) | D12: =IF(전도대상자!C12="","",전도대상자!C12) | E12: =IF(전도대상자!F12="","",전도대상자!F12) | F12: =IF(전도대상자!E12="","",전도대상자!E12) | I12: =IF(전도대상자!I12="","",전도대상자!I12)
A13: 11 | B13: =IF(전도대상자!B13="","",전도대상자!B13) | C13: =IF(전도대상자!D13="","",전도대상자!D13) | D13: =IF(전도대상자!C13="","",전도대상자!C13) | E13: =IF(전도대상자!F13="","",전도대상자!F13) | F13: =IF(전도대상자!E13="","",전도대상자!E13) | I13: =IF(전도대상자!I13="","",전도대상자!I13)
A14: 12 | B14: =IF(전도대상자!B14="","",전도대상자!B14) | C14: =IF(전도대상자!D14="","",전도대상자!D14) | D14: =IF(전도대상자!C14="","",전도대상자!C14) | E14: =IF(전도대상자!F14="","",전도대상자!F14) | F14: =IF(전도대상자!E14="","",전도대상자!E14) | I14: =IF(전도대상자!I14="","",전도대상자!I14)
... A38: 36 | B38: =IF(전도대상자!B38="","",전도대상자!B38) | C38: =IF(전도대상자!D38="","",전도대상자!D38) | D38: =IF(전도대상자!C38="","",전도대상자!C38) | E38: =IF(전도대상자!F38="","",전도대상자!F38) | F38: =IF(전도대상자!E38="","",전도대상자!E38) | I38: =IF(전도대상자!I38="","",전도대상자!I38)

Sheet 회비지원
A1: 회비 지원 명단
A2: NO | B2: 구역 | C2: 부서(회별) | D2: 성 명 | E2: 금액 | F2: 비고 | J2: 회비
A3: 1 | E3: =IF(C3="","",VLOOKUP(C3,$J$3:$K$11,2,0)) | J3: 은장회 | K3: 50000
A4: 2 | E4: =IF(C4="","",VLOOKUP(C4,$J$3:$K$11,2,0)) | J4: 봉사회 | K4: 70000
A5: 3 | E5: =IF(C5="","",VLOOKUP(C5,$J$3:$K$11,2,0)) | J5: 어머니회 | K5: 70000
A6: 4 | E6: =IF(C6="","",VLOOKUP(C6,$J$3:$K$11,2,0)) | J6: 청년회 | K6: 70000
A7: 5 | E7: =IF(C7="","",VLOOKUP(C7,$J$3:$K$11,2,0)) | J7: 대학부 | K7: 50000
A8: 6 | E8: =IF(C8="","",VLOOKUP(C8,$J$3:$K$11,2,0)) | J8: 중고등부 | K8: 0
A9: 7 | E9: =IF(C9="","",VLOOKUP(C9,$J$3:$K$11,2,0)) | J9: 초등부 | K9: 0
A10: 8 | E10: =IF(C10="","",VLOOKUP(C10,$J$3:$K$11,2,0)) | J10: 유치부 | K10: 0
A11: 9 | E11: =IF(C11="","",VLOOKUP(C11,$J$3:$K$11,2,0)) | J11: 미취학 | K11: 0
A12: 10 | E12: =IF(C12="","",VLOOKUP(C12,$J$3:$K$11,2,0))
A13: 11 | E13: =IF(C13="","",VLOOKUP(C13,$J$3:$K$11,2,0))
A14: 12 | E14: =IF(C14="","",VLOOKUP(C14,$J$3:$K$11,2,0))
A15: 13 | E15: =IF(C15="","",VLOOKUP(C15,$J$3:$K$11,2,0))
A16: 14 | E16: =IF(C16="","",VLOOKUP(C16,$J$3:$K$11,2,0))
A17: 15 | E17: =IF(C17="","",VLOOKUP(C17,$J$3:$K$11,2,0))
A18: 16 | E18: =IF(C18="","",VLOOKUP(C18,$J$3:$K$11,2,0))
A19: 17 | E19: =IF(C19="","",VLOOKUP(C19,$J$3:$K$11,2,0))
A20: 18 | E20: =IF(C20="","",VLOOKUP(C20,$J$3:$K$11,2,0))
A21: 19 | E21: =IF(C21="","",VLOOKUP(C21,$J$3:$K$11,2,0))
A22: 20 | E22: =IF(C22="","",VLOOKUP(C22,$J$3:$K$11,2,0))
A23: 21 | E23: =IF(C23="","",VLOOKUP(C23,$J$3:$K$11,2,0))
... A82: 80 | E82: =IF(C82="","",VLOOKUP(C82,$J$3:$K$11,2,0))
A83: 합 계 | E83: =IF(SUM(E3:E82)=0,"",SUM(E3:E82))

Sheet 통계
A1: 2026년 하계수양회 교통편 통계
A2: 구역 | B2: 본대 버스 | D2: 기타 상행 | E2: 기타 하행 | F2: 교회차 | H2: 타교회 | J2: 개인차량 | L2: 대중교통
B3: 상행 | C3: 하행 | F3: 상행 | G3: 하행 | H3: 상행 | I3: 하행 | J3: 상행 | K3: 하행 | L3: 상행 | M3: 하행
A4: 11구역 | B4: =IF(COUNTIFS(11구역!F4:F43,"1호차",11구역!E4:E43,$B23)+COUNTIFS(11구역!F4:F43,"2호차",11구역!E4:E43,$B23)+COUNTIFS(11구역!F4:F43,"3호차",11구역!E4:E43,$B23)+COUNTIFS(11구역!F4:F43,"4호차",11구역!E4:E43,$B23)+COUNTIFS(11구역!F4:F43,"5호차",11구역!E4:E43,$B23)+COUNTIFS(11구역!F4:F43,"6호차",11구역!E4:E43,$B23)+COUNTIFS(11구역!F4:F43,"7호차",11구역!E4:E43,$B23)=0,"",COUNTIFS(11구역!F4:F43,"1호차",11구역!E4:E43,$B23)+COUNTIFS(11구역!F4:F43,"2호차",11구역!E4:E43,$B23)+COUNTIFS(11구역!F4:F43,"3호차",11구역!E4:E43,$B23)+COUNTIFS(11구역!F4:F43,"4호차",11구역!E4:E43,$B23)+COUNTIFS(11구역!F4:F43,"5호차",11구역!E4:E43,$B23)+COUNTIFS(11구역!F4:F43,"6호차",11구역!E4:E43,$B23)+COUNTIFS(11구역!F4:F43,"7호차",11구역!E4:E43,$B23)) | C4: =IF(COUNTIFS(11구역!G4:G43,"1호차",11구역!E4:E43,$B23)+COUNTIFS(11구역!G4:G43,"2호차",11구역!E4:E43,$B23)+COUNTIFS(11구역!G4:G43,"3호차",11구역!E4:E43,$B23)+COUNTIFS(11구역!G4:G43,"4호차",11구역!E4:E43,$B23)+COUNTIFS(11구역!G4:G43,"5호차",11구역!E4:E43,$B23)+COUNTIFS(11구역!G4:G43,"6호차",11구역!E4:E43,$B23)+COUNTIFS(11구역!G4:G43,"7호차",11구역!E4:E43,$B23)=0,"",COUNTIFS(11구역!G4:G43,"1호차",11구역!E4:E43,$B23)+COUNTIFS(11구역!G4:G43,"2호차",11구역!E4:E43,$B23)+COUNTIFS(11구역!G4:G43,"3호차",11구역!E4:E43,$B23)+COUNTIFS(11구역!G4:G43,"4호차",11구역!E4:E43,$B23)+COUNTIFS(11구역!G4:G43,"5호차",11구역!E4:E43,$B23)+COUNTIFS(11구역!G4:G43,"6호차",11구역!E4:E43,$B23)+COUNTIFS(11구역!G4:G43,"7호차",11구역!E4:E43,$B23)) | D4: =IF(COUNTIFS(11구역!H4:H43,"<>",11구역!E4:E43,$B23)=0,"",COUNTIFS(11구역!H4:H43,"<>",11구역!E4:E43,$B23)) | E4: =IF(COUNTIFS(11구역!I4:I43,"<>",11구역!E4:E43,$B23)=0,"",COUNTIFS(11구역!I4:I43,"<>",11구역!E4:E43,$B23)) | F4: =IF(COUNTIFS(11구역!F4:F43,"교회차1",11구역!E4:E43,$B23)+COUNTIFS(11구역!H4:H43,"교회차1",11구역!E4:E43,$B23)+COUNTIFS(11구역!F4:F43,"교회차2",11구역!E4:E43,$B23)+COUNTIFS(11구역!H4:H43,"교회차2",11구역!E4:E43,$B23)=0,"",COUNTIFS(11구역!F4:F43,"교회차1",11구역!E4:E43,$B23)+COUNTIFS(11구역!H4:H43,"교회차1",11구역!E4:E43,$B23)+COUNTIFS(11구역!F4:F43,"교회차2",11구역!E4:E43,$B23)+COUNTIFS(11구역!H4:H43,"교회차2",11구역!E4:E43,$B23)) | G4: =IF(COUNTIFS(11구역!G4:G43,"교회차1",11구역!E4:E43,$B23)+COUNTIFS(11구역!I4:I43,"교회차1",11구역!E4:E43,$B23)+COUNTIFS(11구역!G4:G43,"교회차2",11구역!E4:E43,$B23)+COUNTIFS(11구역!I4:I43,"교회차2",11구역!E4:E43,$B23)=0,"",COUNTIFS(11구역!G4:G43,"교회차1",11구역!E4:E43,$B23)+COUNTIFS(11구역!I4:I43,"교회차1",11구역!E4:E43,$B23)+COUNTIFS(11구역!G4:G43,"교회차2",11구역!E4:E43,$B23)+COUNTIFS(11구역!I4:I43,"교회차2",11구역!E4:E43,$B23)) | H4: =IF(COUNTIFS(11구역!F4:F43,"타교회",11구역!E4:E43,$B23)+COUNTIFS(11구역!H4:H43,"타교회",11구역!E4:E43,$B23)=0,"",COUNTIFS(11구역!F4:F43,"타교회",11구역!E4:E43,$B23)+COUNTIFS(11구역!H4:H43,"타교회",11구역!E4:E43,$B23)) | I4: =IF(COUNTIFS(11구역!G4:G43,"타교회",11구역!E4:E43,$B23)+COUNTIFS(11구역!I4:I43,"타교회",11구역!E4:E43,$B23)=0,"",COUNTIFS(11구역!G4:G43,"타교회",11구역!E4:E43,$B23)+COUNTIFS(11구역!I4:I43,"타교회",11구역!E4:E43,$B23)) | J4: =IF(COUNTIFS(11구역!F4:F43,"개인차",11구역!E4:E43,$B23)=0,"",COUNTIFS(11구역!F4:F43,"개인차",11구역!E4:E43,$B23)) | K4: =IF(COUNTIFS(11구역!G4:G43,"개인차",11구역!E4:E43,$B23)=0,"",COUNTIFS(11구역!G4:G43,"개인차",11구역!E4:E43,$B23)) | L4: =IF(COUNTIFS(11구역!F4:F43,"대중교통",11구역!E4:E43,$B23)+COUNTIFS(11구역!H4:H43,"대중교통",11구역!E4:E43,$B23)=0,"",COUNTIFS(11구역!F4:F43,"대중교통",11구역!E4:E43,$B23)+COUNTIFS(11구역!H4:H43,"대중교통",11구역!E4:E43,$B23)) | M4: =IF(COUNTIFS(11구역!G4:G43,"대중교통",11구역!E4:E43,$B23)+COUNTIFS(11구역!I4:I43,"대중교통",11구역!E4:E43,$B23)=0,"",COUNTIFS(11구역!G4:G43,"대중교통",11구역!E4:E43,$B23)+COUNTIFS(11구역!I4:I43,"대중교통",11구역!E4:E43,$B23))
A5: 12구역 | B5: =IF(COUNTIFS(12구역!F4:F43,"1호차",12구역!E4:E43,$B23)+COUNTIFS(12구역!F4:F43,"2호차",12구역!E4:E43,$B23)+COUNTIFS(12구역!F4:F43,"3호차",12구역!E4:E43,$B23)+COUNTIFS(12구역!F4:F43,"4호차",12구역!E4:E43,$B23)+COUNTIFS(12구역!F4:F43,"5호차",12구역!E4:E43,$B23)+COUNTIFS(12구역!F4:F43,"6호차",12구역!E4:E43,$B23)+COUNTIFS(12구역!F4:F43,"7호차",12구역!E4:E43,$B23)=0,"",COUNTIFS(12구역!F4:F43,"1호차",12구역!E4:E43,$B23)+COUNTIFS(12구역!F4:F43,"2호차",12구역!E4:E43,$B23)+COUNTIFS(12구역!F4:F43,"3호차",12구역!E4:E43,$B23)+COUNTIFS(12구역!F4:F43,"4호차",12구역!E4:E43,$B23)+COUNTIFS(12구역!F4:F43,"5호차",12구역!E4:E43,$B23)+COUNTIFS(12구역!F4:F43,"6호차",12구역!E4:E43,$B23)+COUNTIFS(12구역!F4:F43,"7호차",12구역!E4:E43,$B23)) | C5: =IF(COUNTIFS(12구역!G4:G43,"1호차",12구역!E4:E43,$B23)+COUNTIFS(12구역!G4:G43,"2호차",12구역!E4:E43,$B23)+COUNTIFS(12구역!G4:G43,"3호차",12구역!E4:E43,$B23)+COUNTIFS(12구역!G4:G43,"4호차",12구역!E4:E43,$B23)+COUNTIFS(12구역!G4:G43,"5호차",12구역!E4:E43,$B23)+COUNTIFS(12구역!G4:G43,"6호차",12구역!E4:E43,$B23)+COUNTIFS(12구역!G4:G43,"7호차",12구역!E4:E43,$B23)=0,"",COUNTIFS(12구역!G4:G43,"1호차",12구역!E4:E43,$B23)+COUNTIFS(12구역!G4:G43,"2호차",12구역!E4:E43,$B23)+COUNTIFS(12구역!G4:G43,"3호차",12구역!E4:E43,$B23)+COUNTIFS(12구역!G4:G43,"4호차",12구역!E4:E43,$B23)+COUNTIFS(12구역!G4:G43,"5호차",12구역!E4:E43,$B23)+COUNTIFS(12구역!G4:G43,"6호차",12구역!E4:E43,$B23)+COUNTIFS(12구역!G4:G43,"7호차",12구역!E4:E43,$B23)) | D5: =IF(COUNTIFS(12구역!H4:H43,"<>",12구역!E4:E43,$B23)=0,"",COUNTIFS(12구역!H4:H43,"<>",12구역!E4:E43,$B23)) | E5: =IF(COUNTIFS(12구역!I4:I43,"<>",12구역!E4:E43,$B23)=0,"",COUNTIFS(12구역!I4:I43,"<>",12구역!E4:E43,$B23)) | F5: =IF(COUNTIFS(12구역!F4:F43,"교회차1",12구역!E4:E43,$B23)+COUNTIFS(12구역!H4:H43,"교회차1",12구역!E4:E43,$B23)+COUNTIFS(12구역!F4:F43,"교회차2",12구역!E4:E43,$B23)+COUNTIFS(12구역!H4:H43,"교회차2",12구역!E4:E43,$B23)=0,"",COUNTIFS(12구역!F4:F43,"교회차1",12구역!E4:E43,$B23)+COUNTIFS(12구역!H4:H43,"교회차1",12구역!E4:E43,$B23)+COUNTIFS(12구역!F4:F43,"교회차2",12구역!E4:E43,$B23)+COUNTIFS(12구역!H4:H43,"교회차2",12구역!E4:E43,$B23)) | G5: =IF(COUNTIFS(12구역!G4:G43,"교회차1",12구역!E4:E43,$B23)+COUNTIFS(12구역!I4:I43,"교회차1",12구역!E4:E43,$B23)+COUNTIFS(12구역!G4:G43,"교회차2",12구역!E4:E43,$B23)+COUNTIFS(12구역!I4:I43,"교회차2",12구역!E4:E43,$B23)=0,"",COUNTIFS(12구역!G4:G43,"교회차1",12구역!E4:E43,$B23)+COUNTIFS(12구역!I4:I43,"교회차1",12구역!E4:E43,$B23)+COUNTIFS(12구역!G4:G43,"교회차2",12구역!E4:E43,$B23)+COUNTIFS(12구역!I4:I43,"교회차2",12구역!E4:E43,$B23)) | H5: =IF(COUNTIFS(12구역!F4:F43,"타교회",12구역!E4:E43,$B23)+COUNTIFS(12구역!H4:H43,"타교회",12구역!E4:E43,$B23)=0,"",COUNTIFS(12구역!F4:F43,"타교회",12구역!E4:E43,$B23)+COUNTIFS(12구역!H4:H43,"타교회",12구역!E4:E43,$B23)) | I5: =IF(COUNTIFS(12구역!G4:G43,"타교회",12구역!E4:E43,$B23)+COUNTIFS(12구역!I4:I43,"타교회",12구역!E4:E43,$B23)=0,"",COUNTIFS(12구역!G4:G43,"타교회",12구역!E4:E43,$B23)+COUNTIFS(12구역!I4:I43,"타교회",12구역!E4:E43,$B23)) | J5: =IF(COUNTIFS(12구역!F4:F43,"개인차",12구역!E4:E43,$B23)=0,"",COUNTIFS(12구역!F4:F43,"개인차",12구역!E4:E43,$B23)) | K5: =IF(COUNTIFS(12구역!G4:G43,"개인차",12구역!E4:E43,$B23)=0,"",COUNTIFS(12구역!G4:G43,"개인차",12구역!E4:E43,$B23)) | L5: =IF(COUNTIFS(12구역!F4:F43,"대중교통",12구역!E4:E43,$B23)+COUNTIFS(12구역!H4:H43,"대중교통",12구역!E4:E43,$B23)=0,"",COUNTIFS(12구역!F4:F43,"대중교통",12구역!E4:E43,$B23)+COUNTIFS(12구역!H4:H43,"대중교통",12구역!E4:E43,$B23)) | M5: =IF(COUNTIFS(12구역!G4:G43,"대중교통",12구역!E4:E43,$B23)+COUNTIFS(12구역!I4:I43,"대중교통",12구역!E4:E43,$B23)=0,"",COUNTIFS(12구역!G4:G43,"대중교통",12구역!E4:E43,$B23)+COUNTIFS(12구역!I4:I43,"대중교통",12구역!E4:E43,$B23))
A6: 13구역 | B6: =IF(COUNTIFS(13구역!F4:F43,"1호차",13구역!E4:E43,$B23)+COUNTIFS(13구역!F4:F43,"2호차",13구역!E4:E43,$B23)+COUNTIFS(13구역!F4:F43,"3호차",13구역!E4:E43,$B23)+COUNTIFS(13구역!F4:F43,"4호차",13구역!E4:E43,$B23)+COUNTIFS(13구역!F4:F43,"5호차",13구역!E4:E43,$B23)+COUNTIFS(13구역!F4:F43,"6호차",13구역!E4:E43,$B23)+COUNTIFS(13구역!F4:F43,"7호차",13구역!E4:E43,$B23)=0,"",COUNTIFS(13구역!F4:F43,"1호차",13구역!E4:E43,$B23)+COUNTIFS(13구역!F4:F43,"2호차",13구역!E4:E43,$B23)+COUNTIFS(13구역!F4:F43,"3호차",13구역!E4:E43,$B23)+COUNTIFS(13구역!F4:F43,"4호차",13구역!E4:E43,$B23)+COUNTIFS(13구역!F4:F43,"5호차",13구역!E4:E43,$B23)+COUNTIFS(13구역!F4:F43,"6호차",13구역!E4:E43,$B23)+COUNTIFS(13구역!F4:F43,"7호차",13구역!E4:E43,$B23)) | C6: =IF(COUNTIFS(13구역!G4:G43,"1호차",13구역!E4:E43,$B23)+COUNTIFS(13구역!G4:G43,"2호차",13구역!E4:E43,$B23)+COUNTIFS(13구역!G4:G43,"3호차",13구역!E4:E43,$B23)+COUNTIFS(13구역!G4:G43,"4호차",13구역!E4:E43,$B23)+COUNTIFS(13구역!G4:G43,"5호차",13구역!E4:E43,$B23)+COUNTIFS(13구역!G4:G43,"6호차",13구역!E4:E43,$B23)+COUNTIFS(13구역!G4:G43,"7호차",13구역!E4:E43,$B23)=0,"",COUNTIFS(13구역!G4:G43,"1호차",13구역!E4:E43,$B23)+COUNTIFS(13구역!G4:G43,"2호차",13구역!E4:E43,$B23)+COUNTIFS(13구역!G4:G43,"3호차",13구역!E4:E43,$B23)+COUNTIFS(13구역!G4:G43,"4호차",13구역!E4:E43,$B23)+COUNTIFS(13구역!G4:G43,"5호차",13구역!E4:E43,$B23)+COUNTIFS(13구역!G4:G43,"6호차",13구역!E4:E43,$B23)+COUNTIFS(13구역!G4:G43,"7호차",13구역!E4:E43,$B23)) | D6: =IF(COUNTIFS(13구역!H4:H43,"<>",13구역!E4:E43,$B23)=0,"",COUNTIFS(13구역!H4:H43,"<>",13구역!E4:E43,$B23)) | E6: =IF(COUNTIFS(13구역!I4:I43,"<>",13구역!E4:E43,$B23)=0,"",COUNTIFS(13구역!I4:I43,"<>",13구역!E4:E43,$B23)) | F6: =IF(COUNTIFS(13구역!F4:F43,"교회차1",13구역!E4:E43,$B23)+COUNTIFS(13구역!H4:H43,"교회차1",13구역!E4:E43,$B23)+COUNTIFS(13구역!F4:F43,"교회차2",13구역!E4:E43,$B23)+COUNTIFS(13구역!H4:H43,"교회차2",13구역!E4:E43,$B23)=0,"",COUNTIFS(13구역!F4:F43,"교회차1",13구역!E4:E43,$B23)+COUNTIFS(13구역!H4:H43,"교회차1",13구역!E4:E43,$B23)+COUNTIFS(13구역!F4:F43,"교회차2",13구역!E4:E43,$B23)+COUNTIFS(13구역!H4:H43,"교회차2",13구역!E4:E43,$B23)) | G6: =IF(COUNTIFS(13구역!G4:G43,"교회차1",13구역!E4:E43,$B23)+COUNTIFS(13구역!I4:I43,"교회차1",13구역!E4:E43,$B23)+COUNTIFS(13구역!G4:G43,"교회차2",13구역!E4:E43,$B23)+COUNTIFS(13구역!I4:I43,"교회차2",13구역!E4:E43,$B23)=0,"",COUNTIFS(13구역!G4:G43,"교회차1",13구역!E4:E43,$B23)+COUNTIFS(13구역!I4:I43,"교회차1",13구역!E4:E43,$B23)+COUNTIFS(13구역!G4:G43,"교회차2",13구역!E4:E43,$B23)+COUNTIFS(13구역!I4:I43,"교회차2",13구역!E4:E43,$B23)) | H6: =IF(COUNTIFS(13구역!F4:F43,"타교회",13구역!E4:E43,$B23)+COUNTIFS(13구역!H4:H43,"타교회",13구역!E4:E43,$B23)=0,"",COUNTIFS(13구역!F4:F43,"타교회",13구역!E4:E43,$B23)+COUNTIFS(13구역!H4:H43,"타교회",13구역!E4:E43,$B23)) | I6: =IF(COUNTIFS(13구역!G4:G43,"타교회",13구역!E4:E43,$B23)+COUNTIFS(13구역!I4:I43,"타교회",13구역!E4:E43,$B23)=0,"",COUNTIFS(13구역!G4:G43,"타교회",13구역!E4:E43,$B23)+COUNTIFS(13구역!I4:I43,"타교회",13구역!E4:E43,$B23)) | J6: =IF(COUNTIFS(13구역!F4:F43,"개인차",13구역!E4:E43,$B23)=0,"",COUNTIFS(13구역!F4:F43,"개인차",13구역!E4:E43,$B23)) | K6: =IF(COUNTIFS(13구역!G4:G43,"개인차",13구역!E4:E43,$B23)=0,"",COUNTIFS(13구역!G4:G43,"개인차",13구역!E4:E43,$B23)) | L6: =IF(COUNTIFS(13구역!F4:F43,"대중교통",13구역!E4:E43,$B23)+COUNTIFS(13구역!H4:H43,"대중교통",13구역!E4:E43,$B23)=0,"",COUNTIFS(13구역!F4:F43,"대중교통",13구역!E4:E43,$B23)+COUNTIFS(13구역!H4:H43,"대중교통",13구역!E4:E43,$B23)) | M6: =IF(COUNTIFS(13구역!G4:G43,"대중교통",13구역!E4:E43,$B23)+COUNTIFS(13구역!I4:I43,"대중교통",13구역!E4:E43,$B23)=0,"",COUNTIFS(13구역!G4:G43,"대중교통",13구역!E4:E43,$B23)+COUNTIFS(13구역!I4:I43,"대중교통",13구역!E4:E43,$B23))
A7: 14구역 | B7: =IF(COUNTIFS(14구역!F4:F43,"1호차",14구역!E4:E43,$B23)+COUNTIFS(14구역!F4:F43,"2호차",14구역!E4:E43,$B23)+COUNTIFS(14구역!F4:F43,"3호차",14구역!E4:E43,$B23)+COUNTIFS(14구역!F4:F43,"4호차",14구역!E4:E43,$B23)+COUNTIFS(14구역!F4:F43,"5호차",14구역!E4:E43,$B23)+COUNTIFS(14구역!F4:F43,"6호차",14구역!E4:E43,$B23)+COUNTIFS(14구역!F4:F43,"7호차",14구역!E4:E43,$B23)=0,"",COUNTIFS(14구역!F4:F43,"1호차",14구역!E4:E43,$B23)+COUNTIFS(14구역!F4:F43,"2호차",14구역!E4:E43,$B23)+COUNTIFS(14구역!F4:F43,"3호차",14구역!E4:E43,$B23)+COUNTIFS(14구역!F4:F43,"4호차",14구역!E4:E43,$B23)+COUNTIFS(14구역!F4:F43,"5호차",14구역!E4:E43,$B23)+COUNTIFS(14구역!F4:F43,"6호차",14구역!E4:E43,$B23)+COUNTIFS(14구역!F4:F43,"7호차",14구역!E4:E43,$B23)) | C7: =IF(COUNTIFS(14구역!G4:G43,"1호차",14구역!E4:E43,$B23)+COUNTIFS(14구역!G4:G43,"2호차",14구역!E4:E43,$B23)+COUNTIFS(14구역!G4:G43,"3호차",14구역!E4:E43,$B23)+COUNTIFS(14구역!G4:G43,"4호차",14구역!E4:E43,$B23)+COUNTIFS(14구역!G4:G43,"5호차",14구역!E4:E43,$B23)+COUNTIFS(14구역!G4:G43,"6호차",14구역!E4:E43,$B23)+COUNTIFS(14구역!G4:G43,"7호차",14구역!E4:E43,$B23)=0,"",COUNTIFS(14구역!G4:G43,"1호차",14구역!E4:E43,$B23)+COUNTIFS(14구역!G4:G43,"2호차",14구역!E4:E43,$B23)+COUNTIFS(14구역!G4:G43,"3호차",14구역!E4:E43,$B23)+COUNTIFS(14구역!G4:G43,"4호차",14구역!E4:E43,$B23)+COUNTIFS(14구역!G4:G43,"5호차",14구역!E4:E43,$B23)+COUNTIFS(14구역!G4:G43,"6호차",14구역!E4:E43,$B23)+COUNTIFS(14구역!G4:G43,"7호차",14구역!E4:E43,$B23)) | D7: =IF(COUNTIFS(14구역!H4:H43,"<>",14구역!E4:E43,$B23)=0,"",COUNTIFS(14구역!H4:H43,"<>",14구역!E4:E43,$B23)) | E7: =IF(COUNTIFS(14구역!I4:I43,"<>",14구역!E4:E43,$B23)=0,"",COUNTIFS(14구역!I4:I43,"<>",14구역!E4:E43,$B23)) | F7: =IF(COUNTIFS(14구역!F4:F43,"교회차1",14구역!E4:E43,$B23)+COUNTIFS(14구역!H4:H43,"교회차1",14구역!E4:E43,$B23)+COUNTIFS(14구역!F4:F43,"교회차2",14구역!E4:E43,$B23)+COUNTIFS(14구역!H4:H43,"교회차2",14구역!E4:E43,$B23)=0,"",COUNTIFS(14구역!F4:F43,"교회차1",14구역!E4:E43,$B23)+COUNTIFS(14구역!H4:H43,"교회차1",14구역!E4:E43,$B23)+COUNTIFS(14구역!F4:F43,"교회차2",14구역!E4:E43,$B23)+COUNTIFS(14구역!H4:H43,"교회차2",14구역!E4:E43,$B23)) | G7: =IF(COUNTIFS(14구역!G4:G43,"교회차1",14구역!E4:E43,$B23)+COUNTIFS(14구역!I4:I43,"교회차1",14구역!E4:E43,$B23)+COUNTIFS(14구역!G4:G43,"교회차2",14구역!E4:E43,$B23)+COUNTIFS(14구역!I4:I43,"교회차2",14구역!E4:E43,$B23)=0,"",COUNTIFS(14구역!G4:G43,"교회차1",14구역!E4:E43,$B23)+COUNTIFS(14구역!I4:I43,"교회차1",14구역!E4:E43,$B23)+COUNTIFS(14구역!G4:G43,"교회차2",14구역!E4:E43,$B23)+COUNTIFS(14구역!I4:I43,"교회차2",14구역!E4:E43,$B23)) | H7: =IF(COUNTIFS(14구역!F4:F43,"타교회",14구역!E4:E43,$B23)+COUNTIFS(14구역!H4:H43,"타교회",14구역!E4:E43,$B23)=0,"",COUNTIFS(14구역!F4:F43,"타교회",14구역!E4:E43,$B23)+COUNTIFS(14구역!H4:H43,"타교회",14구역!E4:E43,$B23)) | I7: =IF(COUNTIFS(14구역!G4:G43,"타교회",14구역!E4:E43,$B23)+COUNTIFS(14구역!I4:I43,"타교회",14구역!E4:E43,$B23)=0,"",COUNTIFS(14구역!G4:G43,"타교회",14구역!E4:E43,$B23)+COUNTIFS(14구역!I4:I43,"타교회",14구역!E4:E43,$B23)) | J7: =IF(COUNTIFS(14구역!F4:F43,"개인차",14구역!E4:E43,$B23)=0,"",COUNTIFS(14구역!F4:F43,"개인차",14구역!E4:E43,$B23)) | K7: =IF(COUNTIFS(14구역!G4:G43,"개인차",14구역!E4:E43,$B23)=0,"",COUNTIFS(14구역!G4:G43,"개인차",14구역!E4:E43,$B23)) | L7: =IF(COUNTIFS(14구역!F4:F43,"대중교통",14구역!E4:E43,$B23)+COUNTIFS(14구역!H4:H43,"대중교통",14구역!E4:E43,$B23)=0,"",COUNTIFS(14구역!F4:F43,"대중교통",14구역!E4:E43,$B23)+COUNTIFS(14구역!H4:H43,"대중교통",14구역!E4:E43,$B23)) | M7: =IF(COUNTIFS(14구역!G4:G43,"대중교통",14구역!E4:E43,$B23)+COUNTIFS(14구역!I4:I43,"대중교통",14구역!E4:E43,$B23)=0,"",COUNTIFS(14구역!G4:G43,"대중교통",14구역!E4:E43,$B23)+COUNTIFS(14구역!I4:I43,"대중교통",14구역!E4:E43,$B23))
A8: 21구역 | B8: =IF(COUNTIFS(21구역!F4:F43,"1호차",21구역!E4:E43,$B23)+COUNTIFS(21구역!F4:F43,"2호차",21구역!E4:E43,$B23)+COUNTIFS(21구역!F4:F43,"3호차",21구역!E4:E43,$B23)+COUNTIFS(21구역!F4:F43,"4호차",21구역!E4:E43,$B23)+COUNTIFS(21구역!F4:F43,"5호차",21구역!E4:E43,$B23)+COUNTIFS(21구역!F4:F43,"6호차",21구역!E4:E43,$B23)+COUNTIFS(21구역!F4:F43,"7호차",21구역!E4:E43,$B23)=0,"",COUNTIFS(21구역!F4:F43,"1호차",21구역!E4:E43,$B23)+COUNTIFS(21구역!F4:F43,"2호차",21구역!E4:E43,$B23)+COUNTIFS(21구역!F4:F43,"3호차",21구역!E4:E43,$B23)+COUNTIFS(21구역!F4:F43,"4호차",21구역!E4:E43,$B23)+COUNTIFS(21구역!F4:F43,"5호차",21구역!E4:E43,$B23)+COUNTIFS(21구역!F4:F43,"6호차",21구역!E4:E43,$B23)+COUNTIFS(21구역!F4:F43,"7호차",21구역!E4:E43,$B23)) | C8: =IF(COUNTIFS(21구역!G4:G43,"1호차",21구역!E4:E43,$B23)+COUNTIFS(21구역!G4:G43,"2호차",21구역!E4:E43,$B23)+COUNTIFS(21구역!G4:G43,"3호차",21구역!E4:E43,$B23)+COUNTIFS(21구역!G4:G43,"4호차",21구역!E4:E43,$B23)+COUNTIFS(21구역!G4:G43,"5호차",21구역!E4:E43,$B23)+COUNTIFS(21구역!G4:G43,"6호차",21구역!E4:E43,$B23)+COUNTIFS(21구역!G4:G43,"7호차",21구역!E4:E43,$B23)=0,"",COUNTIFS(21구역!G4:G43,"1호차",21구역!E4:E43,$B23)+COUNTIFS(21구역!G4:G43,"2호차",21구역!E4:E43,$B23)+COUNTIFS(21구역!G4:G43,"3호차",21구역!E4:E43,$B23)+COUNTIFS(21구역!G4:G43,"4호차",21구역!E4:E43,$B23)+COUNTIFS(21구역!G4:G43,"5호차",21구역!E4:E43,$B23)+COUNTIFS(21구역!G4:G43,"6호차",21구역!E4:E43,$B23)+COUNTIFS(21구역!G4:G43,"7호차",21구역!E4:E43,$B23)) | D8: =IF(COUNTIFS(21구역!H4:H43,"<>",21구역!E4:E43,$B23)=0,"",COUNTIFS(21구역!H4:H43,"<>",21구역!E4:E43,$B23)) | E8: =IF(COUNTIFS(21구역!I4:I43,"<>",21구역!E4:E43,$B23)=0,"",COUNTIFS(21구역!I4:I43,"<>",21구역!E4:E43,$B23)) | F8: =IF(COUNTIFS(21구역!F4:F43,"교회차1",21구역!E4:E43,$B23)+COUNTIFS(21구역!H4:H43,"교회차1",21구역!E4:E43,$B23)+COUNTIFS(21구역!F4:F43,"교회차2",21구역!E4:E43,$B23)+COUNTIFS(21구역!H4:H43,"교회차2",21구역!E4:E43,$B23)=0,"",COUNTIFS(21구역!F4:F43,"교회차1",21구역!E4:E43,$B23)+COUNTIFS(21구역!H4:H43,"교회차1",21구역!E4:E43,$B23)+COUNTIFS(21구역!F4:F43,"교회차2",21구역!E4:E43,$B23)+COUNTIFS(21구역!H4:H43,"교회차2",21구역!E4:E43,$B23)) | G8: =IF(COUNTIFS(21구역!G4:G43,"교회차1",21구역!E4:E43,$B23)+COUNTIFS(21구역!I4:I43,"교회차1",21구역!E4:E43,$B23)+COUNTIFS(21구역!G4:G43,"교회차2",21구역!E4:E43,$B23)+COUNTIFS(21구역!I4:I43,"교회차2",21구역!E4:E43,$B23)=0,"",COUNTIFS(21구역!G4:G43,"교회차1",21구역!E4:E43,$B23)+COUNTIFS(21구역!I4:I43,"교회차1",21구역!E4:E43,$B23)+COUNTIFS(21구역!G4:G43,"교회차2",21구역!E4:E43,$B23)+COUNTIFS(21구역!I4:I43,"교회차2",21구역!E4:E43,$B23)) | H8: =IF(COUNTIFS(21구역!F4:F43,"타교회",21구역!E4:E43,$B23)+COUNTIFS(21구역!H4:H43,"타교회",21구역!E4:E43,$B23)=0,"",COUNTIFS(21구역!F4:F43,"타교회",21구역!E4:E43,$B23)+COUNTIFS(21구역!H4:H43,"타교회",21구역!E4:E43,$B23)) | I8: =IF(COUNTIFS(21구역!G4:G43,"타교회",21구역!E4:E43,$B23)+COUNTIFS(21구역!I4:I43,"타교회",21구역!E4:E43,$B23)=0,"",COUNTIFS(21구역!G4:G43,"타교회",21구역!E4:E43,$B23)+COUNTIFS(21구역!I4:I43,"타교회",21구역!E4:E43,$B23)) | J8: =IF(COUNTIFS(21구역!F4:F43,"개인차",21구역!E4:E43,$B23)=0,"",COUNTIFS(21구역!F4:F43,"개인차",21구역!E4:E43,$B23)) | K8: =IF(COUNTIFS(21구역!G4:G43,"개인차",21구역!E4:E43,$B23)=0,"",COUNTIFS(21구역!G4:G43,"개인차",21구역!E4:E43,$B23)) | L8: =IF(COUNTIFS(21구역!F4:F43,"대중교통",21구역!E4:E43,$B23)+COUNTIFS(21구역!H4:H43,"대중교통",21구역!E4:E43,$B23)=0,"",COUNTIFS(21구역!F4:F43,"대중교통",21구역!E4:E43,$B23)+COUNTIFS(21구역!H4:H43,"대중교통",21구역!E4:E43,$B23)) | M8: =IF(COUNTIFS(21구역!G4:G43,"대중교통",21구역!E4:E43,$B23)+COUNTIFS(21구역!I4:I43,"대중교통",21구역!E4:E43,$B23)=0,"",COUNTIFS(21구역!G4:G43,"대중교통",21구역!E4:E43,$B23)+COUNTIFS(21구역!I4:I43,"대중교통",21구역!E4:E43,$B23))
A9: 22구역 | B9: =IF(COUNTIFS(22구역!F4:F43,"1호차",22구역!E4:E43,$B23)+COUNTIFS(22구역!F4:F43,"2호차",22구역!E4:E43,$B23)+COUNTIFS(22구역!F4:F43,"3호차",22구역!E4:E43,$B23)+COUNTIFS(22구역!F4:F43,"4호차",22구역!E4:E43,$B23)+COUNTIFS(22구역!F4:F43,"5호차",22구역!E4:E43,$B23)+COUNTIFS(22구역!F4:F43,"6호차",22구역!E4:E43,$B23)+COUNTIFS(22구역!F4:F43,"7호차",22구역!E4:E43,$B23)=0,"",COUNTIFS(22구역!F4:F43,"1호차",22구역!E4:E43,$B23)+COUNTIFS(22구역!F4:F43,"2호차",22구역!E4:E43,$B23)+COUNTIFS(22구역!F4:F43,"3호차",22구역!E4:E43,$B23)+COUNTIFS(22구역!F4:F43,"4호차",22구역!E4:E43,$B23)+COUNTIFS(22구역!F4:F43,"5호차",22구역!E4:E43,$B23)+COUNTIFS(22구역!F4:F43,"6호차",22구역!E4:E43,$B23)+COUNTIFS(22구역!F4:F43,"7호차",22구역!E4:E43,$B23)) | C9: =IF(COUNTIFS(22구역!G4:G43,"1호차",22구역!E4:E43,$B23)+COUNTIFS(22구역!G4:G43,"2호차",22구역!E4:E43,$B23)+COUNTIFS(22구역!G4:G43,"3호차",22구역!E4:E43,$B23)+COUNTIFS(22구역!G4:G43,"4호차",22구역!E4:E43,$B23)+COUNTIFS(22구역!G4:G43,"5호차",22구역!E4:E43,$B23)+COUNTIFS(22구역!G4:G43,"6호차",22구역!E4:E43,$B23)+COUNTIFS(22구역!G4:G43,"7호차",22구역!E4:E43,$B23)=0,"",COUNTIFS(22구역!G4:G43,"1호차",22구역!E4:E43,$B23)+COUNTIFS(22구역!G4:G43,"2호차",22구역!E4:E43,$B23)+COUNTIFS(22구역!G4:G43,"3호차",22구역!E4:E43,$B23)+COUNTIFS(22구역!G4:G43,"4호차",22구역!E4:E43,$B23)+COUNTIFS(22구역!G4:G43,"5호차",22구역!E4:E43,$B23)+COUNTIFS(22구역!G4:G43,"6호차",22구역!E4:E43,$B23)+COUNTIFS(22구역!G4:G43,"7호차",22구역!E4:E43,$B23)) | D9: =IF(COUNTIFS(22구역!H4:H43,"<>",22구역!E4:E43,$B23)=0,"",COUNTIFS(22구역!H4:H43,"<>",22구역!E4:E43,$B23)) | E9: =IF(COUNTIFS(22구역!I4:I43,"<>",22구역!E4:E43,$B23)=0,"",COUNTIFS(22구역!I4:I43,"<>",22구역!E4:E43,$B23)) | F9: =IF(COUNTIFS(22구역!F4:F43,"교회차1",22구역!E4:E43,$B23)+COUNTIFS(22구역!H4:H43,"교회차1",22구역!E4:E43,$B23)+COUNTIFS(22구역!F4:F43,"교회차2",22구역!E4:E43,$B23)+COUNTIFS(22구역!H4:H43,"교회차2",22구역!E4:E43,$B23)=0,"",COUNTIFS(22구역!F4:F43,"교회차1",22구역!E4:E43,$B23)+COUNTIFS(22구역!H4:H43,"교회차1",22구역!E4:E43,$B23)+COUNTIFS(22구역!F4:F43,"교회차2",22구역!E4:E43,$B23)+COUNTIFS(22구역!H4:H43,"교회차2",22구역!E4:E43,$B23)) | G9: =IF(COUNTIFS(22구역!G4:G43,"교회차1",22구역!E4:E43,$B23)+COUNTIFS(22구역!I4:I43,"교회차1",22구역!E4:E43,$B23)+COUNTIFS(22구역!G4:G43,"교회차2",22구역!E4:E43,$B23)+COUNTIFS(22구역!I4:I43,"교회차2",22구역!E4:E43,$B23)=0,"",COUNTIFS(22구역!G4:G43,"교회차1",22구역!E4:E43,$B23)+COUNTIFS(22구역!I4:I43,"교회차1",22구역!E4:E43,$B23)+COUNTIFS(22구역!G4:G43,"교회차2",22구역!E4:E43,$B23)+COUNTIFS(22구역!I4:I43,"교회차2",22구역!E4:E43,$B23)) | H9: =IF(COUNTIFS(22구역!F4:F43,"타교회",22구역!E4:E43,$B23)+COUNTIFS(22구역!H4:H43,"타교회",22구역!E4:E43,$B23)=0,"",COUNTIFS(22구역!F4:F43,"타교회",22구역!E4:E43,$B23)+COUNTIFS(22구역!H4:H43,"타교회",22구역!E4:E43,$B23)) | I9: =IF(COUNTIFS(22구역!G4:G43,"타교회",22구역!E4:E43,$B23)+COUNTIFS(22구역!I4:I43,"타교회",22구역!E4:E43,$B23)=0,"",COUNTIFS(22구역!G4:G43,"타교회",22구역!E4:E43,$B23)+COUNTIFS(22구역!I4:I43,"타교회",22구역!E4:E43,$B23)) | J9: =IF(COUNTIFS(22구역!F4:F43,"개인차",22구역!E4:E43,$B23)=0,"",COUNTIFS(22구역!F4:F43,"개인차",22구역!E4:E43,$B23)) | K9: =IF(COUNTIFS(22구역!G4:G43,"개인차",22구역!E4:E43,$B23)=0,"",COUNTIFS(22구역!G4:G43,"개인차",22구역!E4:E43,$B23)) | L9: =IF(COUNTIFS(22구역!F4:F43,"대중교통",22구역!E4:E43,$B23)+COUNTIFS(22구역!H4:H43,"대중교통",22구역!E4:E43,$B23)=0,"",COUNTIFS(22구역!F4:F43,"대중교통",22구역!E4:E43,$B23)+COUNTIFS(22구역!H4:H43,"대중교통",22구역!E4:E43,$B23)) | M9: =IF(COUNTIFS(22구역!G4:G43,"대중교통",22구역!E4:E43,$B23)+COUNTIFS(22구역!I4:I43,"대중교통",22구역!E4:E43,$B23)=0,"",COUNTIFS(22구역!G4:G43,"대중교통",22구역!E4:E43,$B23)+COUNTIFS(22구역!I4:I43,"대중교통",22구역!E4:E43,$B23))
A10: 23구역 | B10: =IF(COUNTIFS(23구역!F4:F43,"1호차",23구역!E4:E43,$B23)+COUNTIFS(23구역!F4:F43,"2호차",23구역!E4:E43,$B23)+COUNTIFS(23구역!F4:F43,"3호차",23구역!E4:E43,$B23)+COUNTIFS(23구역!F4:F43,"4호차",23구역!E4:E43,$B23)+COUNTIFS(23구역!F4:F43,"5호차",23구역!E4:E43,$B23)+COUNTIFS(23구역!F4:F43,"6호차",23구역!E4:E43,$B23)+COUNTIFS(23구역!F4:F43,"7호차",23구역!E4:E43,$B23)=0,"",COUNTIFS(23구역!F4:F43,"1호차",23구역!E4:E43,$B23)+COUNTIFS(23구역!F4:F43,"2호차",23구역!E4:E43,$B23)+COUNTIFS(23구역!F4:F43,"3호차",23구역!E4:E43,$B23)+COUNTIFS(23구역!F4:F43,"4호차",23구역!E4:E43,$B23)+COUNTIFS(23구역!F4:F43,"5호차",23구역!E4:E43,$B23)+COUNTIFS(23구역!F4:F43,"6호차",23구역!E4:E43,$B23)+COUNTIFS(23구역!F4:F43,"7호차",23구역!E4:E43,$B23)) | C10: =IF(COUNTIFS(23구역!G4:G43,"1호차",23구역!E4:E43,$B23)+COUNTIFS(23구역!G4:G43,"2호차",23구역!E4:E43,$B23)+COUNTIFS(23구역!G4:G43,"3호차",23구역!E4:E43,$B23)+COUNTIFS(23구역!G4:G43,"4호차",23구역!E4:E43,$B23)+COUNTIFS(23구역!G4:G43,"5호차",23구역!E4:E43,$B23)+COUNTIFS(23구역!G4:G43,"6호차",23구역!E4:E43,$B23)+COUNTIFS(23구역!G4:G43,"7호차",23구역!E4:E43,$B23)=0,"",COUNTIFS(23구역!G4:G43,"1호차",23구역!E4:E43,$B23)+COUNTIFS(23구역!G4:G43,"2호차",23구역!E4:E43,$B23)+COUNTIFS(23구역!G4:G43,"3호차",23구역!E4:E43,$B23)+COUNTIFS(23구역!G4:G43,"4호차",23구역!E4:E43,$B23)+COUNTIFS(23구역!G4:G43,"5호차",23구역!E4:E43,$B23)+COUNTIFS(23구역!G4:G43,"6호차",23구역!E4:E43,$B23)+COUNTIFS(23구역!G4:G43,"7호차",23구역!E4:E43,$B23)) | D10: =IF(COUNTIFS(23구역!H4:H43,"<>",23구역!E4:E43,$B23)=0,"",COUNTIFS(23구역!H4:H43,"<>",23구역!E4:E43,$B23)) | E10: =IF(COUNTIFS(23구역!I4:I43,"<>",23구역!E4:E43,$B23)=0,"",COUNTIFS(23구역!I4:I43,"<>",23구역!E4:E43,$B23)) | F10: =IF(COUNTIFS(23구역!F4:F43,"교회차1",23구역!E4:E43,$B23)+COUNTIFS(23구역!H4:H43,"교회차1",23구역!E4:E43,$B23)+COUNTIFS(23구역!F4:F43,"교회차2",23구역!E4:E43,$B23)+COUNTIFS(23구역!H4:H43,"교회차2",23구역!E4:E43,$B23)=0,"",COUNTIFS(23구역!F4:F43,"교회차1",23구역!E4:E43,$B23)+COUNTIFS(23구역!H4:H43,"교회차1",23구역!E4:E43,$B23)+COUNTIFS(23구역!F4:F43,"교회차2",23구역!E4:E43,$B23)+COUNTIFS(23구역!H4:H43,"교회차2",23구역!E4:E43,$B23)) | G10: =IF(COUNTIFS(23구역!G4:G43,"교회차1",23구역!E4:E43,$B23)+COUNTIFS(23구역!I4:I43,"교회차1",23구역!E4:E43,$B23)+COUNTIFS(23구역!G4:G43,"교회차2",23구역!E4:E43,$B23)+COUNTIFS(23구역!I4:I43,"교회차2",23구역!E4:E43,$B23)=0,"",COUNTIFS(23구역!G4:G43,"교회차1",23구역!E4:E43,$B23)+COUNTIFS(23구역!I4:I43,"교회차1",23구역!E4:E43,$B23)+COUNTIFS(23구역!G4:G43,"교회차2",23구역!E4:E43,$B23)+COUNTIFS(23구역!I4:I43,"교회차2",23구역!E4:E43,$B23)) | H10: =IF(COUNTIFS(23구역!F4:F43,"타교회",23구역!E4:E43,$B23)+COUNTIFS(23구역!H4:H43,"타교회",23구역!E4:E43,$B23)=0,"",COUNTIFS(23구역!F4:F43,"타교회",23구역!E4:E43,$B23)+COUNTIFS(23구역!H4:H43,"타교회",23구역!E4:E43,$B23)) | I10: =IF(COUNTIFS(23구역!G4:G43,"타교회",23구역!E4:E43,$B23)+COUNTIFS(23구역!I4:I43,"타교회",23구역!E4:E43,$B23)=0,"",COUNTIFS(23구역!G4:G43,"타교회",23구역!E4:E43,$B23)+COUNTIFS(23구역!I4:I43,"타교회",23구역!E4:E43,$B23)) | J10: =IF(COUNTIFS(23구역!F4:F43,"개인차",23구역!E4:E43,$B23)=0,"",COUNTIFS(23구역!F4:F43,"개인차",23구역!E4:E43,$B23)) | K10: =IF(COUNTIFS(23구역!G4:G43,"개인차",23구역!E4:E43,$B23)=0,"",COUNTIFS(23구역!G4:G43,"개인차",23구역!E4:E43,$B23)) | L10: =IF(COUNTIFS(23구역!F4:F43,"대중교통",23구역!E4:E43,$B23)+COUNTIFS(23구역!H4:H43,"대중교통",23구역!E4:E43,$B23)=0,"",COUNTIFS(23구역!F4:F43,"대중교통",23구역!E4:E43,$B23)+COUNTIFS(23구역!H4:H43,"대중교통",23구역!E4:E43,$B23)) | M10: =IF(COUNTIFS(23구역!G4:G43,"대중교통",23구역!E4:E43,$B23)+COUNTIFS(23구역!I4:I43,"대중교통",23구역!E4:E43,$B23)=0,"",COUNTIFS(23구역!G4:G43,"대중교통",23구역!E4:E43,$B23)+COUNTIFS(23구역!I4:I43,"대중교통",23구역!E4:E43,$B23))
A11: 24구역 | B11: =IF(COUNTIFS(24구역!F4:F43,"1호차",24구역!E4:E43,$B23)+COUNTIFS(24구역!F4:F43,"2호차",24구역!E4:E43,$B23)+COUNTIFS(24구역!F4:F43,"3호차",24구역!E4:E43,$B23)+COUNTIFS(24구역!F4:F43,"4호차",24구역!E4:E43,$B23)+COUNTIFS(24구역!F4:F43,"5호차",24구역!E4:E43,$B23)+COUNTIFS(24구역!F4:F43,"6호차",24구역!E4:E43,$B23)+COUNTIFS(24구역!F4:F43,"7호차",24구역!E4:E43,$B23)=0,"",COUNTIFS(24구역!F4:F43,"1호차",24구역!E4:E43,$B23)+COUNTIFS(24구역!F4:F43,"2호차",24구역!E4:E43,$B23)+COUNTIFS(24구역!F4:F43,"3호차",24구역!E4:E43,$B23)+COUNTIFS(24구역!F4:F43,"4호차",24구역!E4:E43,$B23)+COUNTIFS(24구역!F4:F43,"5호차",24구역!E4:E43,$B23)+COUNTIFS(24구역!F4:F43,"6호차",24구역!E4:E43,$B23)+COUNTIFS(24구역!F4:F43,"7호차",24구역!E4:E43,$B23)) | C11: =IF(COUNTIFS(24구역!G4:G43,"1호차",24구역!E4:E43,$B23)+COUNTIFS(24구역!G4:G43,"2호차",24구역!E4:E43,$B23)+COUNTIFS(24구역!G4:G43,"3호차",24구역!E4:E43,$B23)+COUNTIFS(24구역!G4:G43,"4호차",24구역!E4:E43,$B23)+COUNTIFS(24구역!G4:G43,"5호차",24구역!E4:E43,$B23)+COUNTIFS(24구역!G4:G43,"6호차",24구역!E4:E43,$B23)+COUNTIFS(24구역!G4:G43,"7호차",24구역!E4:E43,$B23)=0,"",COUNTIFS(24구역!G4:G43,"1호차",24구역!E4:E43,$B23)+COUNTIFS(24구역!G4:G43,"2호차",24구역!E4:E43,$B23)+COUNTIFS(24구역!G4:G43,"3호차",24구역!E4:E43,$B23)+COUNTIFS(24구역!G4:G43,"4호차",24구역!E4:E43,$B23)+COUNTIFS(24구역!G4:G43,"5호차",24구역!E4:E43,$B23)+COUNTIFS(24구역!G4:G43,"6호차",24구역!E4:E43,$B23)+COUNTIFS(24구역!G4:G43,"7호차",24구역!E4:E43,$B23)) | D11: =IF(COUNTIFS(24구역!H4:H43,"<>",24구역!E4:E43,$B23)=0,"",COUNTIFS(24구역!H4:H43,"<>",24구역!E4:E43,$B23)) | E11: =IF(COUNTIFS(24구역!I4:I43,"<>",24구역!E4:E43,$B23)=0,"",COUNTIFS(24구역!I4:I43,"<>",24구역!E4:E43,$B23)) | F11: =IF(COUNTIFS(24구역!F4:F43,"교회차1",24구역!E4:E43,$B23)+COUNTIFS(24구역!H4:H43,"교회차1",24구역!E4:E43,$B23)+COUNTIFS(24구역!F4:F43,"교회차2",24구역!E4:E43,$B23)+COUNTIFS(24구역!H4:H43,"교회차2",24구역!E4:E43,$B23)=0,"",COUNTIFS(24구역!F4:F43,"교회차1",24구역!E4:E43,$B23)+COUNTIFS(24구역!H4:H43,"교회차1",24구역!E4:E43,$B23)+COUNTIFS(24구역!F4:F43,"교회차2",24구역!E4:E43,$B23)+COUNTIFS(24구역!H4:H43,"교회차2",24구역!E4:E43,$B23)) | G11: =IF(COUNTIFS(24구역!G4:G43,"교회차1",24구역!E4:E43,$B23)+COUNTIFS(24구역!I4:I43,"교회차1",24구역!E4:E43,$B23)+COUNTIFS(24구역!G4:G43,"교회차2",24구역!E4:E43,$B23)+COUNTIFS(24구역!I4:I43,"교회차2",24구역!E4:E43,$B23)=0,"",COUNTIFS(24구역!G4:G43,"교회차1",24구역!E4:E43,$B23)+COUNTIFS(24구역!I4:I43,"교회차1",24구역!E4:E43,$B23)+COUNTIFS(24구역!G4:G43,"교회차2",24구역!E4:E43,$B23)+COUNTIFS(24구역!I4:I43,"교회차2",24구역!E4:E43,$B23)) | H11: =IF(COUNTIFS(24구역!F4:F43,"타교회",24구역!E4:E43,$B23)+COUNTIFS(24구역!H4:H43,"타교회",24구역!E4:E43,$B23)=0,"",COUNTIFS(24구역!F4:F43,"타교회",24구역!E4:E43,$B23)+COUNTIFS(24구역!H4:H43,"타교회",24구역!E4:E43,$B23)) | I11: =IF(COUNTIFS(24구역!G4:G43,"타교회",24구역!E4:E43,$B23)+COUNTIFS(24구역!I4:I43,"타교회",24구역!E4:E43,$B23)=0,"",COUNTIFS(24구역!G4:G43,"타교회",24구역!E4:E43,$B23)+COUNTIFS(24구역!I4:I43,"타교회",24구역!E4:E43,$B23)) | J11: =IF(COUNTIFS(24구역!F4:F43,"개인차",24구역!E4:E43,$B23)=0,"",COUNTIFS(24구역!F4:F43,"개인차",24구역!E4:E43,$B23)) | K11: =IF(COUNTIFS(24구역!G4:G43,"개인차",24구역!E4:E43,$B23)=0,"",COUNTIFS(24구역!G4:G43,"개인차",24구역!E4:E43,$B23)) | L11: =IF(COUNTIFS(24구역!F4:F43,"대중교통",24구역!E4:E43,$B23)+COUNTIFS(24구역!H4:H43,"대중교통",24구역!E4:E43,$B23)=0,"",COUNTIFS(24구역!F4:F43,"대중교통",24구역!E4:E43,$B23)+COUNTIFS(24구역!H4:H43,"대중교통",24구역!E4:E43,$B23)) | M11: =IF(COUNTIFS(24구역!G4:G43,"대중교통",24구역!E4:E43,$B23)+COUNTIFS(24구역!I4:I43,"대중교통",24구역!E4:E43,$B23)=0,"",COUNTIFS(24구역!G4:G43,"대중교통",24구역!E4:E43,$B23)+COUNTIFS(24구역!I4:I43,"대중교통",24구역!E4:E43,$B23))
A12: 31구역 | B12: =IF(COUNTIFS(31구역!F4:F43,"1호차",31구역!E4:E43,$B23)+COUNTIFS(31구역!F4:F43,"2호차",31구역!E4:E43,$B23)+COUNTIFS(31구역!F4:F43,"3호차",31구역!E4:E43,$B23)+COUNTIFS(31구역!F4:F43,"4호차",31구역!E4:E43,$B23)+COUNTIFS(31구역!F4:F43,"5호차",31구역!E4:E43,$B23)+COUNTIFS(31구역!F4:F43,"6호차",31구역!E4:E43,$B23)+COUNTIFS(31구역!F4:F43,"7호차",31구역!E4:E43,$B23)=0,"",COUNTIFS(31구역!F4:F43,"1호차",31구역!E4:E43,$B23)+COUNTIFS(31구역!F4:F43,"2호차",31구역!E4:E43,$B23)+COUNTIFS(31구역!F4:F43,"3호차",31구역!E4:E43,$B23)+COUNTIFS(31구역!F4:F43,"4호차",31구역!E4:E43,$B23)+COUNTIFS(31구역!F4:F43,"5호차",31구역!E4:E43,$B23)+COUNTIFS(31구역!F4:F43,"6호차",31구역!E4:E43,$B23)+COUNTIFS(31구역!F4:F43,"7호차",31구역!E4:E43,$B23)) | C12: =IF(COUNTIFS(31구역!G4:G43,"1호차",31구역!E4:E43,$B23)+COUNTIFS(31구역!G4:G43,"2호차",31구역!E4:E43,$B23)+COUNTIFS(31구역!G4:G43,"3호차",31구역!E4:E43,$B23)+COUNTIFS(31구역!G4:G43,"4호차",31구역!E4:E43,$B23)+COUNTIFS(31구역!G4:G43,"5호차",31구역!E4:E43,$B23)+COUNTIFS(31구역!G4:G43,"6호차",31구역!E4:E43,$B23)+COUNTIFS(31구역!G4:G43,"7호차",31구역!E4:E43,$B23)=0,"",COUNTIFS(31구역!G4:G43,"1호차",31구역!E4:E43,$B23)+COUNTIFS(31구역!G4:G43,"2호차",31구역!E4:E43,$B23)+COUNTIFS(31구역!G4:G43,"3호차",31구역!E4:E43,$B23)+COUNTIFS(31구역!G4:G43,"4호차",31구역!E4:E43,$B23)+COUNTIFS(31구역!G4:G43,"5호차",31구역!E4:E43,$B23)+COUNTIFS(31구역!G4:G43,"6호차",31구역!E4:E43,$B23)+COUNTIFS(31구역!G4:G43,"7호차",31구역!E4:E43,$B23)) | D12: =IF(COUNTIFS(31구역!H4:H43,"<>",31구역!E4:E43,$B23)=0,"",COUNTIFS(31구역!H4:H43,"<>",31구역!E4:E43,$B23)) | E12: =IF(COUNTIFS(31구역!I4:I43,"<>",31구역!E4:E43,$B23)=0,"",COUNTIFS(31구역!I4:I43,"<>",31구역!E4:E43,$B23)) | F12: =IF(COUNTIFS(31구역!F4:F43,"교회차1",31구역!E4:E43,$B23)+COUNTIFS(31구역!H4:H43,"교회차1",31구역!E4:E43,$B23)+COUNTIFS(31구역!F4:F43,"교회차2",31구역!E4:E43,$B23)+COUNTIFS(31구역!H4:H43,"교회차2",31구역!E4:E43,$B23)=0,"",COUNTIFS(31구역!F4:F43,"교회차1",31구역!E4:E43,$B23)+COUNTIFS(31구역!H4:H43,"교회차1",31구역!E4:E43,$B23)+COUNTIFS(31구역!F4:F43,"교회차2",31구역!E4:E43,$B23)+COUNTIFS(31구역!H4:H43,"교회차2",31구역!E4:E43,$B23)) | G12: =IF(COUNTIFS(31구역!G4:G43,"교회차1",31구역!E4:E43,$B23)+COUNTIFS(31구역!I4:I43,"교회차1",31구역!E4:E43,$B23)+COUNTIFS(31구역!G4:G43,"교회차2",31구역!E4:E43,$B23)+COUNTIFS(31구역!I4:I43,"교회차2",31구역!E4:E43,$B23)=0,"",COUNTIFS(31구역!G4:G43,"교회차1",31구역!E4:E43,$B23)+COUNTIFS(31구역!I4:I43,"교회차1",31구역!E4:E43,$B23)+COUNTIFS(31구역!G4:G43,"교회차2",31구역!E4:E43,$B23)+COUNTIFS(31구역!I4:I43,"교회차2",31구역!E4:E43,$B23)) | H12: =IF(COUNTIFS(31구역!F4:F43,"타교회",31구역!E4:E43,$B23)+COUNTIFS(31구역!H4:H43,"타교회",31구역!E4:E43,$B23)=0,"",COUNTIFS(31구역!F4:F43,"타교회",31구역!E4:E43,$B23)+COUNTIFS(31구역!H4:H43,"타교회",31구역!E4:E43,$B23)) | I12: =IF(COUNTIFS(31구역!G4:G43,"타교회",31구역!E4:E43,$B23)+COUNTIFS(31구역!I4:I43,"타교회",31구역!E4:E43,$B23)=0,"",COUNTIFS(31구역!G4:G43,"타교회",31구역!E4:E43,$B23)+COUNTIFS(31구역!I4:I43,"타교회",31구역!E4:E43,$B23)) | J12: =IF(COUNTIFS(31구역!F4:F43,"개인차",31구역!E4:E43,$B23)=0,"",COUNTIFS(31구역!F4:F43,"개인차",31구역!E4:E43,$B23)) | K12: =IF(COUNTIFS(31구역!G4:G43,"개인차",31구역!E4:E43,$B23)=0,"",COUNTIFS(31구역!G4:G43,"개인차",31구역!E4:E43,$B23)) | L12: =IF(COUNTIFS(31구역!F4:F43,"대중교통",31구역!E4:E43,$B23)+COUNTIFS(31구역!H4:H43,"대중교통",31구역!E4:E43,$B23)=0,"",COUNTIFS(31구역!F4:F43,"대중교통",31구역!E4:E43,$B23)+COUNTIFS(31구역!H4:H43,"대중교통",31구역!E4:E43,$B23)) | M12: =IF(COUNTIFS(31구역!G4:G43,"대중교통",31구역!E4:E43,$B23)+COUNTIFS(31구역!I4:I43,"대중교통",31구역!E4:E43,$B23)=0,"",COUNTIFS(31구역!G4:G43,"대중교통",31구역!E4:E43,$B23)+COUNTIFS(31구역!I4:I43,"대중교통",31구역!E4:E43,$B23))
A13: 32구역 | B13: =IF(COUNTIFS(32구역!F4:F43,"1호차",32구역!E4:E43,$B23)+COUNTIFS(32구역!F4:F43,"2호차",32구역!E4:E43,$B23)+COUNTIFS(32구역!F4:F43,"3호차",32구역!E4:E43,$B23)+COUNTIFS(32구역!F4:F43,"4호차",32구역!E4:E43,$B23)+COUNTIFS(32구역!F4:F43,"5호차",32구역!E4:E43,$B23)+COUNTIFS(32구역!F4:F43,"6호차",32구역!E4:E43,$B23)+COUNTIFS(32구역!F4:F43,"7호차",32구역!E4:E43,$B23)=0,"",COUNTIFS(32구역!F4:F43,"1호차",32구역!E4:E43,$B23)+COUNTIFS(32구역!F4:F43,"2호차",32구역!E4:E43,$B23)+COUNTIFS(32구역!F4:F43,"3호차",32구역!E4:E43,$B23)+COUNTIFS(32구역!F4:F43,"4호차",32구역!E4:E43,$B23)+COUNTIFS(32구역!F4:F43,"5호차",32구역!E4:E43,$B23)+COUNTIFS(32구역!F4:F43,"6호차",32구역!E4:E43,$B23)+COUNTIFS(32구역!F4:F43,"7호차",32구역!E4:E43,$B23)) | C13: =IF(COUNTIFS(32구역!G4:G43,"1호차",32구역!E4:E43,$B23)+COUNTIFS(32구역!G4:G43,"2호차",32구역!E4:E43,$B23)+COUNTIFS(32구역!G4:G43,"3호차",32구역!E4:E43,$B23)+COUNTIFS(32구역!G4:G43,"4호차",32구역!E4:E43,$B23)+COUNTIFS(32구역!G4:G43,"5호차",32구역!E4:E43,$B23)+COUNTIFS(32구역!G4:G43,"6호차",32구역!E4:E43,$B23)+COUNTIFS(32구역!G4:G43,"7호차",32구역!E4:E43,$B23)=0,"",COUNTIFS(32구역!G4:G43,"1호차",32구역!E4:E43,$B23)+COUNTIFS(32구역!G4:G43,"2호차",32구역!E4:E43,$B23)+COUNTIFS(32구역!G4:G43,"3호차",32구역!E4:E43,$B23)+COUNTIFS(32구역!G4:G43,"4호차",32구역!E4:E43,$B23)+COUNTIFS(32구역!G4:G43,"5호차",32구역!E4:E43,$B23)+COUNTIFS(32구역!G4:G43,"6호차",32구역!E4:E43,$B23)+COUNTIFS(32구역!G4:G43,"7호차",32구역!E4:E43,$B23)) | D13: =IF(COUNTIFS(32구역!H4:H43,"<>",32구역!E4:E43,$B23)=0,"",COUNTIFS(32구역!H4:H43,"<>",32구역!E4:E43,$B23)) | E13: =IF(COUNTIFS(32구역!I4:I43,"<>",32구역!E4:E43,$B23)=0,"",COUNTIFS(32구역!I4:I43,"<>",32구역!E4:E43,$B23)) | F13: =IF(COUNTIFS(32구역!F4:F43,"교회차1",32구역!E4:E43,$B23)+COUNTIFS(32구역!H4:H43,"교회차1",32구역!E4:E43,$B23)+COUNTIFS(32구역!F4:F43,"교회차2",32구역!E4:E43,$B23)+COUNTIFS(32구역!H4:H43,"교회차2",32구역!E4:E43,$B23)=0,"",COUNTIFS(32구역!F4:F43,"교회차1",32구역!E4:E43,$B23)+COUNTIFS(32구역!H4:H43,"교회차1",32구역!E4:E43,$B23)+COUNTIFS(32구역!F4:F43,"교회차2",32구역!E4:E43,$B23)+COUNTIFS(32구역!H4:H43,"교회차2",32구역!E4:E43,$B23)) | G13: =IF(COUNTIFS(32구역!G4:G43,"교회차1",32구역!E4:E43,$B23)+COUNTIFS(32구역!I4:I43,"교회차1",32구역!E4:E43,$B23)+COUNTIFS(32구역!G4:G43,"교회차2",32구역!E4:E43,$B23)+COUNTIFS(32구역!I4:I43,"교회차2",32구역!E4:E43,$B23)=0,"",COUNTIFS(32구역!G4:G43,"교회차1",32구역!E4:E43,$B23)+COUNTIFS(32구역!I4:I43,"교회차1",32구역!E4:E43,$B23)+COUNTIFS(32구역!G4:G43,"교회차2",32구역!E4:E43,$B23)+COUNTIFS(32구역!I4:I43,"교회차2",32구역!E4:E43,$B23)) | H13: =IF(COUNTIFS(32구역!F4:F43,"타교회",32구역!E4:E43,$B23)+COUNTIFS(32구역!H4:H43,"타교회",32구역!E4:E43,$B23)=0,"",COUNTIFS(32구역!F4:F43,"타교회",32구역!E4:E43,$B23)+COUNTIFS(32구역!H4:H43,"타교회",32구역!E4:E43,$B23)) | I13: =IF(COUNTIFS(32구역!G4:G43,"타교회",32구역!E4:E43,$B23)+COUNTIFS(32구역!I4:I43,"타교회",32구역!E4:E43,$B23)=0,"",COUNTIFS(32구역!G4:G43,"타교회",32구역!E4:E43,$B23)+COUNTIFS(32구역!I4:I43,"타교회",32구역!E4:E43,$B23)) | J13: =IF(COUNTIFS(32구역!F4:F43,"개인차",32구역!E4:E43,$B23)=0,"",COUNTIFS(32구역!F4:F43,"개인차",32구역!E4:E43,$B23)) | K13: =IF(COUNTIFS(32구역!G4:G43,"개인차",32구역!E4:E43,$B23)=0,"",COUNTIFS(32구역!G4:G43,"개인차",32구역!E4:E43,$B23)) | L13: =IF(COUNTIFS(32구역!F4:F43,"대중교통",32구역!E4:E43,$B23)+COUNTIFS(32구역!H4:H43,"대중교통",32구역!E4:E43,$B23)=0,"",COUNTIFS(32구역!F4:F43,"대중교통",32구역!E4:E43,$B23)+COUNTIFS(32구역!H4:H43,"대중교통",32구역!E4:E43,$B23)) | M13: =IF(COUNTIFS(32구역!G4:G43,"대중교통",32구역!E4:E43,$B23)+COUNTIFS(32구역!I4:I43,"대중교통",32구역!E4:E43,$B23)=0,"",COUNTIFS(32구역!G4:G43,"대중교통",32구역!E4:E43,$B23)+COUNTIFS(32구역!I4:I43,"대중교통",32구역!E4:E43,$B23))
A14: 33구역 | B14: =IF(COUNTIFS(33구역!F4:F43,"1호차",33구역!E4:E43,$B23)+COUNTIFS(33구역!F4:F43,"2호차",33구역!E4:E43,$B23)+COUNTIFS(33구역!F4:F43,"3호차",33구역!E4:E43,$B23)+COUNTIFS(33구역!F4:F43,"4호차",33구역!E4:E43,$B23)+COUNTIFS(33구역!F4:F43,"5호차",33구역!E4:E43,$B23)+COUNTIFS(33구역!F4:F43,"6호차",33구역!E4:E43,$B23)+COUNTIFS(33구역!F4:F43,"7호차",33구역!E4:E43,$B23)=0,"",COUNTIFS(33구역!F4:F43,"1호차",33구역!E4:E43,$B23)+COUNTIFS(33구역!F4:F43,"2호차",33구역!E4:E43,$B23)+COUNTIFS(33구역!F4:F43,"3호차",33구역!E4:E43,$B23)+COUNTIFS(33구역!F4:F43,"4호차",33구역!E4:E43,$B23)+COUNTIFS(33구역!F4:F43,"5호차",33구역!E4:E43,$B23)+COUNTIFS(33구역!F4:F43,"6호차",33구역!E4:E43,$B23)+COUNTIFS(33구역!F4:F43,"7호차",33구역!E4:E43,$B23)) | C14: =IF(COUNTIFS(33구역!G4:G43,"1호차",33구역!E4:E43,$B23)+COUNTIFS(33구역!G4:G43,"2호차",33구역!E4:E43,$B23)+COUNTIFS(33구역!G4:G43,"3호차",33구역!E4:E43,$B23)+COUNTIFS(33구역!G4:G43,"4호차",33구역!E4:E43,$B23)+COUNTIFS(33구역!G4:G43,"5호차",33구역!E4:E43,$B23)+COUNTIFS(33구역!G4:G43,"6호차",33구역!E4:E43,$B23)+COUNTIFS(33구역!G4:G43,"7호차",33구역!E4:E43,$B23)=0,"",COUNTIFS(33구역!G4:G43,"1호차",33구역!E4:E43,$B23)+COUNTIFS(33구역!G4:G43,"2호차",33구역!E4:E43,$B23)+COUNTIFS(33구역!G4:G43,"3호차",33구역!E4:E43,$B23)+COUNTIFS(33구역!G4:G43,"4호차",33구역!E4:E43,$B23)+COUNTIFS(33구역!G4:G43,"5호차",33구역!E4:E43,$B23)+COUNTIFS(33구역!G4:G43,"6호차",33구역!E4:E43,$B23)+COUNTIFS(33구역!G4:G43,"7호차",33구역!E4:E43,$B23)) | D14: =IF(COUNTIFS(33구역!H4:H43,"<>",33구역!E4:E43,$B23)=0,"",COUNTIFS(33구역!H4:H43,"<>",33구역!E4:E43,$B23)) | E14: =IF(COUNTIFS(33구역!I4:I43,"<>",33구역!E4:E43,$B23)=0,"",COUNTIFS(33구역!I4:I43,"<>",33구역!E4:E43,$B23)) | F14: =IF(COUNTIFS(33구역!F4:F43,"교회차1",33구역!E4:E43,$B23)+COUNTIFS(33구역!H4:H43,"교회차1",33구역!E4:E43,$B23)+COUNTIFS(33구역!F4:F43,"교회차2",33구역!E4:E43,$B23)+COUNTIFS(33구역!H4:H43,"교회차2",33구역!E4:E43,$B23)=0,"",COUNTIFS(33구역!F4:F43,"교회차1",33구역!E4:E43,$B23)+COUNTIFS(33구역!H4:H43,"교회차1",33구역!E4:E43,$B23)+COUNTIFS(33구역!F4:F43,"교회차2",33구역!E4:E43,$B23)+COUNTIFS(33구역!H4:H43,"교회차2",33구역!E4:E43,$B23)) | G14: =IF(COUNTIFS(33구역!G4:G43,"교회차1",33구역!E4:E43,$B23)+COUNTIFS(33구역!I4:I43,"교회차1",33구역!E4:E43,$B23)+COUNTIFS(33구역!G4:G43,"교회차2",33구역!E4:E43,$B23)+COUNTIFS(33구역!I4:I43,"교회차2",33구역!E4:E43,$B23)=0,"",COUNTIFS(33구역!G4:G43,"교회차1",33구역!E4:E43,$B23)+COUNTIFS(33구역!I4:I43,"교회차1",33구역!E4:E43,$B23)+COUNTIFS(33구역!G4:G43,"교회차2",33구역!E4:E43,$B23)+COUNTIFS(33구역!I4:I43,"교회차2",33구역!E4:E43,$B23)) | H14: =IF(COUNTIFS(33구역!F4:F43,"타교회",33구역!E4:E43,$B23)+COUNTIFS(33구역!H4:H43,"타교회",33구역!E4:E43,$B23)=0,"",COUNTIFS(33구역!F4:F43,"타교회",33구역!E4:E43,$B23)+COUNTIFS(33구역!H4:H43,"타교회",33구역!E4:E43,$B23)) | I14: =IF(COUNTIFS(33구역!G4:G43,"타교회",33구역!E4:E43,$B23)+COUNTIFS(33구역!I4:I43,"타교회",33구역!E4:E43,$B23)=0,"",COUNTIFS(33구역!G4:G43,"타교회",33구역!E4:E43,$B23)+COUNTIFS(33구역!I4:I43,"타교회",33구역!E4:E43,$B23)) | J14: =IF(COUNTIFS(33구역!F4:F43,"개인차",33구역!E4:E43,$B23)=0,"",COUNTIFS(33구역!F4:F43,"개인차",33구역!E4:E43,$B23)) | K14: =IF(COUNTIFS(33구역!G4:G43,"개인차",33구역!E4:E43,$B23)=0,"",COUNTIFS(33구역!G4:G43,"개인차",33구역!E4:E43,$B23)) | L14: =IF(COUNTIFS(33구역!F4:F43,"대중교통",33구역!E4:E43,$B23)+COUNTIFS(33구역!H4:H43,"대중교통",33구역!E4:E43,$B23)=0,"",COUNTIFS(33구역!F4:F43,"대중교통",33구역!E4:E43,$B23)+COUNTIFS(33구역!H4:H43,"대중교통",33구역!E4:E43,$B23)) | M14: =IF(COUNTIFS(33구역!G4:G43,"대중교통",33구역!E4:E43,$B23)+COUNTIFS(33구역!I4:I43,"대중교통",33구역!E4:E43,$B23)=0,"",COUNTIFS(33구역!G4:G43,"대중교통",33구역!E4:E43,$B23)+COUNTIFS(33구역!I4:I43,"대중교통",33구역!E4:E43,$B23))
A15: 34구역 | B15: =IF(COUNTIFS(34구역!F4:F43,"1호차",34구역!E4:E43,$B23)+COUNTIFS(34구역!F4:F43,"2호차",34구역!E4:E43,$B23)+COUNTIFS(34구역!F4:F43,"3호차",34구역!E4:E43,$B23)+COUNTIFS(34구역!F4:F43,"4호차",34구역!E4:E43,$B23)+COUNTIFS(34구역!F4:F43,"5호차",34구역!E4:E43,$B23)+COUNTIFS(34구역!F4:F43,"6호차",34구역!E4:E43,$B23)+COUNTIFS(34구역!F4:F43,"7호차",34구역!E4:E43,$B23)=0,"",COUNTIFS(34구역!F4:F43,"1호차",34구역!E4:E43,$B23)+COUNTIFS(34구역!F4:F43,"2호차",34구역!E4:E43,$B23)+COUNTIFS(34구역!F4:F43,"3호차",34구역!E4:E43,$B23)+COUNTIFS(34구역!F4:F43,"4호차",34구역!E4:E43,$B23)+COUNTIFS(34구역!F4:F43,"5호차",34구역!E4:E43,$B23)+COUNTIFS(34구역!F4:F43,"6호차",34구역!E4:E43,$B23)+COUNTIFS(34구역!F4:F43,"7호차",34구역!E4:E43,$B23)) | C15: =IF(COUNTIFS(34구역!G4:G43,"1호차",34구역!E4:E43,$B23)+COUNTIFS(34구역!G4:G43,"2호차",34구역!E4:E43,$B23)+COUNTIFS(34구역!G4:G43,"3호차",34구역!E4:E43,$B23)+COUNTIFS(34구역!G4:G43,"4호차",34구역!E4:E43,$B23)+COUNTIFS(34구역!G4:G43,"5호차",34구역!E4:E43,$B23)+COUNTIFS(34구역!G4:G43,"6호차",34구역!E4:E43,$B23)+COUNTIFS(34구역!G4:G43,"7호차",34구역!E4:E43,$B23)=0,"",COUNTIFS(34구역!G4:G43,"1호차",34구역!E4:E43,$B23)+COUNTIFS(34구역!G4:G43,"2호차",34구역!E4:E43,$B23)+COUNTIFS(34구역!G4:G43,"3호차",34구역!E4:E43,$B23)+COUNTIFS(34구역!G4:G43,"4호차",34구역!E4:E43,$B23)+COUNTIFS(34구역!G4:G43,"5호차",34구역!E4:E43,$B23)+COUNTIFS(34구역!G4:G43,"6호차",34구역!E4:E43,$B23)+COUNTIFS(34구역!G4:G43,"7호차",34구역!E4:E43,$B23)) | D15: =IF(COUNTIFS(34구역!H4:H43,"<>",34구역!E4:E43,$B23)=0,"",COUNTIFS(34구역!H4:H43,"<>",34구역!E4:E43,$B23)) | E15: =IF(COUNTIFS(34구역!I4:I43,"<>",34구역!E4:E43,$B23)=0,"",COUNTIFS(34구역!I4:I43,"<>",34구역!E4:E43,$B23)) | F15: =IF(COUNTIFS(34구역!F4:F43,"교회차1",34구역!E4:E43,$B23)+COUNTIFS(34구역!H4:H43,"교회차1",34구역!E4:E43,$B23)+COUNTIFS(34구역!F4:F43,"교회차2",34구역!E4:E43,$B23)+COUNTIFS(34구역!H4:H43,"교회차2",34구역!E4:E43,$B23)=0,"",COUNTIFS(34구역!F4:F43,"교회차1",34구역!E4:E43,$B23)+COUNTIFS(34구역!H4:H43,"교회차1",34구역!E4:E43,$B23)+COUNTIFS(34구역!F4:F43,"교회차2",34구역!E4:E43,$B23)+COUNTIFS(34구역!H4:H43,"교회차2",34구역!E4:E43,$B23)) | G15: =IF(COUNTIFS(34구역!G4:G43,"교회차1",34구역!E4:E43,$B23)+COUNTIFS(34구역!I4:I43,"교회차1",34구역!E4:E43,$B23)+COUNTIFS(34구역!G4:G43,"교회차2",34구역!E4:E43,$B23)+COUNTIFS(34구역!I4:I43,"교회차2",34구역!E4:E43,$B23)=0,"",COUNTIFS(34구역!G4:G43,"교회차1",34구역!E4:E43,$B23)+COUNTIFS(34구역!I4:I43,"교회차1",34구역!E4:E43,$B23)+COUNTIFS(34구역!G4:G43,"교회차2",34구역!E4:E43,$B23)+COUNTIFS(34구역!I4:I43,"교회차2",34구역!E4:E43,$B23)) | H15: =IF(COUNTIFS(34구역!F4:F43,"타교회",34구역!E4:E43,$B23)+COUNTIFS(34구역!H4:H43,"타교회",34구역!E4:E43,$B23)=0,"",COUNTIFS(34구역!F4:F43,"타교회",34구역!E4:E43,$B23)+COUNTIFS(34구역!H4:H43,"타교회",34구역!E4:E43,$B23)) | I15: =IF(COUNTIFS(34구역!G4:G43,"타교회",34구역!E4:E43,$B23)+COUNTIFS(34구역!I4:I43,"타교회",34구역!E4:E43,$B23)=0,"",COUNTIFS(34구역!G4:G43,"타교회",34구역!E4:E43,$B23)+COUNTIFS(34구역!I4:I43,"타교회",34구역!E4:E43,$B23)) | J15: =IF(COUNTIFS(34구역!F4:F43,"개인차",34구역!E4:E43,$B23)=0,"",COUNTIFS(34구역!F4:F43,"개인차",34구역!E4:E43,$B23)) | K15: =IF(COUNTIFS(34구역!G4:G43,"개인차",34구역!E4:E43,$B23)=0,"",COUNTIFS(34구역!G4:G43,"개인차",34구역!E4:E43,$B23)) | L15: =IF(COUNTIFS(34구역!F4:F43,"대중교통",34구역!E4:E43,$B23)+COUNTIFS(34구역!H4:H43,"대중교통",34구역!E4:E43,$B23)=0,"",COUNTIFS(34구역!F4:F43,"대중교통",34구역!E4:E43,$B23)+COUNTIFS(34구역!H4:H43,"대중교통",34구역!E4:E43,$B23)) | M15: =IF(COUNTIFS(34구역!G4:G43,"대중교통",34구역!E4:E43,$B23)+COUNTIFS(34구역!I4:I43,"대중교통",34구역!E4:E43,$B23)=0,"",COUNTIFS(34구역!G4:G43,"대중교통",34구역!E4:E43,$B23)+COUNTIFS(34구역!I4:I43,"대중교통",34구역!E4:E43,$B23))
A16: 합 계 | B16: =IF(SUM(B4:B15)=0,"",SUM(B4:B15)) | C16: =IF(SUM(C4:C15)=0,"",SUM(C4:C15)) | D16: =IF(SUM(D4:D15)=0,"",SUM(D4:D15)) | E16: =IF(SUM(E4:E15)=0,"",SUM(E4:E15)) | F16: =IF(SUM(F4:F15)=0,"",SUM(F4:F15)) | G16: =IF(SUM(G4:G15)=0,"",SUM(G4:G15)) | H16: =IF(SUM(H4:H15)=0,"",SUM(H4:H15)) | I16: =IF(SUM(I4:I15)=0,"",SUM(I4:I15)) | ... M16: =IF(SUM(M4:M15)=0,"",SUM(M4:M15))
A18: 차수별 접수인원
A19: 차수 | B19: 1차 | C19: 2차 | D19: 3차 | E19: 4차 | F19: 5차 | G19: 6차 | H19: 7차 | I19: 8차 | J19: 계
A20: 접수인원 | B20: =IF(COUNTIF(11구역!E4:E43,"1차")+COUNTIF(12구역!E4:E43,"1차")+COUNTIF(13구역!E4:E43,"1차")+COUNTIF(14구역!E4:E43,"1차")+COUNTIF(21구역!E4:E43,"1차")+COUNTIF(22구역!E4:E43,"1차")+COUNTIF(23구역!E4:E43,"1차")+COUNTIF(24구역!E4:E43,"1차")+COUNTIF(31구역!E4:E43,"1차")+COUNTIF(32구역!E4:E43,"1차")+COUNTIF(33구역!E4:E43,"1차")+COUNTIF(34구역!E4:E43,"1차")=0,"",COUNTIF(11구역!E4:E43,"1차")+COUNTIF(12구역!E4:E43,"1차")+COUNTIF(13구역!E4:E43,"1차")+COUNTIF(14구역!E4:E43,"1차")+COUNTIF(21구역!E4:E43,"1차")+COUNTIF(22구역!E4:E43,"1차")+COUNTIF(23구역!E4:E43,"1차")+COUNTIF(24구역!E4:E43,"1차")+COUNTIF(31구역!E4:E43,"1차")+COUNTIF(32구역!E4:E43,"1차")+COUNTIF(33구역!E4:E43,"1차")+COUNTIF(34구역!E4:E43,"1차")) | C20: =IF(COUNTIF(11구역!E4:E43,"2차")+COUNTIF(12구역!E4:E43,"2차")+COUNTIF(13구역!E4:E43,"2차")+COUNTIF(14구역!E4:E43,"2차")+COUNTIF(21구역!E4:E43,"2차")+COUNTIF(22구역!E4:E43,"2차")+COUNTIF(23구역!E4:E43,"2차")+COUNTIF(24구역!E4:E43,"2차")+COUNTIF(31구역!E4:E43,"2차")+COUNTIF(32구역!E4:E43,"2차")+COUNTIF(33구역!E4:E43,"2차")+COUNTIF(34구역!E4:E43,"2차")=0,"",COUNTIF(11구역!E4:E43,"2차")+COUNTIF(12구역!E4:E43,"2차")+COUNTIF(13구역!E4:E43,"2차")+COUNTIF(14구역!E4:E43,"2차")+COUNTIF(21구역!E4:E43,"2차")+COUNTIF(22구역!E4:E43,"2차")+COUNTIF(23구역!E4:E43,"2차")+COUNTIF(24구역!E4:E43,"2차")+COUNTIF(31구역!E4:E43,"2차")+COUNTIF(32구역!E4:E43,"2차")+COUNTIF(33구역!E4:E43,"2차")+COUNTIF(34구역!E4:E43,"2차")) | D20: =IF(COUNTIF(11구역!E4:E43,"3차")+COUNTIF(12구역!E4:E43,"3차")+COUNTIF(13구역!E4:E43,"3차")+COUNTIF(14구역!E4:E43,"3차")+COUNTIF(21구역!E4:E43,"3차")+COUNTIF(22구역!E4:E43,"3차")+COUNTIF(23구역!E4:E43,"3차")+COUNTIF(24구역!E4:E43,"3차")+COUNTIF(31구역!E4:E43,"3차")+COUNTIF(32구역!E4:E43,"3차")+COUNTIF(33구역!E4:E43,"3차")+COUNTIF(34구역!E4:E43,"3차")=0,"",COUNTIF(11구역!E4:E43,"3차")+COUNTIF(12구역!E4:E43,"3차")+COUNTIF(13구역!E4:E43,"3차")+COUNTIF(14구역!E4:E43,"3차")+COUNTIF(21구역!E4:E43,"3차")+COUNTIF(22구역!E4:E43,"3차")+COUNTIF(23구역!E4:E43,"3차")+COUNTIF(24구역!E4:E43,"3차")+COUNTIF(31구역!E4:E43,"3차")+COUNTIF(32구역!E4:E43,"3차")+COUNTIF(33구역!E4:E43,"3차")+COUNTIF(34구역!E4:E43,"3차")) | E20: =IF(COUNTIF(11구역!E4:E43,"4차")+COUNTIF(12구역!E4:E43,"4차")+COUNTIF(13구역!E4:E43,"4차")+COUNTIF(14구역!E4:E43,"4차")+COUNTIF(21구역!E4:E43,"4차")+COUNTIF(22구역!E4:E43,"4차")+COUNTIF(23구역!E4:E43,"4차")+COUNTIF(24구역!E4:E43,"4차")+COUNTIF(31구역!E4:E43,"4차")+COUNTIF(32구역!E4:E43,"4차")+COUNTIF(33구역!E4:E43,"4차")+COUNTIF(34구역!E4:E43,"4차")=0,"",COUNTIF(11구역!E4:E43,"4차")+COUNTIF(12구역!E4:E43,"4차")+COUNTIF(13구역!E4:E43,"4차")+COUNTIF(14구역!E4:E43,"4차")+COUNTIF(21구역!E4:E43,"4차")+COUNTIF(22구역!E4:E43,"4차")+COUNTIF(23구역!E4:E43,"4차")+COUNTIF(24구역!E4:E43,"4차")+COUNTIF(31구역!E4:E43,"4차")+COUNTIF(32구역!E4:E43,"4차")+COUNTIF(33구역!E4:E43,"4차")+COUNTIF(34구역!E4:E43,"4차")) | F20: =IF(COUNTIF(11구역!E4:E43,"5차")+COUNTIF(12구역!E4:E43,"5차")+COUNTIF(13구역!E4:E43,"5차")+COUNTIF(14구역!E4:E43,"5차")+COUNTIF(21구역!E4:E43,"5차")+COUNTIF(22구역!E4:E43,"5차")+COUNTIF(23구역!E4:E43,"5차")+COUNTIF(24구역!E4:E43,"5차")+COUNTIF(31구역!E4:E43,"5차")+COUNTIF(32구역!E4:E43,"5차")+COUNTIF(33구역!E4:E43,"5차")+COUNTIF(34구역!E4:E43,"5차")=0,"",COUNTIF(11구역!E4:E43,"5차")+COUNTIF(12구역!E4:E43,"5차")+COUNTIF(13구역!E4:E43,"5차")+COUNTIF(14구역!E4:E43,"5차")+COUNTIF(21구역!E4:E43,"5차")+COUNTIF(22구역!E4:E43,"5차")+COUNTIF(23구역!E4:E43,"5차")+COUNTIF(24구역!E4:E43,"5차")+COUNTIF(31구역!E4:E43,"5차")+COUNTIF(32구역!E4:E43,"5차")+COUNTIF(33구역!E4:E43,"5차")+COUNTIF(34구역!E4:E43,"5차")) | G20: =IF(COUNTIF(11구역!E4:E43,"6차")+COUNTIF(12구역!E4:E43,"6차")+COUNTIF(13구역!E4:E43,"6차")+COUNTIF(14구역!E4:E43,"6차")+COUNTIF(21구역!E4:E43,"6차")+COUNTIF(22구역!E4:E43,"6차")+COUNTIF(23구역!E4:E43,"6차")+COUNTIF(24구역!E4:E43,"6차")+COUNTIF(31구역!E4:E43,"6차")+COUNTIF(32구역!E4:E43,"6차")+COUNTIF(33구역!E4:E43,"6차")+COUNTIF(34구역!E4:E43,"6차")=0,"",COUNTIF(11구역!E4:E43,"6차")+COUNTIF(12구역!E4:E43,"6차")+COUNTIF(13구역!E4:E43,"6차")+COUNTIF(14구역!E4:E43,"6차")+COUNTIF(21구역!E4:E43,"6차")+COUNTIF(22구역!E4:E43,"6차")+COUNTIF(23구역!E4:E43,"6차")+COUNTIF(24구역!E4:E43,"6차")+COUNTIF(31구역!E4:E43,"6차")+COUNTIF(32구역!E4:E43,"6차")+COUNTIF(33구역!E4:E43,"6차")+COUNTIF(34구역!E4:E43,"6차")) | H20: =IF(COUNTIF(11구역!E4:E43,"7차")+COUNTIF(12구역!E4:E43,"7차")+COUNTIF(13구역!E4:E43,"7차")+COUNTIF(14구역!E4:E43,"7차")+COUNTIF(21구역!E4:E43,"7차")+COUNTIF(22구역!E4:E43,"7차")+COUNTIF(23구역!E4:E43,"7차")+COUNTIF(24구역!E4:E43,"7차")+COUNTIF(31구역!E4:E43,"7차")+COUNTIF(32구역!E4:E43,"7차")+COUNTIF(33구역!E4:E43,"7차")+COUNTIF(34구역!E4:E43,"7차")=0,"",COUNTIF(11구역!E4:E43,"7차")+COUNTIF(12구역!E4:E43,"7차")+COUNTIF(13구역!E4:E43,"7차")+COUNTIF(14구역!E4:E43,"7차")+COUNTIF(21구역!E4:E43,"7차")+COUNTIF(22구역!E4:E43,"7차")+COUNTIF(23구역!E4:E43,"7차")+COUNTIF(24구역!E4:E43,"7차")+COUNTIF(31구역!E4:E43,"7차")+COUNTIF(32구역!E4:E43,"7차")+COUNTIF(33구역!E4:E43,"7차")+COUNTIF(34구역!E4:E43,"7차")) | I20: =IF(COUNTIF(11구역!E4:E43,"8차")+COUNTIF(12구역!E4:E43,"8차")+COUNTIF(13구역!E4:E43,"8차")+COUNTIF(14구역!E4:E43,"8차")+COUNTIF(21구역!E4:E43,"8차")+COUNTIF(22구역!E4:E43,"8차")+COUNTIF(23구역!E4:E43,"8차")+COUNTIF(24구역!E4:E43,"8차")+COUNTIF(31구역!E4:E43,"8차")+COUNTIF(32구역!E4:E43,"8차")+COUNTIF(33구역!E4:E43,"8차")+COUNTIF(34구역!E4:E43,"8차")=0,"",COUNTIF(11구역!E4:E43,"8차")+COUNTIF(12구역!E4:E43,"8차")+COUNTIF(13구역!E4:E43,"8차")+COUNTIF(14구역!E4:E43,"8차")+COUNTIF(21구역!E4:E43,"8차")+COUNTIF(22구역!E4:E43,"8차")+COUNTIF(23구역!E4:E43,"8차")+COUNTIF(24구역!E4:E43,"8차")+COUNTIF(31구역!E4:E43,"8차")+COUNTIF(32구역!E4:E43,"8차")+COUNTIF(33구역!E4:E43,"8차")+COUNTIF(34구역!E4:E43,"8차")) | J20: =IF(SUM(B20:I20)=0,"",SUM(B20:I20))
A23: 적용 차수

Sheet 1호차
A1: 상행 1호차 | H1: 하행 1호차
A2: 선탑자: | H2: 선탑자:
A3: NO | B3: 구역 | C3: 회(부서) | D3: 성 명 | E3: 확인 | F3: 비고 | H3: NO | I3: 구역 | J3: 회(부서) | K3: 성 명 | L3: 확인 | M3: 비고
A4: 1 | B4: {=IFERROR(INDEX(통합!$A$1:$A$400,SMALL(IF(통합!$E$1:$E$400="1호차",ROW(통합!$E$1:$E$400)),1)),"")} | C4: {=IFERROR(INDEX(통합!$B$1:$B$400,SMALL(IF(통합!$E$1:$E$400="1호차",ROW(통합!$E$1:$E$400)),1)),"")} | D4: {=IFERROR(INDEX(통합!$C$1:$C$400,SMALL(IF(통합!$E$1:$E$400="1호차",ROW(통합!$E$1:$E$400)),1)),"")} | H4: 1 | I4: {=IFERROR(INDEX(통합!$A$1:$A$400,SMALL(IF(통합!$F$1:$F$400="1호차",ROW(통합!$F$1:$F$400)),1)),"")} | J4: {=IFERROR(INDEX(통합!$B$1:$B$400,SMALL(IF(통합!$F$1:$F$400="1호차",ROW(통합!$F$1:$F$400)),1)),"")} | K4: {=IFERROR(INDEX(통합!$C$1:$C$400,SMALL(IF(통합!$F$1:$F$400="1호차",ROW(통합!$F$1:$F$400)),1)),"")}
A5: 2 | B5: {=IFERROR(INDEX(통합!$A$1:$A$400,SMALL(IF(통합!$E$1:$E$400="1호차",ROW(통합!$E$1:$E$400)),2)),"")} | C5: {=IFERROR(INDEX(통합!$B$1:$B$400,SMALL(IF(통합!$E$1:$E$400="1호차",ROW(통합!$E$1:$E$400)),2)),"")} | D5: {=IFERROR(INDEX(통합!$C$1:$C$400,SMALL(IF(통합!$E$1:$E$400="1호차",ROW(통합!$E$1:$E$400)),2)),"")} | H5: 2 | I5: {=IFERROR(INDEX(통합!$A$1:$A$400,SMALL(IF(통합!$F$1:$F$400="1호차",ROW(통합!$F$1:$F$400)),2)),"")} | J5: {=IFERROR(INDEX(통합!$B$1:$B$400,SMALL(IF(통합!$F$1:$F$400="1호차",ROW(통합!$F$1:$F$400)),2)),"")} | K5: {=IFERROR(INDEX(통합!$C$1:$C$400,SMALL(IF(통합!$F$1:$F$400="1호차",ROW(통합!$F$1:$F$400)),2)),"")}
